Workbook

Sheet Data Source
A1: SL | B1: Name | C1: Quran | D1: Hadith | E1: Arabic_I | F1: Arabic_II | G1: Aqaid | H1: English_I | I1: English_II | J1: Bangla_I_MCQ | K1: Bangla_I_Written | L1: Bangla_II_MCQ | M1: Bangla_II_Written | N1: Mathematics_MCQ | O1: Mathematics_Written | P1: Islamic_History_MCQ | Q1: Islamic_History_Written | R1: ICT | S1: Agriculture | T1: Total | U1: Average | V1: GPA (Compulsory) | W1: GPA (Final) | X1: Overall Grade
A2: 1 | B2: Ahmed Rahman | C2: 67 | D2: 78 | E2: 66 | F2: 89 | G2: 64 | H2: 68 | I2: 62 | J2: 8 | K2: 52 | L2: 10 | M2: 43 | N2: 15 | O2: 26 | P2: 22 | Q2: 50 | R2: 36 | S2: 75 | T2: =SUM(C2:R2) | U2: =ROUND(T2/11.5,2) | V2: =IF(B2="","",IF(AB2,0,ROUND(AL2,2))) | W2: =IF(B2="","",IF(AB2,0,MIN(5,ROUND(AL2+AM2,2)))) | X2: =IF(B2="","",IF(W2>=5,"A+",IF(W2>=4,"A",IF(W2>=3.5,"A-",IF(W2>=3,"B",IF(W2>=2,"C",IF(W2>=1,"D","F"))))))) | Y2: =NOT(OR(AND(J2>=10,K2>=23,L2>=10,M2>=23),AND(J2+L2>=20,K2+M2>=46))) | Z2: =OR(N2<10,O2<23) | AA2: =OR(P2<10,Q2<23) | AB2: =OR((C2+D2)<66,(E2+F2)<66,G2<33,(H2+I2)<66,Y2,Z2,AA2,R2<8.25) | AC2: =IF(C2+D2<66,0,IF((C2+D2)/2>=80,5,IF((C2+D2)/2>=70,4,IF((C2+D2)/2>=60,3.5,IF((C2+D2)/2>=50,3,IF((C2+D2)/2>=40,2,IF((C2+D2)/2>=33,1,0))))))) | AD2: =IF(E2+F2<66,0,IF((E2+F2)/2>=80,5,IF((E2+F2)/2>=70,4,IF((E2+F2)/2>=60,3.5,IF((E2+F2)/2>=50,3,IF((E2+F2)/2>=40,2,IF((E2+F2)/2>=33,1,0))))))) | AE2: =IF(G2<33,0,IF(G2>=80,5,IF(G2>=70,4,IF(G2>=60,3.5,IF(G2>=50,3,IF(G2>=40,2,IF(G2>=33,1,0))))))) | AF2: =IF(H2+I2<66,0,IF((H2+I2)/2>=80,5,IF((H2+I2)/2>=70,4,IF((H2+I2)/2>=60,3.5,IF((H2+I2)/2>=50,3,IF((H2+I2)/2>=40,2,IF((H2+I2)/2>=33,1,0))))))) | AG2: =IF(Y2,0,IF((J2+K2+L2+M2)/2>=80,5,IF((J2+K2+L2+M2)/2>=70,4,IF((J2+K2+L2+M2)/2>=60,3.5,IF((J2+K2+L2+M2)/2>=50,3,IF((J2+K2+L2+M2)/2>=40,2,IF((J2+K2+L2+M2)/2>=33,1,0))))))) | AH2: =IF(Z2,0,IF(N2+O2>=80,5,IF(N2+O2>=70,4,IF(N2+O2>=60,3.5,IF(N2+O2>=50,3,IF(N2+O2>=40,2,IF(N2+O2>=33,1,0))))))) | AI2: =IF(AA2,0,IF(P2+Q2>=80,5,IF(P2+Q2>=70,4,IF(P2+Q2>=60,3.5,IF(P2+Q2>=50,3,IF(P2+Q2>=40,2,IF(P2+Q2>=33,1,0))))))) | AJ2: =IF(R2<8.25,0,IF(R2*2>=80,5,IF(R2*2>=70,4,IF(R2*2>=60,3.5,IF(R2*2>=50,3,IF(R2*2>=40,2,IF(R2*2>=33,1,0))))))) | AK2: =IF(S2<33,0,IF(S2>=80,5,IF(S2>=70,4,IF(S2>=60,3.5,IF(S2>=50,3,IF(S2>=40,2,IF(S2>=33,1,0))))))) | AL2: =(AC2+AD2+AE2+AF2+AG2+AH2+AI2+AJ2)/8 | AM2: =IF(AK2>=2,(AK2-2)/8,0)
A3: 2 | B3: Fatima Khan | C3: 61 | D3: 72 | E3: 65 | F3: 74 | G3: 70 | H3: 86 | I3: 84 | J3: 11 | K3: 58 | L3: 10 | M3: 48 | N3: 10 | O3: 62 | P3: 12 | Q3: 33 | R3: 31 | S3: 57 | T3: =SUM(C3:R3) | U3: =ROUND(T3/11.5,2) | V3: =IF(B3="","",IF(AB3,0,ROUND(AL3,2))) | W3: =IF(B3="","",IF(AB3,0,MIN(5,ROUND(AL3+AM3,2)))) | X3: =IF(B3="","",IF(W3>=5,"A+",IF(W3>=4,"A",IF(W3>=3.5,"A-",IF(W3>=3,"B",IF(W3>=2,"C",IF(W3>=1,"D","F"))))))) | Y3: =NOT(OR(AND(J3>=10,K3>=23,L3>=10,M3>=23),AND(J3+L3>=20,K3+M3>=46))) | Z3: =OR(N3<10,O3<23) | AA3: =OR(P3<10,Q3<23) | AB3: =OR((C3+D3)<66,(E3+F3)<66,G3<33,(H3+I3)<66,Y3,Z3,AA3,R3<8.25) | AC3: =IF(C3+D3<66,0,IF((C3+D3)/2>=80,5,IF((C3+D3)/2>=70,4,IF((C3+D3)/2>=60,3.5,IF((C3+D3)/2>=50,3,IF((C3+D3)/2>=40,2,IF((C3+D3)/2>=33,1,0))))))) | AD3: =IF(E3+F3<66,0,IF((E3+F3)/2>=80,5,IF((E3+F3)/2>=70,4,IF((E3+F3)/2>=60,3.5,IF((E3+F3)/2>=50,3,IF((E3+F3)/2>=40,2,IF((E3+F3)/2>=33,1,0))))))) | AE3: =IF(G3<33,0,IF(G3>=80,5,IF(G3>=70,4,IF(G3>=60,3.5,IF(G3>=50,3,IF(G3>=40,2,IF(G3>=33,1,0))))))) | AF3: =IF(H3+I3<66,0,IF((H3+I3)/2>=80,5,IF((H3+I3)/2>=70,4,IF((H3+I3)/2>=60,3.5,IF((H3+I3)/2>=50,3,IF((H3+I3)/2>=40,2,IF((H3+I3)/2>=33,1,0))))))) | AG3: =IF(Y3,0,IF((J3+K3+L3+M3)/2>=80,5,IF((J3+K3+L3+M3)/2>=70,4,IF((J3+K3+L3+M3)/2>=60,3.5,IF((J3+K3+L3+M3)/2>=50,3,IF((J3+K3+L3+M3)/2>=40,2,IF((J3+K3+L3+M3)/2>=33,1,0))))))) | AH3: =IF(Z3,0,IF(N3+O3>=80,5,IF(N3+O3>=70,4,IF(N3+O3>=60,3.5,IF(N3+O3>=50,3,IF(N3+O3>=40,2,IF(N3+O3>=33,1,0))))))) | AI3: =IF(AA3,0,IF(P3+Q3>=80,5,IF(P3+Q3>=70,4,IF(P3+Q3>=60,3.5,IF(P3+Q3>=50,3,IF(P3+Q3>=40,2,IF(P3+Q3>=33,1,0))))))) | AJ3: =IF(R3<8.25,0,IF(R3*2>=80,5,IF(R3*2>=70,4,IF(R3*2>=60,3.5,IF(R3*2>=50,3,IF(R3*2>=40,2,IF(R3*2>=33,1,0))))))) | AK3: =IF(S3<33,0,IF(S3>=80,5,IF(S3>=70,4,IF(S3>=60,3.5,IF(S3>=50,3,IF(S3>=40,2,IF(S3>=33,1,0))))))) | AL3: =(AC3+AD3+AE3+AF3+AG3+AH3+AI3+AJ3)/8 | AM3: =IF(AK3>=2,(AK3-2)/8,0)
A4: 3 | B4: Karim Hassan | C4: 77 | D4: 79 | E4: 84 | F4: 67 | G4: 94 | H4: 80 | I4: 61 | J4: 25 | K4: 32 | L4: 23 | M4: 53 | N4: 9 | O4: 47 | P4: 21 | Q4: 45 | R4: 48 | S4: 86 | T4: =SUM(C4:R4) | U4: =ROUND(T4/11.5,2) | V4: =IF(B4="","",IF(AB4,0,ROUND(AL4,2))) | W4: =IF(B4="","",IF(AB4,0,MIN(5,ROUND(AL4+AM4,2)))) | X4: =IF(B4="","",IF(W4>=5,"A+",IF(W4>=4,"A",IF(W4>=3.5,"A-",IF(W4>=3,"B",IF(W4>=2,"C",IF(W4>=1,"D","F"))))))) | Y4: =NOT(OR(AND(J4>=10,K4>=23,L4>=10,M4>=23),AND(J4+L4>=20,K4+M4>=46))) | Z4: =OR(N4<10,O4<23) | AA4: =OR(P4<10,Q4<23) | AB4: =OR((C4+D4)<66,(E4+F4)<66,G4<33,(H4+I4)<66,Y4,Z4,AA4,R4<8.25) | AC4: =IF(C4+D4<66,0,IF((C4+D4)/2>=80,5,IF((C4+D4)/2>=70,4,IF((C4+D4)/2>=60,3.5,IF((C4+D4)/2>=50,3,IF((C4+D4)/2>=40,2,IF((C4+D4)/2>=33,1,0))))))) | AD4: =IF(E4+F4<66,0,IF((E4+F4)/2>=80,5,IF((E4+F4)/2>=70,4,IF((E4+F4)/2>=60,3.5,IF((E4+F4)/2>=50,3,IF((E4+F4)/2>=40,2,IF((E4+F4)/2>=33,1,0))))))) | AE4: =IF(G4<33,0,IF(G4>=80,5,IF(G4>=70,4,IF(G4>=60,3.5,IF(G4>=50,3,IF(G4>=40,2,IF(G4>=33,1,0))))))) | AF4: =IF(H4+I4<66,0,IF((H4+I4)/2>=80,5,IF((H4+I4)/2>=70,4,IF((H4+I4)/2>=60,3.5,IF((H4+I4)/2>=50,3,IF((H4+I4)/2>=40,2,IF((H4+I4)/2>=33,1,0))))))) | AG4: =IF(Y4,0,IF((J4+K4+L4+M4)/2>=80,5,IF((J4+K4+L4+M4)/2>=70,4,IF((J4+K4+L4+M4)/2>=60,3.5,IF((J4+K4+L4+M4)/2>=50,3,IF((J4+K4+L4+M4)/2>=40,2,IF((J4+K4+L4+M4)/2>=33,1,0))))))) | AH4: =IF(Z4,0,IF(N4+O4>=80,5,IF(N4+O4>=70,4,IF(N4+O4>=60,3.5,IF(N4+O4>=50,3,IF(N4+O4>=40,2,IF(N4+O4>=33,1,0))))))) | AI4: =IF(AA4,0,IF(P4+Q4>=80,5,IF(P4+Q4>=70,4,IF(P4+Q4>=60,3.5,IF(P4+Q4>=50,3,IF(P4+Q4>=40,2,IF(P4+Q4>=33,1,0))))))) | AJ4: =IF(R4<8.25,0,IF(R4*2>=80,5,IF(R4*2>=70,4,IF(R4*2>=60,3.5,IF(R4*2>=50,3,IF(R4*2>=40,2,IF(R4*2>=33,1,0))))))) | AK4: =IF(S4<33,0,IF(S4>=80,5,IF(S4>=70,4,IF(S4>=60,3.5,IF(S4>=50,3,IF(S4>=40,2,IF(S4>=33,1,0))))))) | AL4: =(AC4+AD4+AE4+AF4+AG4+AH4+AI4+AJ4)/8 | AM4: =IF(AK4>=2,(AK4-2)/8,0)
A5: 4 | B5: Ayesha Begum | C5: 75 | D5: 83 | E5: 66 | F5: 92 | G5: 75 | H5: 84 | I5: 87 | J5: 16 | K5: 29 | L5: 10 | M5: 48 | N5: 18 | O5: 42 | P5: 13 | Q5: 23 | R5: 47 | S5: 65 | T5: =SUM(C5:R5) | U5: =ROUND(T5/11.5,2) | V5: =IF(B5="","",IF(AB5,0,ROUND(AL5,2))) | W5: =IF(B5="","",IF(AB5,0,MIN(5,ROUND(AL5+AM5,2)))) | X5: =IF(B5="","",IF(W5>=5,"A+",IF(W5>=4,"A",IF(W5>=3.5,"A-",IF(W5>=3,"B",IF(W5>=2,"C",IF(W5>=1,"D","F"))))))) | Y5: =NOT(OR(AND(J5>=10,K5>=23,L5>=10,M5>=23),AND(J5+L5>=20,K5+M5>=46))) | Z5: =OR(N5<10,O5<23) | AA5: =OR(P5<10,Q5<23) | AB5: =OR((C5+D5)<66,(E5+F5)<66,G5<33,(H5+I5)<66,Y5,Z5,AA5,R5<8.25) | AC5: =IF(C5+D5<66,0,IF((C5+D5)/2>=80,5,IF((C5+D5)/2>=70,4,IF((C5+D5)/2>=60,3.5,IF((C5+D5)/2>=50,3,IF((C5+D5)/2>=40,2,IF((C5+D5)/2>=33,1,0))))))) | AD5: =IF(E5+F5<66,0,IF((E5+F5)/2>=80,5,IF((E5+F5)/2>=70,4,IF((E5+F5)/2>=60,3.5,IF((E5+F5)/2>=50,3,IF((E5+F5)/2>=40,2,IF((E5+F5)/2>=33,1,0))))))) | AE5: =IF(G5<33,0,IF(G5>=80,5,IF(G5>=70,4,IF(G5>=60,3.5,IF(G5>=50,3,IF(G5>=40,2,IF(G5>=33,1,0))))))) | AF5: =IF(H5+I5<66,0,IF((H5+I5)/2>=80,5,IF((H5+I5)/2>=70,4,IF((H5+I5)/2>=60,3.5,IF((H5+I5)/2>=50,3,IF((H5+I5)/2>=40,2,IF((H5+I5)/2>=33,1,0))))))) | AG5: =IF(Y5,0,IF((J5+K5+L5+M5)/2>=80,5,IF((J5+K5+L5+M5)/2>=70,4,IF((J5+K5+L5+M5)/2>=60,3.5,IF((J5+K5+L5+M5)/2>=50,3,IF((J5+K5+L5+M5)/2>=40,2,IF((J5+K5+L5+M5)/2>=33,1,0))))))) | AH5: =IF(Z5,0,IF(N5+O5>=80,5,IF(N5+O5>=70,4,IF(N5+O5>=60,3.5,IF(N5+O5>=50,3,IF(N5+O5>=40,2,IF(N5+O5>=33,1,0))))))) | AI5: =IF(AA5,0,IF(P5+Q5>=80,5,IF(P5+Q5>=70,4,IF(P5+Q5>=60,3.5,IF(P5+Q5>=50,3,IF(P5+Q5>=40,2,IF(P5+Q5>=33,1,0))))))) | AJ5: =IF(R5<8.25,0,IF(R5*2>=80,5,IF(R5*2>=70,4,IF(R5*2>=60,3.5,IF(R5*2>=50,3,IF(R5*2>=40,2,IF(R5*2>=33,1,0))))))) | AK5: =IF(S5<33,0,IF(S5>=80,5,IF(S5>=70,4,IF(S5>=60,3.5,IF(S5>=50,3,IF(S5>=40,2,IF(S5>=33,1,0))))))) | AL5: =(AC5+AD5+AE5+AF5+AG5+AH5+AI5+AJ5)/8 | AM5: =IF(AK5>=2,(AK5-2)/8,0)
A6: 5 | B6: Rahim Uddin | C6: 74 | D6: 73 | E6: 82 | F6: 72 | G6: 70 | H6: 64 | I6: 63 | J6: 28 | K6: 43 | L6: 25 | M6: 27 | N6: 10 | O6: 47 | P6: 16 | Q6: 30 | R6: 31 | S6: 87 | T6: =SUM(C6:R6) | U6: =ROUND(T6/11.5,2) | V6: =IF(B6="","",IF(AB6,0,ROUND(AL6,2))) | W6: =IF(B6="","",IF(AB6,0,MIN(5,ROUND(AL6+AM6,2)))) | X6: =IF(B6="","",IF(W6>=5,"A+",IF(W6>=4,"A",IF(W6>=3.5,"A-",IF(W6>=3,"B",IF(W6>=2,"C",IF(W6>=1,"D","F"))))))) | Y6: =NOT(OR(AND(J6>=10,K6>=23,L6>=10,M6>=23),AND(J6+L6>=20,K6+M6>=46))) | Z6: =OR(N6<10,O6<23) | AA6: =OR(P6<10,Q6<23) | AB6: =OR((C6+D6)<66,(E6+F6)<66,G6<33,(H6+I6)<66,Y6,Z6,AA6,R6<8.25) | AC6: =IF(C6+D6<66,0,IF((C6+D6)/2>=80,5,IF((C6+D6)/2>=70,4,IF((C6+D6)/2>=60,3.5,IF((C6+D6)/2>=50,3,IF((C6+D6)/2>=40,2,IF((C6+D6)/2>=33,1,0))))))) | AD6: =IF(E6+F6<66,0,IF((E6+F6)/2>=80,5,IF((E6+F6)/2>=70,4,IF((E6+F6)/2>=60,3.5,IF((E6+F6)/2>=50,3,IF((E6+F6)/2>=40,2,IF((E6+F6)/2>=33,1,0))))))) | AE6: =IF(G6<33,0,IF(G6>=80,5,IF(G6>=70,4,IF(G6>=60,3.5,IF(G6>=50,3,IF(G6>=40,2,IF(G6>=33,1,0))))))) | AF6: =IF(H6+I6<66,0,IF((H6+I6)/2>=80,5,IF((H6+I6)/2>=70,4,IF((H6+I6)/2>=60,3.5,IF((H6+I6)/2>=50,3,IF((H6+I6)/2>=40,2,IF((H6+I6)/2>=33,1,0))))))) | AG6: =IF(Y6,0,IF((J6+K6+L6+M6)/2>=80,5,IF((J6+K6+L6+M6)/2>=70,4,IF((J6+K6+L6+M6)/2>=60,3.5,IF((J6+K6+L6+M6)/2>=50,3,IF((J6+K6+L6+M6)/2>=40,2,IF((J6+K6+L6+M6)/2>=33,1,0))))))) | AH6: =IF(Z6,0,IF(N6+O6>=80,5,IF(N6+O6>=70,4,IF(N6+O6>=60,3.5,IF(N6+O6>=50,3,IF(N6+O6>=40,2,IF(N6+O6>=33,1,0))))))) | AI6: =IF(AA6,0,IF(P6+Q6>=80,5,IF(P6+Q6>=70,4,IF(P6+Q6>=60,3.5,IF(P6+Q6>=50,3,IF(P6+Q6>=40,2,IF(P6+Q6>=33,1,0))))))) | AJ6: =IF(R6<8.25,0,IF(R6*2>=80,5,IF(R6*2>=70,4,IF(R6*2>=60,3.5,IF(R6*2>=50,3,IF(R6*2>=40,2,IF(R6*2>=33,1,0))))))) | AK6: =IF(S6<33,0,IF(S6>=80,5,IF(S6>=70,4,IF(S6>=60,3.5,IF(S6>=50,3,IF(S6>=40,2,IF(S6>=33,1,0))))))) | AL6: =(AC6+AD6+AE6+AF6+AG6+AH6+AI6+AJ6)/8 | AM6: =IF(AK6>=2,(AK6-2)/8,0)
A7: 6 | B7: Nadia Islam | C7: 68 | D7: 90 | E7: 82 | F7: 92 | G7: 89 | H7: 71 | I7: 64 | J7: 18 | K7: 30 | L7: 12 | M7: 35 | N7: 24 | O7: 46 | P7: 22 | Q7: 44 | R7: 40 | S7: 88 | T7: =SUM(C7:R7) | U7: =ROUND(T7/11.5,2) | V7: =IF(B7="","",IF(AB7,0,ROUND(AL7,2))) | W7: =IF(B7="","",IF(AB7,0,MIN(5,ROUND(AL7+AM7,2)))) | X7: =IF(B7="","",IF(W7>=5,"A+",IF(W7>=4,"A",IF(W7>=3.5,"A-",IF(W7>=3,"B",IF(W7>=2,"C",IF(W7>=1,"D","F"))))))) | Y7: =NOT(OR(AND(J7>=10,K7>=23,L7>=10,M7>=23),AND(J7+L7>=20,K7+M7>=46))) | Z7: =OR(N7<10,O7<23) | AA7: =OR(P7<10,Q7<23) | AB7: =OR((C7+D7)<66,(E7+F7)<66,G7<33,(H7+I7)<66,Y7,Z7,AA7,R7<8.25) | AC7: =IF(C7+D7<66,0,IF((C7+D7)/2>=80,5,IF((C7+D7)/2>=70,4,IF((C7+D7)/2>=60,3.5,IF((C7+D7)/2>=50,3,IF((C7+D7)/2>=40,2,IF((C7+D7)/2>=33,1,0))))))) | AD7: =IF(E7+F7<66,0,IF((E7+F7)/2>=80,5,IF((E7+F7)/2>=70,4,IF((E7+F7)/2>=60,3.5,IF((E7+F7)/2>=50,3,IF((E7+F7)/2>=40,2,IF((E7+F7)/2>=33,1,0))))))) | AE7: =IF(G7<33,0,IF(G7>=80,5,IF(G7>=70,4,IF(G7>=60,3.5,IF(G7>=50,3,IF(G7>=40,2,IF(G7>=33,1,0))))))) | AF7: =IF(H7+I7<66,0,IF((H7+I7)/2>=80,5,IF((H7+I7)/2>=70,4,IF((H7+I7)/2>=60,3.5,IF((H7+I7)/2>=50,3,IF((H7+I7)/2>=40,2,IF((H7+I7)/2>=33,1,0))))))) | AG7: =IF(Y7,0,IF((J7+K7+L7+M7)/2>=80,5,IF((J7+K7+L7+M7)/2>=70,4,IF((J7+K7+L7+M7)/2>=60,3.5,IF((J7+K7+L7+M7)/2>=50,3,IF((J7+K7+L7+M7)/2>=40,2,IF((J7+K7+L7+M7)/2>=33,1,0))))))) | AH7: =IF(Z7,0,IF(N7+O7>=80,5,IF(N7+O7>=70,4,IF(N7+O7>=60,3.5,IF(N7+O7>=50,3,IF(N7+O7>=40,2,IF(N7+O7>=33,1,0))))))) | AI7: =IF(AA7,0,IF(P7+Q7>=80,5,IF(P7+Q7>=70,4,IF(P7+Q7>=60,3.5,IF(P7+Q7>=50,3,IF(P7+Q7>=40,2,IF(P7+Q7>=33,1,0))))))) | AJ7: =IF(R7<8.25,0,IF(R7*2>=80,5,IF(R7*2>=70,4,IF(R7*2>=60,3.5,IF(R7*2>=50,3,IF(R7*2>=40,2,IF(R7*2>=33,1,0))))))) | AK7: =IF(S7<33,0,IF(S7>=80,5,IF(S7>=70,4,IF(S7>=60,3.5,IF(S7>=50,3,IF(S7>=40,2,IF(S7>=33,1,0))))))) | AL7: =(AC7+AD7+AE7+AF7+AG7+AH7+AI7+AJ7)/8 | AM7: =IF(AK7>=2,(AK7-2)/8,0)
A8: 7 | B8: Jahir Ahmed | C8: 66 | D8: 92 | E8: 76 | F8: 68 | G8: 84 | H8: 63 | I8: 80 | J8: 11 | K8: 54 | L8: 12 | M8: 34 | N8: 15 | O8: 49 | P8: 15 | Q8: 20 | R8: 31 | S8: 52 | T8: =SUM(C8:R8) | U8: =ROUND(T8/11.5,2) | V8: =IF(B8="","",IF(AB8,0,ROUND(AL8,2))) | W8: =IF(B8="","",IF(AB8,0,MIN(5,ROUND(AL8+AM8,2)))) | X8: =IF(B8="","",IF(W8>=5,"A+",IF(W8>=4,"A",IF(W8>=3.5,"A-",IF(W8>=3,"B",IF(W8>=2,"C",IF(W8>=1,"D","F"))))))) | Y8: =NOT(OR(AND(J8>=10,K8>=23,L8>=10,M8>=23),AND(J8+L8>=20,K8+M8>=46))) | Z8: =OR(N8<10,O8<23) | AA8: =OR(P8<10,Q8<23) | AB8: =OR((C8+D8)<66,(E8+F8)<66,G8<33,(H8+I8)<66,Y8,Z8,AA8,R8<8.25) | AC8: =IF(C8+D8<66,0,IF((C8+D8)/2>=80,5,IF((C8+D8)/2>=70,4,IF((C8+D8)/2>=60,3.5,IF((C8+D8)/2>=50,3,IF((C8+D8)/2>=40,2,IF((C8+D8)/2>=33,1,0))))))) | AD8: =IF(E8+F8<66,0,IF((E8+F8)/2>=80,5,IF((E8+F8)/2>=70,4,IF((E8+F8)/2>=60,3.5,IF((E8+F8)/2>=50,3,IF((E8+F8)/2>=40,2,IF((E8+F8)/2>=33,1,0))))))) | AE8: =IF(G8<33,0,IF(G8>=80,5,IF(G8>=70,4,IF(G8>=60,3.5,IF(G8>=50,3,IF(G8>=40,2,IF(G8>=33,1,0))))))) | AF8: =IF(H8+I8<66,0,IF((H8+I8)/2>=80,5,IF((H8+I8)/2>=70,4,IF((H8+I8)/2>=60,3.5,IF((H8+I8)/2>=50,3,IF((H8+I8)/2>=40,2,IF((H8+I8)/2>=33,1,0))))))) | AG8: =IF(Y8,0,IF((J8+K8+L8+M8)/2>=80,5,IF((J8+K8+L8+M8)/2>=70,4,IF((J8+K8+L8+M8)/2>=60,3.5,IF((J8+K8+L8+M8)/2>=50,3,IF((J8+K8+L8+M8)/2>=40,2,IF((J8+K8+L8+M8)/2>=33,1,0))))))) | AH8: =IF(Z8,0,IF(N8+O8>=80,5,IF(N8+O8>=70,4,IF(N8+O8>=60,3.5,IF(N8+O8>=50,3,IF(N8+O8>=40,2,IF(N8+O8>=33,1,0))))))) | AI8: =IF(AA8,0,IF(P8+Q8>=80,5,IF(P8+Q8>=70,4,IF(P8+Q8>=60,3.5,IF(P8+Q8>=50,3,IF(P8+Q8>=40,2,IF(P8+Q8>=33,1,0))))))) | AJ8: =IF(R8<8.25,0,IF(R8*2>=80,5,IF(R8*2>=70,4,IF(R8*2>=60,3.5,IF(R8*2>=50,3,IF(R8*2>=40,2,IF(R8*2>=33,1,0))))))) | AK8: =IF(S8<33,0,IF(S8>=80,5,IF(S8>=70,4,IF(S8>=60,3.5,IF(S8>=50,3,IF(S8>=40,2,IF(S8>=33,1,0))))))) | AL8: =(AC8+AD8+AE8+AF8+AG8+AH8+AI8+AJ8)/8 | AM8: =IF(AK8>=2,(AK8-2)/8,0)
A9: 8 | B9: Sadia Sultana | C9: 94 | D9: 65 | E9: 62 | F9: 77 | G9: 77 | H9: 70 | I9: 65 | J9: 17 | K9: 53 | L9: 23 | M9: 24 | N9: 16 | O9: 23 | P9: 10 | Q9: 44 | R9: 31 | S9: 89 | T9: =SUM(C9:R9) | U9: =ROUND(T9/11.5,2) | V9: =IF(B9="","",IF(AB9,0,ROUND(AL9,2))) | W9: =IF(B9="","",IF(AB9,0,MIN(5,ROUND(AL9+AM9,2)))) | X9: =IF(B9="","",IF(W9>=5,"A+",IF(W9>=4,"A",IF(W9>=3.5,"A-",IF(W9>=3,"B",IF(W9>=2,"C",IF(W9>=1,"D","F"))))))) | Y9: =NOT(OR(AND(J9>=10,K9>=23,L9>=10,M9>=23),AND(J9+L9>=20,K9+M9>=46))) | Z9: =OR(N9<10,O9<23) | AA9: =OR(P9<10,Q9<23) | AB9: =OR((C9+D9)<66,(E9+F9)<66,G9<33,(H9+I9)<66,Y9,Z9,AA9,R9<8.25) | AC9: =IF(C9+D9<66,0,IF((C9+D9)/2>=80,5,IF((C9+D9)/2>=70,4,IF((C9+D9)/2>=60,3.5,IF((C9+D9)/2>=50,3,IF((C9+D9)/2>=40,2,IF((C9+D9)/2>=33,1,0))))))) | AD9: =IF(E9+F9<66,0,IF((E9+F9)/2>=80,5,IF((E9+F9)/2>=70,4,IF((E9+F9)/2>=60,3.5,IF((E9+F9)/2>=50,3,IF((E9+F9)/2>=40,2,IF((E9+F9)/2>=33,1,0))))))) | AE9: =IF(G9<33,0,IF(G9>=80,5,IF(G9>=70,4,IF(G9>=60,3.5,IF(G9>=50,3,IF(G9>=40,2,IF(G9>=33,1,0))))))) | AF9: =IF(H9+I9<66,0,IF((H9+I9)/2>=80,5,IF((H9+I9)/2>=70,4,IF((H9+I9)/2>=60,3.5,IF((H9+I9)/2>=50,3,IF((H9+I9)/2>=40,2,IF((H9+I9)/2>=33,1,0))))))) | AG9: =IF(Y9,0,IF((J9+K9+L9+M9)/2>=80,5,IF((J9+K9+L9+M9)/2>=70,4,IF((J9+K9+L9+M9)/2>=60,3.5,IF((J9+K9+L9+M9)/2>=50,3,IF((J9+K9+L9+M9)/2>=40,2,IF((J9+K9+L9+M9)/2>=33,1,0))))))) | AH9: =IF(Z9,0,IF(N9+O9>=80,5,IF(N9+O9>=70,4,IF(N9+O9>=60,3.5,IF(N9+O9>=50,3,IF(N9+O9>=40,2,IF(N9+O9>=33,1,0))))))) | AI9: =IF(AA9,0,IF(P9+Q9>=80,5,IF(P9+Q9>=70,4,IF(P9+Q9>=60,3.5,IF(P9+Q9>=50,3,IF(P9+Q9>=40,2,IF(P9+Q9>=33,1,0))))))) | AJ9: =IF(R9<8.25,0,IF(R9*2>=80,5,IF(R9*2>=70,4,IF(R9*2>=60,3.5,IF(R9*2>=50,3,IF(R9*2>=40,2,IF(R9*2>=33,1,0))))))) | AK9: =IF(S9<33,0,IF(S9>=80,5,IF(S9>=70,4,IF(S9>=60,3.5,IF(S9>=50,3,IF(S9>=40,2,IF(S9>=33,1,0))))))) | AL9: =(AC9+AD9+AE9+AF9+AG9+AH9+AI9+AJ9)/8 | AM9: =IF(AK9>=2,(AK9-2)/8,0)
A10: 9 | B10: Tarik Hasan | C10: 65 | D10: 89 | E10: 89 | F10: 73 | G10: 95 | H10: 90 | I10: 85 | J10: 21 | K10: 20 | L10: 25 | M10: 41 | N10: 23 | O10: 63 | P10: 22 | Q10: 36 | R10: 48 | S10: 55 | T10: =SUM(C10:R10) | U10: =ROUND(T10/11.5,2) | V10: =IF(B10="","",IF(AB10,0,ROUND(AL10,2))) | W10: =IF(B10="","",IF(AB10,0,MIN(5,ROUND(AL10+AM10,2)))) | X10: =IF(B10="","",IF(W10>=5,"A+",IF(W10>=4,"A",IF(W10>=3.5,"A-",IF(W10>=3,"B",IF(W10>=2,"C",IF(W10>=1,"D","F"))))))) | Y10: =NOT(OR(AND(J10>=10,K10>=23,L10>=10,M10>=23),AND(J10+L10>=20,K10+M10>=46))) | Z10: =OR(N10<10,O10<23) | AA10: =OR(P10<10,Q10<23) | AB10: =OR((C10+D10)<66,(E10+F10)<66,G10<33,(H10+I10)<66,Y10,Z10,AA10,R10<8.25) | AC10: =IF(C10+D10<66,0,IF((C10+D10)/2>=80,5,IF((C10+D10)/2>=70,4,IF((C10+D10)/2>=60,3.5,IF((C10+D10)/2>=50,3,IF((C10+D10)/2>=40,2,IF((C10+D10)/2>=33,1,0))))))) | AD10: =IF(E10+F10<66,0,IF((E10+F10)/2>=80,5,IF((E10+F10)/2>=70,4,IF((E10+F10)/2>=60,3.5,IF((E10+F10)/2>=50,3,IF((E10+F10)/2>=40,2,IF((E10+F10)/2>=33,1,0))))))) | AE10: =IF(G10<33,0,IF(G10>=80,5,IF(G10>=70,4,IF(G10>=60,3.5,IF(G10>=50,3,IF(G10>=40,2,IF(G10>=33,1,0))))))) | AF10: =IF(H10+I10<66,0,IF((H10+I10)/2>=80,5,IF((H10+I10)/2>=70,4,IF((H10+I10)/2>=60,3.5,IF((H10+I10)/2>=50,3,IF((H10+I10)/2>=40,2,IF((H10+I10)/2>=33,1,0))))))) | AG10: =IF(Y10,0,IF((J10+K10+L10+M10)/2>=80,5,IF((J10+K10+L10+M10)/2>=70,4,IF((J10+K10+L10+M10)/2>=60,3.5,IF((J10+K10+L10+M10)/2>=50,3,IF((J10+K10+L10+M10)/2>=40,2,IF((J10+K10+L10+M10)/2>=33,1,0))))))) | AH10: =IF(Z10,0,IF(N10+O10>=80,5,IF(N10+O10>=70,4,IF(N10+O10>=60,3.5,IF(N10+O10>=50,3,IF(N10+O10>=40,2,IF(N10+O10>=33,1,0))))))) | AI10: =IF(AA10,0,IF(P10+Q10>=80,5,IF(P10+Q10>=70,4,IF(P10+Q10>=60,3.5,IF(P10+Q10>=50,3,IF(P10+Q10>=40,2,IF(P10+Q10>=33,1,0))))))) | AJ10: =IF(R10<8.25,0,IF(R10*2>=80,5,IF(R10*2>=70,4,IF(R10*2>=60,3.5,IF(R10*2>=50,3,IF(R10*2>=40,2,IF(R10*2>=33,1,0))))))) | AK10: =IF(S10<33,0,IF(S10>=80,5,IF(S10>=70,4,IF(S10>=60,3.5,IF(S10>=50,3,IF(S10>=40,2,IF(S10>=33,1,0))))))) | AL10: =(AC10+AD10+AE10+AF10+AG10+AH10+AI10+AJ10)/8 | AM10: =IF(AK10>=2,(AK10-2)/8,0)
A11: 10 | B11: Ruhi Akter | C11: 87 | D11: 90 | E11: 94 | F11: 79 | G11: 74 | H11: 89 | I11: 81 | J11: 13 | K11: 58 | L11: 13 | M11: 21 | N11: 14 | O11: 61 | P11: 25 | Q11: 49 | R11: 45 | S11: 76 | T11: =SUM(C11:R11) | U11: =ROUND(T11/11.5,2) | V11: =IF(B11="","",IF(AB11,0,ROUND(AL11,2))) | W11: =IF(B11="","",IF(AB11,0,MIN(5,ROUND(AL11+AM11,2)))) | X11: =IF(B11="","",IF(W11>=5,"A+",IF(W11>=4,"A",IF(W11>=3.5,"A-",IF(W11>=3,"B",IF(W11>=2,"C",IF(W11>=1,"D","F"))))))) | Y11: =NOT(OR(AND(J11>=10,K11>=23,L11>=10,M11>=23),AND(J11+L11>=20,K11+M11>=46))) | Z11: =OR(N11<10,O11<23) | AA11: =OR(P11<10,Q11<23) | AB11: =OR((C11+D11)<66,(E11+F11)<66,G11<33,(H11+I11)<66,Y11,Z11,AA11,R11<8.25) | AC11: =IF(C11+D11<66,0,IF((C11+D11)/2>=80,5,IF((C11+D11)/2>=70,4,IF((C11+D11)/2>=60,3.5,IF((C11+D11)/2>=50,3,IF((C11+D11)/2>=40,2,IF((C11+D11)/2>=33,1,0))))))) | AD11: =IF(E11+F11<66,0,IF((E11+F11)/2>=80,5,IF((E11+F11)/2>=70,4,IF((E11+F11)/2>=60,3.5,IF((E11+F11)/2>=50,3,IF((E11+F11)/2>=40,2,IF((E11+F11)/2>=33,1,0))))))) | AE11: =IF(G11<33,0,IF(G11>=80,5,IF(G11>=70,4,IF(G11>=60,3.5,IF(G11>=50,3,IF(G11>=40,2,IF(G11>=33,1,0))))))) | AF11: =IF(H11+I11<66,0,IF((H11+I11)/2>=80,5,IF((H11+I11)/2>=70,4,IF((H11+I11)/2>=60,3.5,IF((H11+I11)/2>=50,3,IF((H11+I11)/2>=40,2,IF((H11+I11)/2>=33,1,0))))))) | AG11: =IF(Y11,0,IF((J11+K11+L11+M11)/2>=80,5,IF((J11+K11+L11+M11)/2>=70,4,IF((J11+K11+L11+M11)/2>=60,3.5,IF((J11+K11+L11+M11)/2>=50,3,IF((J11+K11+L11+M11)/2>=40,2,IF((J11+K11+L11+M11)/2>=33,1,0))))))) | AH11: =IF(Z11,0,IF(N11+O11>=80,5,IF(N11+O11>=70,4,IF(N11+O11>=60,3.5,IF(N11+O11>=50,3,IF(N11+O11>=40,2,IF(N11+O11>=33,1,0))))))) | AI11: =IF(AA11,0,IF(P11+Q11>=80,5,IF(P11+Q11>=70,4,IF(P11+Q11>=60,3.5,IF(P11+Q11>=50,3,IF(P11+Q11>=40,2,IF(P11+Q11>=33,1,0))))))) | AJ11: =IF(R11<8.25,0,IF(R11*2>=80,5,IF(R11*2>=70,4,IF(R11*2>=60,3.5,IF(R11*2>=50,3,IF(R11*2>=40,2,IF(R11*2>=33,1,0))))))) | AK11: =IF(S11<33,0,IF(S11>=80,5,IF(S11>=70,4,IF(S11>=60,3.5,IF(S11>=50,3,IF(S11>=40,2,IF(S11>=33,1,0))))))) | AL11: =(AC11+AD11+AE11+AF11+AG11+AH11+AI11+AJ11)/8 | AM11: =IF(AK11>=2,(AK11-2)/8,0)
A12: 11 | B12: Mehedi Hassan | C12: 62 | D12: 70 | E12: 67 | F12: 85 | G12: 80 | H12: 71 | I12: 73 | J12: 22 | K12: 40 | L12: 16 | M12: 57 | N12: 25 | O12: 61 | P12: 11 | Q12: 38 | R12: 46 | S12: 87 | T12: =SUM(C12:R12) | U12: =ROUND(T12/11.5,2) | V12: =IF(B12="","",IF(AB12,0,ROUND(AL12,2))) | W12: =IF(B12="","",IF(AB12,0,MIN(5,ROUND(AL12+AM12,2)))) | X12: =IF(B12="","",IF(W12>=5,"A+",IF(W12>=4,"A",IF(W12>=3.5,"A-",IF(W12>=3,"B",IF(W12>=2,"C",IF(W12>=1,"D","F"))))))) | Y12: =NOT(OR(AND(J12>=10,K12>=23,L12>=10,M12>=23),AND(J12+L12>=20,K12+M12>=46))) | Z12: =OR(N12<10,O12<23) | AA12: =OR(P12<10,Q12<23) | AB12: =OR((C12+D12)<66,(E12+F12)<66,G12<33,(H12+I12)<66,Y12,Z12,AA12,R12<8.25) | AC12: =IF(C12+D12<66,0,IF((C12+D12)/2>=80,5,IF((C12+D12)/2>=70,4,IF((C12+D12)/2>=60,3.5,IF((C12+D12)/2>=50,3,IF((C12+D12)/2>=40,2,IF((C12+D12)/2>=33,1,0))))))) | AD12: =IF(E12+F12<66,0,IF((E12+F12)/2>=80,5,IF((E12+F12)/2>=70,4,IF((E12+F12)/2>=60,3.5,IF((E12+F12)/2>=50,3,IF((E12+F12)/2>=40,2,IF((E12+F12)/2>=33,1,0))))))) | AE12: =IF(G12<33,0,IF(G12>=80,5,IF(G12>=70,4,IF(G12>=60,3.5,IF(G12>=50,3,IF(G12>=40,2,IF(G12>=33,1,0))))))) | AF12: =IF(H12+I12<66,0,IF((H12+I12)/2>=80,5,IF((H12+I12)/2>=70,4,IF((H12+I12)/2>=60,3.5,IF((H12+I12)/2>=50,3,IF((H12+I12)/2>=40,2,IF((H12+I12)/2>=33,1,0))))))) | AG12: =IF(Y12,0,IF((J12+K12+L12+M12)/2>=80,5,IF((J12+K12+L12+M12)/2>=70,4,IF((J12+K12+L12+M12)/2>=60,3.5,IF((J12+K12+L12+M12)/2>=50,3,IF((J12+K12+L12+M12)/2>=40,2,IF((J12+K12+L12+M12)/2>=33,1,0))))))) | AH12: =IF(Z12,0,IF(N12+O12>=80,5,IF(N12+O12>=70,4,IF(N12+O12>=60,3.5,IF(N12+O12>=50,3,IF(N12+O12>=40,2,IF(N12+O12>=33,1,0))))))) | AI12: =IF(AA12,0,IF(P12+Q12>=80,5,IF(P12+Q12>=70,4,IF(P12+Q12>=60,3.5,IF(P12+Q12>=50,3,IF(P12+Q12>=40,2,IF(P12+Q12>=33,1,0))))))) | AJ12: =IF(R12<8.25,0,IF(R12*2>=80,5,IF(R12*2>=70,4,IF(R12*2>=60,3.5,IF(R12*2>=50,3,IF(R12*2>=40,2,IF(R12*2>=33,1,0))))))) | AK12: =IF(S12<33,0,IF(S12>=80,5,IF(S12>=70,4,IF(S12>=60,3.5,IF(S12>=50,3,IF(S12>=40,2,IF(S12>=33,1,0))))))) | AL12: =(AC12+AD12+AE12+AF12+AG12+AH12+AI12+AJ12)/8 | AM12: =IF(AK12>=2,(AK12-2)/8,0)
A13: 12 | B13: Lubna Khatun | C13: 61 | D13: 87 | E13: 84 | F13: 91 | G13: 63 | H13: 92 | I13: 79 | J13: 8 | K13: 51 | L13: 24 | M13: 55 | N13: 12 | O13: 26 | P13: 9 | Q13: 47 | R13: 46 | S13: 86 | T13: =SUM(C13:R13) | U13: =ROUND(T13/11.5,2) | V13: =IF(B13="","",IF(AB13,0,ROUND(AL13,2))) | W13: =IF(B13="","",IF(AB13,0,MIN(5,ROUND(AL13+AM13,2)))) | X13: =IF(B13="","",IF(W13>=5,"A+",IF(W13>=4,"A",IF(W13>=3.5,"A-",IF(W13>=3,"B",IF(W13>=2,"C",IF(W13>=1,"D","F"))))))) | Y13: =NOT(OR(AND(J13>=10,K13>=23,L13>=10,M13>=23),AND(J13+L13>=20,K13+M13>=46))) | Z13: =OR(N13<10,O13<23) | AA13: =OR(P13<10,Q13<23) | AB13: =OR((C13+D13)<66,(E13+F13)<66,G13<33,(H13+I13)<66,Y13,Z13,AA13,R13<8.25) | AC13: =IF(C13+D13<66,0,IF((C13+D13)/2>=80,5,IF((C13+D13)/2>=70,4,IF((C13+D13)/2>=60,3.5,IF((C13+D13)/2>=50,3,IF((C13+D13)/2>=40,2,IF((C13+D13)/2>=33,1,0))))))) | AD13: =IF(E13+F13<66,0,IF((E13+F13)/2>=80,5,IF((E13+F13)/2>=70,4,IF((E13+F13)/2>=60,3.5,IF((E13+F13)/2>=50,3,IF((E13+F13)/2>=40,2,IF((E13+F13)/2>=33,1,0))))))) | AE13: =IF(G13<33,0,IF(G13>=80,5,IF(G13>=70,4,IF(G13>=60,3.5,IF(G13>=50,3,IF(G13>=40,2,IF(G13>=33,1,0))))))) | AF13: =IF(H13+I13<66,0,IF((H13+I13)/2>=80,5,IF((H13+I13)/2>=70,4,IF((H13+I13)/2>=60,3.5,IF((H13+I13)/2>=50,3,IF((H13+I13)/2>=40,2,IF((H13+I13)/2>=33,1,0))))))) | AG13: =IF(Y13,0,IF((J13+K13+L13+M13)/2>=80,5,IF((J13+K13+L13+M13)/2>=70,4,IF((J13+K13+L13+M13)/2>=60,3.5,IF((J13+K13+L13+M13)/2>=50,3,IF((J13+K13+L13+M13)/2>=40,2,IF((J13+K13+L13+M13)/2>=33,1,0))))))) | AH13: =IF(Z13,0,IF(N13+O13>=80,5,IF(N13+O13>=70,4,IF(N13+O13>=60,3.5,IF(N13+O13>=50,3,IF(N13+O13>=40,2,IF(N13+O13>=33,1,0))))))) | AI13: =IF(AA13,0,IF(P13+Q13>=80,5,IF(P13+Q13>=70,4,IF(P13+Q13>=60,3.5,IF(P13+Q13>=50,3,IF(P13+Q13>=40,2,IF(P13+Q13>=33,1,0))))))) | AJ13: =IF(R13<8.25,0,IF(R13*2>=80,5,IF(R13*2>=70,4,IF(R13*2>=60,3.5,IF(R13*2>=50,3,IF(R13*2>=40,2,IF(R13*2>=33,1,0))))))) | AK13: =IF(S13<33,0,IF(S13>=80,5,IF(S13>=70,4,IF(S13>=60,3.5,IF(S13>=50,3,IF(S13>=40,2,IF(S13>=33,1,0))))))) | AL13: =(AC13+AD13+AE13+AF13+AG13+AH13+AI13+AJ13)/8 | AM13: =IF(AK13>=2,(AK13-2)/8,0)
... A21: 20 | B21: Tasnia Akter | C21: 94 | D21: 75 | E21: 74 | F21: 87 | G21: 80 | H21: 86 | I21: 77 | J21: 28 | K21: 56 | L21: 28 | M21: 23 | N21: 11 | O21: 54 | P21: 23 | Q21: 38 | R21: 37 | S21: 75 | T21: =SUM(C21:R21) | U21: =ROUND(T21/11.5,2) | V21: =IF(B21="","",IF(AB21,0,ROUND(AL21,2))) | W21: =IF(B21="","",IF(AB21,0,MIN(5,ROUND(AL21+AM21,2)))) | X21: =IF(B21="","",IF(W21>=5,"A+",IF(W21>=4,"A",IF(W21>=3.5,"A-",IF(W21>=3,"B",IF(W21>=2,"C",IF(W21>=1,"D","F"))))))) | Y21: =NOT(OR(AND(J21>=10,K21>=23,L21>=10,M21>=23),AND(J21+L21>=20,K21+M21>=46))) | Z21: =OR(N21<10,O21<23) | AA21: =OR(P21<10,Q21<23) | AB21: =OR((C21+D21)<66,(E21+F21)<66,G21<33,(H21+I21)<66,Y21,Z21,AA21,R21<8.25) | AC21: =IF(C21+D21<66,0,IF((C21+D21)/2>=80,5,IF((C21+D21)/2>=70,4,IF((C21+D21)/2>=60,3.5,IF((C21+D21)/2>=50,3,IF((C21+D21)/2>=40,2,IF((C21+D21)/2>=33,1,0))))))) | AD21: =IF(E21+F21<66,0,IF((E21+F21)/2>=80,5,IF((E21+F21)/2>=70,4,IF((E21+F21)/2>=60,3.5,IF((E21+F21)/2>=50,3,IF((E21+F21)/2>=40,2,IF((E21+F21)/2>=33,1,0))))))) | AE21: =IF(G21<33,0,IF(G21>=80,5,IF(G21>=70,4,IF(G21>=60,3.5,IF(G21>=50,3,IF(G21>=40,2,IF(G21>=33,1,0))))))) | AF21: =IF(H21+I21<66,0,IF((H21+I21)/2>=80,5,IF((H21+I21)/2>=70,4,IF((H21+I21)/2>=60,3.5,IF((H21+I21)/2>=50,3,IF((H21+I21)/2>=40,2,IF((H21+I21)/2>=33,1,0))))))) | AG21: =IF(Y21,0,IF((J21+K21+L21+M21)/2>=80,5,IF((J21+K21+L21+M21)/2>=70,4,IF((J21+K21+L21+M21)/2>=60,3.5,IF((J21+K21+L21+M21)/2>=50,3,IF((J21+K21+L21+M21)/2>=40,2,IF((J21+K21+L21+M21)/2>=33,1,0))))))) | AH21: =IF(Z21,0,IF(N21+O21>=80,5,IF(N21+O21>=70,4,IF(N21+O21>=60,3.5,IF(N21+O21>=50,3,IF(N21+O21>=40,2,IF(N21+O21>=33,1,0))))))) | AI21: =IF(AA21,0,IF(P21+Q21>=80,5,IF(P21+Q21>=70,4,IF(P21+Q21>=60,3.5,IF(P21+Q21>=50,3,IF(P21+Q21>=40,2,IF(P21+Q21>=33,1,0))))))) | AJ21: =IF(R21<8.25,0,IF(R21*2>=80,5,IF(R21*2>=70,4,IF(R21*2>=60,3.5,IF(R21*2>=50,3,IF(R21*2>=40,2,IF(R21*2>=33,1,0))))))) | AK21: =IF(S21<33,0,IF(S21>=80,5,IF(S21>=70,4,IF(S21>=60,3.5,IF(S21>=50,3,IF(S21>=40,2,IF(S21>=33,1,0))))))) | AL21: =(AC21+AD21+AE21+AF21+AG21+AH21+AI21+AJ21)/8 | AM21: =IF(AK21>=2,(AK21-2)/8,0)
T22: =SUM(C22:R22) | U22: =ROUND(T22/11.5,2) | V22: =IF(B22="","",IF(AB22,0,ROUND(AL22,2))) | W22: =IF(B22="","",IF(AB22,0,MIN(5,ROUND(AL22+AM22,2)))) | X22: =IF(B22="","",IF(W22>=5,"A+",IF(W22>=4,"A",IF(W22>=3.5,"A-",IF(W22>=3,"B",IF(W22>=2,"C",IF(W22>=1,"D","F"))))))) | Y22: =NOT(OR(AND(J22>=10,K22>=23,L22>=10,M22>=23),AND(J22+L22>=20,K22+M22>=46))) | Z22: =OR(N22<10,O22<23) | AA22: =OR(P22<10,Q22<23) | AB22: =OR((C22+D22)<66,(E22+F22)<66,G22<33,(H22+I22)<66,Y22,Z22,AA22,R22<8.25) | AC22: =IF(C22+D22<66,0,IF((C22+D22)/2>=80,5,IF((C22+D22)/2>=70,4,IF((C22+D22)/2>=60,3.5,IF((C22+D22)/2>=50,3,IF((C22+D22)/2>=40,2,IF((C22+D22)/2>=33,1,0))))))) | AD22: =IF(E22+F22<66,0,IF((E22+F22)/2>=80,5,IF((E22+F22)/2>=70,4,IF((E22+F22)/2>=60,3.5,IF((E22+F22)/2>=50,3,IF((E22+F22)/2>=40,2,IF((E22+F22)/2>=33,1,0))))))) | AE22: =IF(G22<33,0,IF(G22>=80,5,IF(G22>=70,4,IF(G22>=60,3.5,IF(G22>=50,3,IF(G22>=40,2,IF(G22>=33,1,0))))))) | AF22: =IF(H22+I22<66,0,IF((H22+I22)/2>=80,5,IF((H22+I22)/2>=70,4,IF((H22+I22)/2>=60,3.5,IF((H22+I22)/2>=50,3,IF((H22+I22)/2>=40,2,IF((H22+I22)/2>=33,1,0))))))) | AG22: =IF(Y22,0,IF((J22+K22+L22+M22)/2>=80,5,IF((J22+K22+L22+M22)/2>=70,4,IF((J22+K22+L22+M22)/2>=60,3.5,IF((J22+K22+L22+M22)/2>=50,3,IF((J22+K22+L22+M22)/2>=40,2,IF((J22+K22+L22+M22)/2>=33,1,0))))))) | AH22: =IF(Z22,0,IF(N22+O22>=80,5,IF(N22+O22>=70,4,IF(N22+O22>=60,3.5,IF(N22+O22>=50,3,IF(N22+O22>=40,2,IF(N22+O22>=33,1,0))))))) | AI22: =IF(AA22,0,IF(P22+Q22>=80,5,IF(P22+Q22>=70,4,IF(P22+Q22>=60,3.5,IF(P22+Q22>=50,3,IF(P22+Q22>=40,2,IF(P22+Q22>=33,1,0))))))) | AJ22: =IF(R22<8.25,0,IF(R22*2>=80,5,IF(R22*2>=70,4,IF(R22*2>=60,3.5,IF(R22*2>=50,3,IF(R22*2>=40,2,IF(R22*2>=33,1,0))))))) | AK22: =IF(S22<33,0,IF(S22>=80,5,IF(S22>=70,4,IF(S22>=60,3.5,IF(S22>=50,3,IF(S22>=40,2,IF(S22>=33,1,0))))))) | AL22: =(AC22+AD22+AE22+AF22+AG22+AH22+AI22+AJ22)/8 | AM22: =IF(AK22>=2,(AK22-2)/8,0)
T23: =SUM(C23:R23) | U23: =ROUND(T23/11.5,2) | V23: =IF(B23="","",IF(AB23,0,ROUND(AL23,2))) | W23: =IF(B23="","",IF(AB23,0,MIN(5,ROUND(AL23+AM23,2)))) | X23: =IF(B23="","",IF(W23>=5,"A+",IF(W23>=4,"A",IF(W23>=3.5,"A-",IF(W23>=3,"B",IF(W23>=2,"C",IF(W23>=1,"D","F"))))))) | Y23: =NOT(OR(AND(J23>=10,K23>=23,L23>=10,M23>=23),AND(J23+L23>=20,K23+M23>=46))) | Z23: =OR(N23<10,O23<23) | AA23: =OR(P23<10,Q23<23) | AB23: =OR((C23+D23)<66,(E23+F23)<66,G23<33,(H23+I23)<66,Y23,Z23,AA23,R23<8.25) | AC23: =IF(C23+D23<66,0,IF((C23+D23)/2>=80,5,IF((C23+D23)/2>=70,4,IF((C23+D23)/2>=60,3.5,IF((C23+D23)/2>=50,3,IF((C23+D23)/2>=40,2,IF((C23+D23)/2>=33,1,0))))))) | AD23: =IF(E23+F23<66,0,IF((E23+F23)/2>=80,5,IF((E23+F23)/2>=70,4,IF((E23+F23)/2>=60,3.5,IF((E23+F23)/2>=50,3,IF((E23+F23)/2>=40,2,IF((E23+F23)/2>=33,1,0))))))) | AE23: =IF(G23<33,0,IF(G23>=80,5,IF(G23>=70,4,IF(G23>=60,3.5,IF(G23>=50,3,IF(G23>=40,2,IF(G23>=33,1,0))))))) | AF23: =IF(H23+I23<66,0,IF((H23+I23)/2>=80,5,IF((H23+I23)/2>=70,4,IF((H23+I23)/2>=60,3.5,IF((H23+I23)/2>=50,3,IF((H23+I23)/2>=40,2,IF((H23+I23)/2>=33,1,0))))))) | AG23: =IF(Y23,0,IF((J23+K23+L23+M23)/2>=80,5,IF((J23+K23+L23+M23)/2>=70,4,IF((J23+K23+L23+M23)/2>=60,3.5,IF((J23+K23+L23+M23)/2>=50,3,IF((J23+K23+L23+M23)/2>=40,2,IF((J23+K23+L23+M23)/2>=33,1,0))))))) | AH23: =IF(Z23,0,IF(N23+O23>=80,5,IF(N23+O23>=70,4,IF(N23+O23>=60,3.5,IF(N23+O23>=50,3,IF(N23+O23>=40,2,IF(N23+O23>=33,1,0))))))) | AI23: =IF(AA23,0,IF(P23+Q23>=80,5,IF(P23+Q23>=70,4,IF(P23+Q23>=60,3.5,IF(P23+Q23>=50,3,IF(P23+Q23>=40,2,IF(P23+Q23>=33,1,0))))))) | AJ23: =IF(R23<8.25,0,IF(R23*2>=80,5,IF(R23*2>=70,4,IF(R23*2>=60,3.5,IF(R23*2>=50,3,IF(R23*2>=40,2,IF(R23*2>=33,1,0))))))) | AK23: =IF(S23<33,0,IF(S23>=80,5,IF(S23>=70,4,IF(S23>=60,3.5,IF(S23>=50,3,IF(S23>=40,2,IF(S23>=33,1,0))))))) | AL23: =(AC23+AD23+AE23+AF23+AG23+AH23+AI23+AJ23)/8 | AM23: =IF(AK23>=2,(AK23-2)/8,0)
T24: =SUM(C24:R24) | U24: =ROUND(T24/11.5,2) | V24: =IF(B24="","",IF(AB24,0,ROUND(AL24,2))) | W24: =IF(B24="","",IF(AB24,0,MIN(5,ROUND(AL24+AM24,2)))) | X24: =IF(B24="","",IF(W24>=5,"A+",IF(W24>=4,"A",IF(W24>=3.5,"A-",IF(W24>=3,"B",IF(W24>=2,"C",IF(W24>=1,"D","F"))))))) | Y24: =NOT(OR(AND(J24>=10,K24>=23,L24>=10,M24>=23),AND(J24+L24>=20,K24+M24>=46))) | Z24: =OR(N24<10,O24<23) | AA24: =OR(P24<10,Q24<23) | AB24: =OR((C24+D24)<66,(E24+F24)<66,G24<33,(H24+I24)<66,Y24,Z24,AA24,R24<8.25) | AC24: =IF(C24+D24<66,0,IF((C24+D24)/2>=80,5,IF((C24+D24)/2>=70,4,IF((C24+D24)/2>=60,3.5,IF((C24+D24)/2>=50,3,IF((C24+D24)/2>=40,2,IF((C24+D24)/2>=33,1,0))))))) | AD24: =IF(E24+F24<66,0,IF((E24+F24)/2>=80,5,IF((E24+F24)/2>=70,4,IF((E24+F24)/2>=60,3.5,IF((E24+F24)/2>=50,3,IF((E24+F24)/2>=40,2,IF((E24+F24)/2>=33,1,0))))))) | AE24: =IF(G24<33,0,IF(G24>=80,5,IF(G24>=70,4,IF(G24>=60,3.5,IF(G24>=50,3,IF(G24>=40,2,IF(G24>=33,1,0))))))) | AF24: =IF(H24+I24<66,0,IF((H24+I24)/2>=80,5,IF((H24+I24)/2>=70,4,IF((H24+I24)/2>=60,3.5,IF((H24+I24)/2>=50,3,IF((H24+I24)/2>=40,2,IF((H24+I24)/2>=33,1,0))))))) | AG24: =IF(Y24,0,IF((J24+K24+L24+M24)/2>=80,5,IF((J24+K24+L24+M24)/2>=70,4,IF((J24+K24+L24+M24)/2>=60,3.5,IF((J24+K24+L24+M24)/2>=50,3,IF((J24+K24+L24+M24)/2>=40,2,IF((J24+K24+L24+M24)/2>=33,1,0))))))) | AH24: =IF(Z24,0,IF(N24+O24>=80,5,IF(N24+O24>=70,4,IF(N24+O24>=60,3.5,IF(N24+O24>=50,3,IF(N24+O24>=40,2,IF(N24+O24>=33,1,0))))))) | AI24: =IF(AA24,0,IF(P24+Q24>=80,5,IF(P24+Q24>=70,4,IF(P24+Q24>=60,3.5,IF(P24+Q24>=50,3,IF(P24+Q24>=40,2,IF(P24+Q24>=33,1,0))))))) | AJ24: =IF(R24<8.25,0,IF(R24*2>=80,5,IF(R24*2>=70,4,IF(R24*2>=60,3.5,IF(R24*2>=50,3,IF(R24*2>=40,2,IF(R24*2>=33,1,0))))))) | AK24: =IF(S24<33,0,IF(S24>=80,5,IF(S24>=70,4,IF(S24>=60,3.5,IF(S24>=50,3,IF(S24>=40,2,IF(S24>=33,1,0))))))) | AL24: =(AC24+AD24+AE24+AF24+AG24+AH24+AI24+AJ24)/8 | AM24: =IF(AK24>=2,(AK24-2)/8,0)
T25: =SUM(C25:R25) | U25: =ROUND(T25/11.5,2) | V25: =IF(B25="","",IF(AB25,0,ROUND(AL25,2))) | W25: =IF(B25="","",IF(AB25,0,MIN(5,ROUND(AL25+AM25,2)))) | X25: =IF(B25="","",IF(W25>=5,"A+",IF(W25>=4,"A",IF(W25>=3.5,"A-",IF(W25>=3,"B",IF(W25>=2,"C",IF(W25>=1,"D","F"))))))) | Y25: =NOT(OR(AND(J25>=10,K25>=23,L25>=10,M25>=23),AND(J25+L25>=20,K25+M25>=46))) | Z25: =OR(N25<10,O25<23) | AA25: =OR(P25<10,Q25<23) | AB25: =OR((C25+D25)<66,(E25+F25)<66,G25<33,(H25+I25)<66,Y25,Z25,AA25,R25<8.25) | AC25: =IF(C25+D25<66,0,IF((C25+D25)/2>=80,5,IF((C25+D25)/2>=70,4,IF((C25+D25)/2>=60,3.5,IF((C25+D25)/2>=50,3,IF((C25+D25)/2>=40,2,IF((C25+D25)/2>=33,1,0))))))) | AD25: =IF(E25+F25<66,0,IF((E25+F25)/2>=80,5,IF((E25+F25)/2>=70,4,IF((E25+F25)/2>=60,3.5,IF((E25+F25)/2>=50,3,IF((E25+F25)/2>=40,2,IF((E25+F25)/2>=33,1,0))))))) | AE25: =IF(G25<33,0,IF(G25>=80,5,IF(G25>=70,4,IF(G25>=60,3.5,IF(G25>=50,3,IF(G25>=40,2,IF(G25>=33,1,0))))))) | AF25: =IF(H25+I25<66,0,IF((H25+I25)/2>=80,5,IF((H25+I25)/2>=70,4,IF((H25+I25)/2>=60,3.5,IF((H25+I25)/2>=50,3,IF((H25+I25)/2>=40,2,IF((H25+I25)/2>=33,1,0))))))) | AG25: =IF(Y25,0,IF((J25+K25+L25+M25)/2>=80,5,IF((J25+K25+L25+M25)/2>=70,4,IF((J25+K25+L25+M25)/2>=60,3.5,IF((J25+K25+L25+M25)/2>=50,3,IF((J25+K25+L25+M25)/2>=40,2,IF((J25+K25+L25+M25)/2>=33,1,0))))))) | AH25: =IF(Z25,0,IF(N25+O25>=80,5,IF(N25+O25>=70,4,IF(N25+O25>=60,3.5,IF(N25+O25>=50,3,IF(N25+O25>=40,2,IF(N25+O25>=33,1,0))))))) | AI25: =IF(AA25,0,IF(P25+Q25>=80,5,IF(P25+Q25>=70,4,IF(P25+Q25>=60,3.5,IF(P25+Q25>=50,3,IF(P25+Q25>=40,2,IF(P25+Q25>=33,1,0))))))) | AJ25: =IF(R25<8.25,0,IF(R25*2>=80,5,IF(R25*2>=70,4,IF(R25*2>=60,3.5,IF(R25*2>=50,3,IF(R25*2>=40,2,IF(R25*2>=33,1,0))))))) | AK25: =IF(S25<33,0,IF(S25>=80,5,IF(S25>=70,4,IF(S25>=60,3.5,IF(S25>=50,3,IF(S25>=40,2,IF(S25>=33,1,0))))))) | AL25: =(AC25+AD25+AE25+AF25+AG25+AH25+AI25+AJ25)/8 | AM25: =IF(AK25>=2,(AK25-2)/8,0)
T26: =SUM(C26:R26) | U26: =ROUND(T26/11.5,2) | V26: =IF(B26="","",IF(AB26,0,ROUND(AL26,2))) | W26: =IF(B26="","",IF(AB26,0,MIN(5,ROUND(AL26+AM26,2)))) | X26: =IF(B26="","",IF(W26>=5,"A+",IF(W26>=4,"A",IF(W26>=3.5,"A-",IF(W26>=3,"B",IF(W26>=2,"C",IF(W26>=1,"D","F"))))))) | Y26: =NOT(OR(AND(J26>=10,K26>=23,L26>=10,M26>=23),AND(J26+L26>=20,K26+M26>=46))) | Z26: =OR(N26<10,O26<23) | AA26: =OR(P26<10,Q26<23) | AB26: =OR((C26+D26)<66,(E26+F26)<66,G26<33,(H26+I26)<66,Y26,Z26,AA26,R26<8.25) | AC26: =IF(C26+D26<66,0,IF((C26+D26)/2>=80,5,IF((C26+D26)/2>=70,4,IF((C26+D26)/2>=60,3.5,IF((C26+D26)/2>=50,3,IF((C26+D26)/2>=40,2,IF((C26+D26)/2>=33,1,0))))))) | AD26: =IF(E26+F26<66,0,IF((E26+F26)/2>=80,5,IF((E26+F26)/2>=70,4,IF((E26+F26)/2>=60,3.5,IF((E26+F26)/2>=50,3,IF((E26+F26)/2>=40,2,IF((E26+F26)/2>=33,1,0))))))) | AE26: =IF(G26<33,0,IF(G26>=80,5,IF(G26>=70,4,IF(G26>=60,3.5,IF(G26>=50,3,IF(G26>=40,2,IF(G26>=33,1,0))))))) | AF26: =IF(H26+I26<66,0,IF((H26+I26)/2>=80,5,IF((H26+I26)/2>=70,4,IF((H26+I26)/2>=60,3.5,IF((H26+I26)/2>=50,3,IF((H26+I26)/2>=40,2,IF((H26+I26)/2>=33,1,0))))))) | AG26: =IF(Y26,0,IF((J26+K26+L26+M26)/2>=80,5,IF((J26+K26+L26+M26)/2>=70,4,IF((J26+K26+L26+M26)/2>=60,3.5,IF((J26+K26+L26+M26)/2>=50,3,IF((J26+K26+L26+M26)/2>=40,2,IF((J26+K26+L26+M26)/2>=33,1,0))))))) | AH26: =IF(Z26,0,IF(N26+O26>=80,5,IF(N26+O26>=70,4,IF(N26+O26>=60,3.5,IF(N26+O26>=50,3,IF(N26+O26>=40,2,IF(N26+O26>=33,1,0))))))) | AI26: =IF(AA26,0,IF(P26+Q26>=80,5,IF(P26+Q26>=70,4,IF(P26+Q26>=60,3.5,IF(P26+Q26>=50,3,IF(P26+Q26>=40,2,IF(P26+Q26>=33,1,0))))))) | AJ26: =IF(R26<8.25,0,IF(R26*2>=80,5,IF(R26*2>=70,4,IF(R26*2>=60,3.5,IF(R26*2>=50,3,IF(R26*2>=40,2,IF(R26*2>=33,1,0))))))) | AK26: =IF(S26<33,0,IF(S26>=80,5,IF(S26>=70,4,IF(S26>=60,3.5,IF(S26>=50,3,IF(S26>=40,2,IF(S26>=33,1,0))))))) | AL26: =(AC26+AD26+AE26+AF26+AG26+AH26+AI26+AJ26)/8 | AM26: =IF(AK26>=2,(AK26-2)/8,0)
T27: =SUM(C27:R27) | U27: =ROUND(T27/11.5,2) | V27: =IF(B27="","",IF(AB27,0,ROUND(AL27,2))) | W27: =IF(B27="","",IF(AB27,0,MIN(5,ROUND(AL27+AM27,2)))) | X27: =IF(B27="","",IF(W27>=5,"A+",IF(W27>=4,"A",IF(W27>=3.5,"A-",IF(W27>=3,"B",IF(W27>=2,"C",IF(W27>=1,"D","F"))))))) | Y27: =NOT(OR(AND(J27>=10,K27>=23,L27>=10,M27>=23),AND(J27+L27>=20,K27+M27>=46))) | Z27: =OR(N27<10,O27<23) | AA27: =OR(P27<10,Q27<23) | AB27: =OR((C27+D27)<66,(E27+F27)<66,G27<33,(H27+I27)<66,Y27,Z27,AA27,R27<8.25) | AC27: =IF(C27+D27<66,0,IF((C27+D27)/2>=80,5,IF((C27+D27)/2>=70,4,IF((C27+D27)/2>=60,3.5,IF((C27+D27)/2>=50,3,IF((C27+D27)/2>=40,2,IF((C27+D27)/2>=33,1,0))))))) | AD27: =IF(E27+F27<66,0,IF((E27+F27)/2>=80,5,IF((E27+F27)/2>=70,4,IF((E27+F27)/2>=60,3.5,IF((E27+F27)/2>=50,3,IF((E27+F27)/2>=40,2,IF((E27+F27)/2>=33,1,0))))))) | AE27: =IF(G27<33,0,IF(G27>=80,5,IF(G27>=70,4,IF(G27>=60,3.5,IF(G27>=50,3,IF(G27>=40,2,IF(G27>=33,1,0))))))) | AF27: =IF(H27+I27<66,0,IF((H27+I27)/2>=80,5,IF((H27+I27)/2>=70,4,IF((H27+I27)/2>=60,3.5,IF((H27+I27)/2>=50,3,IF((H27+I27)/2>=40,2,IF((H27+I27)/2>=33,1,0))))))) | AG27: =IF(Y27,0,IF((J27+K27+L27+M27)/2>=80,5,IF((J27+K27+L27+M27)/2>=70,4,IF((J27+K27+L27+M27)/2>=60,3.5,IF((J27+K27+L27+M27)/2>=50,3,IF((J27+K27+L27+M27)/2>=40,2,IF((J27+K27+L27+M27)/2>=33,1,0))))))) | AH27: =IF(Z27,0,IF(N27+O27>=80,5,IF(N27+O27>=70,4,IF(N27+O27>=60,3.5,IF(N27+O27>=50,3,IF(N27+O27>=40,2,IF(N27+O27>=33,1,0))))))) | AI27: =IF(AA27,0,IF(P27+Q27>=80,5,IF(P27+Q27>=70,4,IF(P27+Q27>=60,3.5,IF(P27+Q27>=50,3,IF(P27+Q27>=40,2,IF(P27+Q27>=33,1,0))))))) | AJ27: =IF(R27<8.25,0,IF(R27*2>=80,5,IF(R27*2>=70,4,IF(R27*2>=60,3.5,IF(R27*2>=50,3,IF(R27*2>=40,2,IF(R27*2>=33,1,0))))))) | AK27: =IF(S27<33,0,IF(S27>=80,5,IF(S27>=70,4,IF(S27>=60,3.5,IF(S27>=50,3,IF(S27>=40,2,IF(S27>=33,1,0))))))) | AL27: =(AC27+AD27+AE27+AF27+AG27+AH27+AI27+AJ27)/8 | AM27: =IF(AK27>=2,(AK27-2)/8,0)
T28: =SUM(C28:R28) | U28: =ROUND(T28/11.5,2) | V28: =IF(B28="","",IF(AB28,0,ROUND(AL28,2))) | W28: =IF(B28="","",IF(AB28,0,MIN(5,ROUND(AL28+AM28,2)))) | X28: =IF(B28="","",IF(W28>=5,"A+",IF(W28>=4,"A",IF(W28>=3.5,"A-",IF(W28>=3,"B",IF(W28>=2,"C",IF(W28>=1,"D","F"))))))) | Y28: =NOT(OR(AND(J28>=10,K28>=23,L28>=10,M28>=23),AND(J28+L28>=20,K28+M28>=46))) | Z28: =OR(N28<10,O28<23) | AA28: =OR(P28<10,Q28<23) | AB28: =OR((C28+D28)<66,(E28+F28)<66,G28<33,(H28+I28)<66,Y28,Z28,AA28,R28<8.25) | AC28: =IF(C28+D28<66,0,IF((C28+D28)/2>=80,5,IF((C28+D28)/2>=70,4,IF((C28+D28)/2>=60,3.5,IF((C28+D28)/2>=50,3,IF((C28+D28)/2>=40,2,IF((C28+D28)/2>=33,1,0))))))) | AD28: =IF(E28+F28<66,0,IF((E28+F28)/2>=80,5,IF((E28+F28)/2>=70,4,IF((E28+F28)/2>=60,3.5,IF((E28+F28)/2>=50,3,IF((E28+F28)/2>=40,2,IF((E28+F28)/2>=33,1,0))))))) | AE28: =IF(G28<33,0,IF(G28>=80,5,IF(G28>=70,4,IF(G28>=60,3.5,IF(G28>=50,3,IF(G28>=40,2,IF(G28>=33,1,0))))))) | AF28: =IF(H28+I28<66,0,IF((H28+I28)/2>=80,5,IF((H28+I28)/2>=70,4,IF((H28+I28)/2>=60,3.5,IF((H28+I28)/2>=50,3,IF((H28+I28)/2>=40,2,IF((H28+I28)/2>=33,1,0))))))) | AG28: =IF(Y28,0,IF((J28+K28+L28+M28)/2>=80,5,IF((J28+K28+L28+M28)/2>=70,4,IF((J28+K28+L28+M28)/2>=60,3.5,IF((J28+K28+L28+M28)/2>=50,3,IF((J28+K28+L28+M28)/2>=40,2,IF((J28+K28+L28+M28)/2>=33,1,0))))))) | AH28: =IF(Z28,0,IF(N28+O28>=80,5,IF(N28+O28>=70,4,IF(N28+O28>=60,3.5,IF(N28+O28>=50,3,IF(N28+O28>=40,2,IF(N28+O28>=33,1,0))))))) | AI28: =IF(AA28,0,IF(P28+Q28>=80,5,IF(P28+Q28>=70,4,IF(P28+Q28>=60,3.5,IF(P28+Q28>=50,3,IF(P28+Q28>=40,2,IF(P28+Q28>=33,1,0))))))) | AJ28: =IF(R28<8.25,0,IF(R28*2>=80,5,IF(R28*2>=70,4,IF(R28*2>=60,3.5,IF(R28*2>=50,3,IF(R28*2>=40,2,IF(R28*2>=33,1,0))))))) | AK28: =IF(S28<33,0,IF(S28>=80,5,IF(S28>=70,4,IF(S28>=60,3.5,IF(S28>=50,3,IF(S28>=40,2,IF(S28>=33,1,0))))))) | AL28: =(AC28+AD28+AE28+AF28+AG28+AH28+AI28+AJ28)/8 | AM28: =IF(AK28>=2,(AK28-2)/8,0)
T29: =SUM(C29:R29) | U29: =ROUND(T29/11.5,2) | V29: =IF(B29="","",IF(AB29,0,ROUND(AL29,2))) | W29: =IF(B29="","",IF(AB29,0,MIN(5,ROUND(AL29+AM29,2)))) | X29: =IF(B29="","",IF(W29>=5,"A+",IF(W29>=4,"A",IF(W29>=3.5,"A-",IF(W29>=3,"B",IF(W29>=2,"C",IF(W29>=1,"D","F"))))))) | Y29: =NOT(OR(AND(J29>=10,K29>=23,L29>=10,M29>=23),AND(J29+L29>=20,K29+M29>=46))) | Z29: =OR(N29<10,O29<23) | AA29: =OR(P29<10,Q29<23) | AB29: =OR((C29+D29)<66,(E29+F29)<66,G29<33,(H29+I29)<66,Y29,Z29,AA29,R29<8.25) | AC29: =IF(C29+D29<66,0,IF((C29+D29)/2>=80,5,IF((C29+D29)/2>=70,4,IF((C29+D29)/2>=60,3.5,IF((C29+D29)/2>=50,3,IF((C29+D29)/2>=40,2,IF((C29+D29)/2>=33,1,0))))))) | AD29: =IF(E29+F29<66,0,IF((E29+F29)/2>=80,5,IF((E29+F29)/2>=70,4,IF((E29+F29)/2>=60,3.5,IF((E29+F29)/2>=50,3,IF((E29+F29)/2>=40,2,IF((E29+F29)/2>=33,1,0))))))) | AE29: =IF(G29<33,0,IF(G29>=80,5,IF(G29>=70,4,IF(G29>=60,3.5,IF(G29>=50,3,IF(G29>=40,2,IF(G29>=33,1,0))))))) | AF29: =IF(H29+I29<66,0,IF((H29+I29)/2>=80,5,IF((H29+I29)/2>=70,4,IF((H29+I29)/2>=60,3.5,IF((H29+I29)/2>=50,3,IF((H29+I29)/2>=40,2,IF((H29+I29)/2>=33,1,0))))))) | AG29: =IF(Y29,0,IF((J29+K29+L29+M29)/2>=80,5,IF((J29+K29+L29+M29)/2>=70,4,IF((J29+K29+L29+M29)/2>=60,3.5,IF((J29+K29+L29+M29)/2>=50,3,IF((J29+K29+L29+M29)/2>=40,2,IF((J29+K29+L29+M29)/2>=33,1,0))))))) | AH29: =IF(Z29,0,IF(N29+O29>=80,5,IF(N29+O29>=70,4,IF(N29+O29>=60,3.5,IF(N29+O29>=50,3,IF(N29+O29>=40,2,IF(N29+O29>=33,1,0))))))) | AI29: =IF(AA29,0,IF(P29+Q29>=80,5,IF(P29+Q29>=70,4,IF(P29+Q29>=60,3.5,IF(P29+Q29>=50,3,IF(P29+Q29>=40,2,IF(P29+Q29>=33,1,0))))))) | AJ29: =IF(R29<8.25,0,IF(R29*2>=80,5,IF(R29*2>=70,4,IF(R29*2>=60,3.5,IF(R29*2>=50,3,IF(R29*2>=40,2,IF(R29*2>=33,1,0))))))) | AK29: =IF(S29<33,0,IF(S29>=80,5,IF(S29>=70,4,IF(S29>=60,3.5,IF(S29>=50,3,IF(S29>=40,2,IF(S29>=33,1,0))))))) | AL29: =(AC29+AD29+AE29+AF29+AG29+AH29+AI29+AJ29)/8 | AM29: =IF(AK29>=2,(AK29-2)/8,0)
T30: =SUM(C30:R30) | U30: =ROUND(T30/11.5,2) | V30: =IF(B30="","",IF(AB30,0,ROUND(AL30,2))) | W30: =IF(B30="","",IF(AB30,0,MIN(5,ROUND(AL30+AM30,2)))) | X30: =IF(B30="","",IF(W30>=5,"A+",IF(W30>=4,"A",IF(W30>=3.5,"A-",IF(W30>=3,"B",IF(W30>=2,"C",IF(W30>=1,"D","F"))))))) | Y30: =NOT(OR(AND(J30>=10,K30>=23,L30>=10,M30>=23),AND(J30+L30>=20,K30+M30>=46))) | Z30: =OR(N30<10,O30<23) | AA30: =OR(P30<10,Q30<23) | AB30: =OR((C30+D30)<66,(E30+F30)<66,G30<33,(H30+I30)<66,Y30,Z30,AA30,R30<8.25) | AC30: =IF(C30+D30<66,0,IF((C30+D30)/2>=80,5,IF((C30+D30)/2>=70,4,IF((C30+D30)/2>=60,3.5,IF((C30+D30)/2>=50,3,IF((C30+D30)/2>=40,2,IF((C30+D30)/2>=33,1,0))))))) | AD30: =IF(E30+F30<66,0,IF((E30+F30)/2>=80,5,IF((E30+F30)/2>=70,4,IF((E30+F30)/2>=60,3.5,IF((E30+F30)/2>=50,3,IF((E30+F30)/2>=40,2,IF((E30+F30)/2>=33,1,0))))))) | AE30: =IF(G30<33,0,IF(G30>=80,5,IF(G30>=70,4,IF(G30>=60,3.5,IF(G30>=50,3,IF(G30>=40,2,IF(G30>=33,1,0))))))) | AF30: =IF(H30+I30<66,0,IF((H30+I30)/2>=80,5,IF((H30+I30)/2>=70,4,IF((H30+I30)/2>=60,3.5,IF((H30+I30)/2>=50,3,IF((H30+I30)/2>=40,2,IF((H30+I30)/2>=33,1,0))))))) | AG30: =IF(Y30,0,IF((J30+K30+L30+M30)/2>=80,5,IF((J30+K30+L30+M30)/2>=70,4,IF((J30+K30+L30+M30)/2>=60,3.5,IF((J30+K30+L30+M30)/2>=50,3,IF((J30+K30+L30+M30)/2>=40,2,IF((J30+K30+L30+M30)/2>=33,1,0))))))) | AH30: =IF(Z30,0,IF(N30+O30>=80,5,IF(N30+O30>=70,4,IF(N30+O30>=60,3.5,IF(N30+O30>=50,3,IF(N30+O30>=40,2,IF(N30+O30>=33,1,0))))))) | AI30: =IF(AA30,0,IF(P30+Q30>=80,5,IF(P30+Q30>=70,4,IF(P30+Q30>=60,3.5,IF(P30+Q30>=50,3,IF(P30+Q30>=40,2,IF(P30+Q30>=33,1,0))))))) | AJ30: =IF(R30<8.25,0,IF(R30*2>=80,5,IF(R30*2>=70,4,IF(R30*2>=60,3.5,IF(R30*2>=50,3,IF(R30*2>=40,2,IF(R30*2>=33,1,0))))))) | AK30: =IF(S30<33,0,IF(S30>=80,5,IF(S30>=70,4,IF(S30>=60,3.5,IF(S30>=50,3,IF(S30>=40,2,IF(S30>=33,1,0))))))) | AL30: =(AC30+AD30+AE30+AF30+AG30+AH30+AI30+AJ30)/8 | AM30: =IF(AK30>=2,(AK30-2)/8,0)
T31: =SUM(C31:R31) | U31: =ROUND(T31/11.5,2) | V31: =IF(B31="","",IF(AB31,0,ROUND(AL31,2))) | W31: =IF(B31="","",IF(AB31,0,MIN(5,ROUND(AL31+AM31,2)))) | X31: =IF(B31="","",IF(W31>=5,"A+",IF(W31>=4,"A",IF(W31>=3.5,"A-",IF(W31>=3,"B",IF(W31>=2,"C",IF(W31>=1,"D","F"))))))) | Y31: =NOT(OR(AND(J31>=10,K31>=23,L31>=10,M31>=23),AND(J31+L31>=20,K31+M31>=46))) | Z31: =OR(N31<10,O31<23) | AA31: =OR(P31<10,Q31<23) | AB31: =OR((C31+D31)<66,(E31+F31)<66,G31<33,(H31+I31)<66,Y31,Z31,AA31,R31<8.25) | AC31: =IF(C31+D31<66,0,IF((C31+D31)/2>=80,5,IF((C31+D31)/2>=70,4,IF((C31+D31)/2>=60,3.5,IF((C31+D31)/2>=50,3,IF((C31+D31)/2>=40,2,IF((C31+D31)/2>=33,1,0))))))) | AD31: =IF(E31+F31<66,0,IF((E31+F31)/2>=80,5,IF((E31+F31)/2>=70,4,IF((E31+F31)/2>=60,3.5,IF((E31+F31)/2>=50,3,IF((E31+F31)/2>=40,2,IF((E31+F31)/2>=33,1,0))))))) | AE31: =IF(G31<33,0,IF(G31>=80,5,IF(G31>=70,4,IF(G31>=60,3.5,IF(G31>=50,3,IF(G31>=40,2,IF(G31>=33,1,0))))))) | AF31: =IF(H31+I31<66,0,IF((H31+I31)/2>=80,5,IF((H31+I31)/2>=70,4,IF((H31+I31)/2>=60,3.5,IF((H31+I31)/2>=50,3,IF((H31+I31)/2>=40,2,IF((H31+I31)/2>=33,1,0))))))) | AG31: =IF(Y31,0,IF((J31+K31+L31+M31)/2>=80,5,IF((J31+K31+L31+M31)/2>=70,4,IF((J31+K31+L31+M31)/2>=60,3.5,IF((J31+K31+L31+M31)/2>=50,3,IF((J31+K31+L31+M31)/2>=40,2,IF((J31+K31+L31+M31)/2>=33,1,0))))))) | AH31: =IF(Z31,0,IF(N31+O31>=80,5,IF(N31+O31>=70,4,IF(N31+O31>=60,3.5,IF(N31+O31>=50,3,IF(N31+O31>=40,2,IF(N31+O31>=33,1,0))))))) | AI31: =IF(AA31,0,IF(P31+Q31>=80,5,IF(P31+Q31>=70,4,IF(P31+Q31>=60,3.5,IF(P31+Q31>=50,3,IF(P31+Q31>=40,2,IF(P31+Q31>=33,1,0))))))) | AJ31: =IF(R31<8.25,0,IF(R31*2>=80,5,IF(R31*2>=70,4,IF(R31*2>=60,3.5,IF(R31*2>=50,3,IF(R31*2>=40,2,IF(R31*2>=33,1,0))))))) | AK31: =IF(S31<33,0,IF(S31>=80,5,IF(S31>=70,4,IF(S31>=60,3.5,IF(S31>=50,3,IF(S31>=40,2,IF(S31>=33,1,0))))))) | AL31: =(AC31+AD31+AE31+AF31+AG31+AH31+AI31+AJ31)/8 | AM31: =IF(AK31>=2,(AK31-2)/8,0)
T32: =SUM(C32:R32) | U32: =ROUND(T32/11.5,2) | V32: =IF(B32="","",IF(AB32,0,ROUND(AL32,2))) | W32: =IF(B32="","",IF(AB32,0,MIN(5,ROUND(AL32+AM32,2)))) | X32: =IF(B32="","",IF(W32>=5,"A+",IF(W32>=4,"A",IF(W32>=3.5,"A-",IF(W32>=3,"B",IF(W32>=2,"C",IF(W32>=1,"D","F"))))))) | Y32: =NOT(OR(AND(J32>=10,K32>=23,L32>=10,M32>=23),AND(J32+L32>=20,K32+M32>=46))) | Z32: =OR(N32<10,O32<23) | AA32: =OR(P32<10,Q32<23) | AB32: =OR((C32+D32)<66,(E32+F32)<66,G32<33,(H32+I32)<66,Y32,Z32,AA32,R32<8.25) | AC32: =IF(C32+D32<66,0,IF((C32+D32)/2>=80,5,IF((C32+D32)/2>=70,4,IF((C32+D32)/2>=60,3.5,IF((C32+D32)/2>=50,3,IF((C32+D32)/2>=40,2,IF((C32+D32)/2>=33,1,0))))))) | AD32: =IF(E32+F32<66,0,IF((E32+F32)/2>=80,5,IF((E32+F32)/2>=70,4,IF((E32+F32)/2>=60,3.5,IF((E32+F32)/2>=50,3,IF((E32+F32)/2>=40,2,IF((E32+F32)/2>=33,1,0))))))) | AE32: =IF(G32<33,0,IF(G32>=80,5,IF(G32>=70,4,IF(G32>=60,3.5,IF(G32>=50,3,IF(G32>=40,2,IF(G32>=33,1,0))))))) | AF32: =IF(H32+I32<66,0,IF((H32+I32)/2>=80,5,IF((H32+I32)/2>=70,4,IF((H32+I32)/2>=60,3.5,IF((H32+I32)/2>=50,3,IF((H32+I32)/2>=40,2,IF((H32+I32)/2>=33,1,0))))))) | AG32: =IF(Y32,0,IF((J32+K32+L32+M32)/2>=80,5,IF((J32+K32+L32+M32)/2>=70,4,IF((J32+K32+L32+M32)/2>=60,3.5,IF((J32+K32+L32+M32)/2>=50,3,IF((J32+K32+L32+M32)/2>=40,2,IF((J32+K32+L32+M32)/2>=33,1,0))))))) | AH32: =IF(Z32,0,IF(N32+O32>=80,5,IF(N32+O32>=70,4,IF(N32+O32>=60,3.5,IF(N32+O32>=50,3,IF(N32+O32>=40,2,IF(N32+O32>=33,1,0))))))) | AI32: =IF(AA32,0,IF(P32+Q32>=80,5,IF(P32+Q32>=70,4,IF(P32+Q32>=60,3.5,IF(P32+Q32>=50,3,IF(P32+Q32>=40,2,IF(P32+Q32>=33,1,0))))))) | AJ32: =IF(R32<8.25,0,IF(R32*2>=80,5,IF(R32*2>=70,4,IF(R32*2>=60,3.5,IF(R32*2>=50,3,IF(R32*2>=40,2,IF(R32*2>=33,1,0))))))) | AK32: =IF(S32<33,0,IF(S32>=80,5,IF(S32>=70,4,IF(S32>=60,3.5,IF(S32>=50,3,IF(S32>=40,2,IF(S32>=33,1,0))))))) | AL32: =(AC32+AD32+AE32+AF32+AG32+AH32+AI32+AJ32)/8 | AM32: =IF(AK32>=2,(AK32-2)/8,0)
T33: =SUM(C33:R33) | U33: =ROUND(T33/11.5,2) | V33: =IF(B33="","",IF(AB33,0,ROUND(AL33,2))) | W33: =IF(B33="","",IF(AB33,0,MIN(5,ROUND(AL33+AM33,2)))) | X33: =IF(B33="","",IF(W33>=5,"A+",IF(W33>=4,"A",IF(W33>=3.5,"A-",IF(W33>=3,"B",IF(W33>=2,"C",IF(W33>=1,"D","F"))))))) | Y33: =NOT(OR(AND(J33>=10,K33>=23,L33>=10,M33>=23),AND(J33+L33>=20,K33+M33>=46))) | Z33: =OR(N33<10,O33<23) | AA33: =OR(P33<10,Q33<23) | AB33: =OR((C33+D33)<66,(E33+F33)<66,G33<33,(H33+I33)<66,Y33,Z33,AA33,R33<8.25) | AC33: =IF(C33+D33<66,0,IF((C33+D33)/2>=80,5,IF((C33+D33)/2>=70,4,IF((C33+D33)/2>=60,3.5,IF((C33+D33)/2>=50,3,IF((C33+D33)/2>=40,2,IF((C33+D33)/2>=33,1,0))))))) | AD33: =IF(E33+F33<66,0,IF((E33+F33)/2>=80,5,IF((E33+F33)/2>=70,4,IF((E33+F33)/2>=60,3.5,IF((E33+F33)/2>=50,3,IF((E33+F33)/2>=40,2,IF((E33+F33)/2>=33,1,0))))))) | AE33: =IF(G33<33,0,IF(G33>=80,5,IF(G33>=70,4,IF(G33>=60,3.5,IF(G33>=50,3,IF(G33>=40,2,IF(G33>=33,1,0))))))) | AF33: =IF(H33+I33<66,0,IF((H33+I33)/2>=80,5,IF((H33+I33)/2>=70,4,IF((H33+I33)/2>=60,3.5,IF((H33+I33)/2>=50,3,IF((H33+I33)/2>=40,2,IF((H33+I33)/2>=33,1,0))))))) | AG33: =IF(Y33,0,IF((J33+K33+L33+M33)/2>=80,5,IF((J33+K33+L33+M33)/2>=70,4,IF((J33+K33+L33+M33)/2>=60,3.5,IF((J33+K33+L33+M33)/2>=50,3,IF((J33+K33+L33+M33)/2>=40,2,IF((J33+K33+L33+M33)/2>=33,1,0))))))) | AH33: =IF(Z33,0,IF(N33+O33>=80,5,IF(N33+O33>=70,4,IF(N33+O33>=60,3.5,IF(N33+O33>=50,3,IF(N33+O33>=40,2,IF(N33+O33>=33,1,0))))))) | AI33: =IF(AA33,0,IF(P33+Q33>=80,5,IF(P33+Q33>=70,4,IF(P33+Q33>=60,3.5,IF(P33+Q33>=50,3,IF(P33+Q33>=40,2,IF(P33+Q33>=33,1,0))))))) | AJ33: =IF(R33<8.25,0,IF(R33*2>=80,5,IF(R33*2>=70,4,IF(R33*2>=60,3.5,IF(R33*2>=50,3,IF(R33*2>=40,2,IF(R33*2>=33,1,0))))))) | AK33: =IF(S33<33,0,IF(S33>=80,5,IF(S33>=70,4,IF(S33>=60,3.5,IF(S33>=50,3,IF(S33>=40,2,IF(S33>=33,1,0))))))) | AL33: =(AC33+AD33+AE33+AF33+AG33+AH33+AI33+AJ33)/8 | AM33: =IF(AK33>=2,(AK33-2)/8,0)
... T1001: =SUM(C1001:R1001) | U1001: =ROUND(T1001/11.5,2) | V1001: =IF(B1001="","",IF(AB1001,0,ROUND(AL1001,2))) | W1001: =IF(B1001="","",IF(AB1001,0,MIN(5,ROUND(AL1001+AM1001,2)))) | X1001: =IF(B1001="","",IF(W1001>=5,"A+",IF(W1001>=4,"A",IF(W1001>=3.5,"A-",IF(W1001>=3,"B",IF(W1001>=2,"C",IF(W1001>=1,"D","F"))))))) | Y1001: =NOT(OR(AND(J1001>=10,K1001>=23,L1001>=10,M1001>=23),AND(J1001+L1001>=20,K1001+M1001>=46))) | Z1001: =OR(N1001<10,O1001<23) | AA1001: =OR(P1001<10,Q1001<23) | AB1001: =OR((C1001+D1001)<66,(E1001+F1001)<66,G1001<33,(H1001+I1001)<66,Y1001,Z1001,AA1001,R1001<8.25) | AC1001: =IF(C1001+D1001<66,0,IF((C1001+D1001)/2>=80,5,IF((C1001+D1001)/2>=70,4,IF((C1001+D1001)/2>=60,3.5,IF((C1001+D1001)/2>=50,3,IF((C1001+D1001)/2>=40,2,IF((C1001+D1001)/2>=33,1,0))))))) | AD1001: =IF(E1001+F1001<66,0,IF((E1001+F1001)/2>=80,5,IF((E1001+F1001)/2>=70,4,IF((E1001+F1001)/2>=60,3.5,IF((E1001+F1001)/2>=50,3,IF((E1001+F1001)/2>=40,2,IF((E1001+F1001)/2>=33,1,0))))))) | AE1001: =IF(G1001<33,0,IF(G1001>=80,5,IF(G1001>=70,4,IF(G1001>=60,3.5,IF(G1001>=50,3,IF(G1001>=40,2,IF(G1001>=33,1,0))))))) | AF1001: =IF(H1001+I1001<66,0,IF((H1001+I1001)/2>=80,5,IF((H1001+I1001)/2>=70,4,IF((H1001+I1001)/2>=60,3.5,IF((H1001+I1001)/2>=50,3,IF((H1001+I1001)/2>=40,2,IF((H1001+I1001)/2>=33,1,0))))))) | AG1001: =IF(Y1001,0,IF((J1001+K1001+L1001+M1001)/2>=80,5,IF((J1001+K1001+L1001+M1001)/2>=70,4,IF((J1001+K1001+L1001+M1001)/2>=60,3.5,IF((J1001+K1001+L1001+M1001)/2>=50,3,IF((J1001+K1001+L1001+M1001)/2>=40,2,IF((J1001+K1001+L1001+M1001)/2>=33,1,0))))))) | AH1001: =IF(Z1001,0,IF(N1001+O1001>=80,5,IF(N1001+O1001>=70,4,IF(N1001+O1001>=60,3.5,IF(N1001+O1001>=50,3,IF(N1001+O1001>=40,2,IF(N1001+O1001>=33,1,0))))))) | AI1001: =IF(AA1001,0,IF(P1001+Q1001>=80,5,IF(P1001+Q1001>=70,4,IF(P1001+Q1001>=60,3.5,IF(P1001+Q1001>=50,3,IF(P1001+Q1001>=40,2,IF(P1001+Q1001>=33,1,0))))))) | AJ1001: =IF(R1001<8.25,0,IF(R1001*2>=80,5,IF(R1001*2>=70,4,IF(R1001*2>=60,3.5,IF(R1001*2>=50,3,IF(R1001*2>=40,2,IF(R1001*2>=33,1,0))))))) | AK1001: =IF(S1001<33,0,IF(S1001>=80,5,IF(S1001>=70,4,IF(S1001>=60,3.5,IF(S1001>=50,3,IF(S1001>=40,2,IF(S1001>=33,1,0))))))) | AL1001: =(AC1001+AD1001+AE1001+AF1001+AG1001+AH1001+AI1001+AJ1001)/8 | AM1001: =IF(AK1001>=2,(AK1001-2)/8,0)

Sheet Dashboard
A1: 📊 ACADEMIC RESULTS DASHBOARD
A4: SUMMARY STATISTICS
B5: Total Students: | C5: =COUNTA('Data Source'!B:B)-1 | E5: Average GPA: | F5: =IFERROR(ROUND(AVERAGE('Data Source'!W:W),2), 0) | H5: Highest Total: | I5: =MAX('Data Source'!T:T) | K5: Pass Rate: | L5: =IF(C5>0,COUNTIF('Data Source'!W:W,">0")/C5,0)
A7: GRADE DISTRIBUTION | D7: SUBJECT-WISE AVERAGE | G7: TOP 5 STUDENTS
A8: Grade | B8: Count | D8: Subject | E8: Avg | F8: % | G8: Rank | H8: Name | I8: GPA
A9: A+ | B9: =COUNTIF('Data Source'!X:X,"A+") | D9: Quran Mazid | E9: =IFERROR(ROUND(AVERAGE('Data Source'!C:C),2),0) | F9: =IFERROR(ROUND(E9/100*100,1),0) | G9: 1 | H9: =IFERROR(INDEX('Data Source'!$B:$B,MATCH(I9,'Data Source'!$W:$W,0)),"") | I9: =IFERROR(LARGE('Data Source'!$W:$W,1),"")
A10: A | B10: =COUNTIF('Data Source'!X:X,"A") | D10: Arabic (Comb.) | E10: =IFERROR(ROUND(AVERAGE('Data Source'!E3:E22+'Data Source'!F3:F22),2),0) | F10: =IFERROR(ROUND(E10/200*100,1),0) | G10: 2 | H10: =IFERROR(INDEX('Data Source'!$B:$B,MATCH(I10,'Data Source'!$W:$W,0)),"") | I10: =IFERROR(LARGE('Data Source'!$W:$W,2),"")
A11: A- | B11: =COUNTIF('Data Source'!X:X,"A-") | D11: Aqaid | E11: =IFERROR(ROUND(AVERAGE('Data Source'!G:G),2),0) | F11: =IFERROR(ROUND(E11/100*100,1),0) | G11: 3 | H11: =IFERROR(INDEX('Data Source'!$B:$B,MATCH(I11,'Data Source'!$W:$W,0)),"") | I11: =IFERROR(LARGE('Data Source'!$W:$W,3),"")
A12: B | B12: =COUNTIF('Data Source'!X:X,"B") | D12: English (Comb.) | E12: =IFERROR(ROUND(AVERAGE('Data Source'!H3:H22+'Data Source'!I3:I22),2),0) | F12: =IFERROR(ROUND(E12/200*100,1),0) | G12: 4 | H12: =IFERROR(INDEX('Data Source'!$B:$B,MATCH(I12,'Data Source'!$W:$W,0)),"") | I12: =IFERROR(LARGE('Data Source'!$W:$W,4),"")
A13: C | B13: =COUNTIF('Data Source'!X:X,"C") | D13: Bangla (Comb.) | E13: =IFERROR(ROUND(AVERAGE('Data Source'!J3:J22+'Data Source'!K3:K22+'Data Source'!L3:L22+'Data Source'!M3:M22),2),0) | F13: =IFERROR(ROUND(E13/200*100,1),0) | G13: 5 | H13: =IFERROR(INDEX('Data Source'!$B:$B,MATCH(I13,'Data Source'!$W:$W,0)),"") | I13: =IFERROR(LARGE('Data Source'!$W:$W,5),"")
A14: D | B14: =COUNTIF('Data Source'!X:X,"D") | D14: Mathematics | E14: =IFERROR(ROUND(AVERAGE('Data Source'!N3:N22+'Data Source'!O3:O22),2),0) | F14: =IFERROR(ROUND(E14/100*100,1),0)
A15: F | B15: =COUNTIF('Data Source'!X:X,"F") | D15: Islamic History | E15: =IFERROR(ROUND(AVERAGE('Data Source'!P3:P22+'Data Source'!Q3:Q22),2),0) | F15: =IFERROR(ROUND(E15/100*100,1),0)
D16: ICT | E16: =IFERROR(ROUND(AVERAGE('Data Source'!R:R),2),0) | F16: =IFERROR(ROUND(E16/50*100,1),0)
D17: Agriculture | E17: =IFERROR(ROUND(AVERAGE('Data Source'!S:S),2),0) | F17: =IFERROR(ROUND(E17/100*100,1),0)

Sheet Subject Grades
A1: SUBJECT-WISE GRADES
A2: SL | B2: Name | C2: Quran+Hadith | D2: Arabic | E2: Aqaid | F2: English | G2: Bangla | H2: Math | I2: History | J2: ICT | K2: Agriculture | L2: Overall GPA | M2: Overall Grade
A3: ='Data Source'!A2 | B3: ='Data Source'!B2 | C3: =IF('Data Source'!AC2>=5,"A+",IF('Data Source'!AC2>=4,"A",IF('Data Source'!AC2>=3.5,"A-",IF('Data Source'!AC2>=3,"B",IF('Data Source'!AC2>=2,"C",IF('Data Source'!AC2>=1,"D","F")))))) | D3: =IF('Data Source'!AD2>=5,"A+",IF('Data Source'!AD2>=4,"A",IF('Data Source'!AD2>=3.5,"A-",IF('Data Source'!AD2>=3,"B",IF('Data Source'!AD2>=2,"C",IF('Data Source'!AD2>=1,"D","F")))))) | E3: =IF('Data Source'!AE2>=5,"A+",IF('Data Source'!AE2>=4,"A",IF('Data Source'!AE2>=3.5,"A-",IF('Data Source'!AE2>=3,"B",IF('Data Source'!AE2>=2,"C",IF('Data Source'!AE2>=1,"D","F")))))) | F3: =IF('Data Source'!AF2>=5,"A+",IF('Data Source'!AF2>=4,"A",IF('Data Source'!AF2>=3.5,"A-",IF('Data Source'!AF2>=3,"B",IF('Data Source'!AF2>=2,"C",IF('Data Source'!AF2>=1,"D","F")))))) | G3: =IF('Data Source'!AG2>=5,"A+",IF('Data Source'!AG2>=4,"A",IF('Data Source'!AG2>=3.5,"A-",IF('Data Source'!AG2>=3,"B",IF('Data Source'!AG2>=2,"C",IF('Data Source'!AG2>=1,"D","F")))))) | H3: =IF('Data Source'!AH2>=5,"A+",IF('Data Source'!AH2>=4,"A",IF('Data Source'!AH2>=3.5,"A-",IF('Data Source'!AH2>=3,"B",IF('Data Source'!AH2>=2,"C",IF('Data Source'!AH2>=1,"D","F")))))) | I3: =IF('Data Source'!AI2>=5,"A+",IF('Data Source'!AI2>=4,"A",IF('Data Source'!AI2>=3.5,"A-",IF('Data Source'!AI2>=3,"B",IF('Data Source'!AI2>=2,"C",IF('Data Source'!AI2>=1,"D","F")))))) | J3: =IF('Data Source'!AJ2>=5,"A+",IF('Data Source'!AJ2>=4,"A",IF('Data Source'!AJ2>=3.5,"A-",IF('Data Source'!AJ2>=3,"B",IF('Data Source'!AJ2>=2,"C",IF('Data Source'!AJ2>=1,"D","F")))))) | K3: =IF('Data Source'!AK2>=5,"A+",IF('Data Source'!AK2>=4,"A",IF('Data Source'!AK2>=3.5,"A-",IF('Data Source'!AK2>=3,"B",IF('Data Source'!AK2>=2,"C",IF('Data Source'!AK2>=1,"D","F")))))) | L3: ='Data Source'!W2 | M3: ='Data Source'!X2
A4: ='Data Source'!A3 | B4: ='Data Source'!B3 | C4: =IF('Data Source'!AC3>=5,"A+",IF('Data Source'!AC3>=4,"A",IF('Data Source'!AC3>=3.5,"A-",IF('Data Source'!AC3>=3,"B",IF('Data Source'!AC3>=2,"C",IF('Data Source'!AC3>=1,"D","F")))))) | D4: =IF('Data Source'!AD3>=5,"A+",IF('Data Source'!AD3>=4,"A",IF('Data Source'!AD3>=3.5,"A-",IF('Data Source'!AD3>=3,"B",IF('Data Source'!AD3>=2,"C",IF('Data Source'!AD3>=1,"D","F")))))) | E4: =IF('Data Source'!AE3>=5,"A+",IF('Data Source'!AE3>=4,"A",IF('Data Source'!AE3>=3.5,"A-",IF('Data Source'!AE3>=3,"B",IF('Data Source'!AE3>=2,"C",IF('Data Source'!AE3>=1,"D","F")))))) | F4: =IF('Data Source'!AF3>=5,"A+",IF('Data Source'!AF3>=4,"A",IF('Data Source'!AF3>=3.5,"A-",IF('Data Source'!AF3>=3,"B",IF('Data Source'!AF3>=2,"C",IF('Data Source'!AF3>=1,"D","F")))))) | G4: =IF('Data Source'!AG3>=5,"A+",IF('Data Source'!AG3>=4,"A",IF('Data Source'!AG3>=3.5,"A-",IF('Data Source'!AG3>=3,"B",IF('Data Source'!AG3>=2,"C",IF('Data Source'!AG3>=1,"D","F")))))) | H4: =IF('Data Source'!AH3>=5,"A+",IF('Data Source'!AH3>=4,"A",IF('Data Source'!AH3>=3.5,"A-",IF('Data Source'!AH3>=3,"B",IF('Data Source'!AH3>=2,"C",IF('Data Source'!AH3>=1,"D","F")))))) | I4: =IF('Data Source'!AI3>=5,"A+",IF('Data Source'!AI3>=4,"A",IF('Data Source'!AI3>=3.5,"A-",IF('Data Source'!AI3>=3,"B",IF('Data Source'!AI3>=2,"C",IF('Data Source'!AI3>=1,"D","F")))))) | J4: =IF('Data Source'!AJ3>=5,"A+",IF('Data Source'!AJ3>=4,"A",IF('Data Source'!AJ3>=3.5,"A-",IF('Data Source'!AJ3>=3,"B",IF('Data Source'!AJ3>=2,"C",IF('Data Source'!AJ3>=1,"D","F")))))) | K4: =IF('Data Source'!AK3>=5,"A+",IF('Data Source'!AK3>=4,"A",IF('Data Source'!AK3>=3.5,"A-",IF('Data Source'!AK3>=3,"B",IF('Data Source'!AK3>=2,"C",IF('Data Source'!AK3>=1,"D","F")))))) | L4: ='Data Source'!W3 | M4: ='Data Source'!X3
A5: ='Data Source'!A4 | B5: ='Data Source'!B4 | C5: =IF('Data Source'!AC4>=5,"A+",IF('Data Source'!AC4>=4,"A",IF('Data Source'!AC4>=3.5,"A-",IF('Data Source'!AC4>=3,"B",IF('Data Source'!AC4>=2,"C",IF('Data Source'!AC4>=1,"D","F")))))) | D5: =IF('Data Source'!AD4>=5,"A+",IF('Data Source'!AD4>=4,"A",IF('Data Source'!AD4>=3.5,"A-",IF('Data Source'!AD4>=3,"B",IF('Data Source'!AD4>=2,"C",IF('Data Source'!AD4>=1,"D","F")))))) | E5: =IF('Data Source'!AE4>=5,"A+",IF('Data Source'!AE4>=4,"A",IF('Data Source'!AE4>=3.5,"A-",IF('Data Source'!AE4>=3,"B",IF('Data Source'!AE4>=2,"C",IF('Data Source'!AE4>=1,"D","F")))))) | F5: =IF('Data Source'!AF4>=5,"A+",IF('Data Source'!AF4>=4,"A",IF('Data Source'!AF4>=3.5,"A-",IF('Data Source'!AF4>=3,"B",IF('Data Source'!AF4>=2,"C",IF('Data Source'!AF4>=1,"D","F")))))) | G5: =IF('Data Source'!AG4>=5,"A+",IF('Data Source'!AG4>=4,"A",IF('Data Source'!AG4>=3.5,"A-",IF('Data Source'!AG4>=3,"B",IF('Data Source'!AG4>=2,"C",IF('Data Source'!AG4>=1,"D","F")))))) | H5: =IF('Data Source'!AH4>=5,"A+",IF('Data Source'!AH4>=4,"A",IF('Data Source'!AH4>=3.5,"A-",IF('Data Source'!AH4>=3,"B",IF('Data Source'!AH4>=2,"C",IF('Data Source'!AH4>=1,"D","F")))))) | I5: =IF('Data Source'!AI4>=5,"A+",IF('Data Source'!AI4>=4,"A",IF('Data Source'!AI4>=3.5,"A-",IF('Data Source'!AI4>=3,"B",IF('Data Source'!AI4>=2,"C",IF('Data Source'!AI4>=1,"D","F")))))) | J5: =IF('Data Source'!AJ4>=5,"A+",IF('Data Source'!AJ4>=4,"A",IF('Data Source'!AJ4>=3.5,"A-",IF('Data Source'!AJ4>=3,"B",IF('Data Source'!AJ4>=2,"C",IF('Data Source'!AJ4>=1,"D","F")))))) | K5: =IF('Data Source'!AK4>=5,"A+",IF('Data Source'!AK4>=4,"A",IF('Data Source'!AK4>=3.5,"A-",IF('Data Source'!AK4>=3,"B",IF('Data Source'!AK4>=2,"C",IF('Data Source'!AK4>=1,"D","F")))))) | L5: ='Data Source'!W4 | M5: ='Data Source'!X4
