Workbook

Sheet Data Source
A1: CLASS 8 - ACADEMIC RESULTS DATA SOURCE
A2: SL | B2: Name | C2: Quran | D2: English I | E2: English II | F2: Bangla I | G2: Bangla II | H2: Science | I2: Mathematics | J2: General Knowledge | K2: Arabic I | L2: Arabic II | M2: Aqaid | N2: ICT | O2: Bangladesh and Global Studies | P2: Total | Q2: Average | R2: GPA | S2: Grade | T2: Position
A3: 1 | B3: Maryam Farooq | C3: 42 | D3: 72 | E3: 36 | F3: 38 | G3: 50 | H3: 84 | I3: 44 | J3: 79 | K3: 25 | L3: 77 | M3: 67 | N3: 42 | O3: 75 | P3: =IF(B3="","",SUM(C3:O3)) | Q3: =IF(B3="","",ROUND(P3/13,2)) | R3: =IF(B3="","",IF(AH3=1,0,MIN(5,ROUND((U3+V3+W3+X3+Y3+Z3+AA3+AB3+AC3+AD3+AE3+AF3+AG3)/13,2)))) | S3: =IF(B3="","",IF(R3>=5,"A+",IF(R3>=4,"A",IF(R3>=3.5,"A-",IF(R3>=3,"B",IF(R3>=2,"C",IF(R3>=1,"D","F"))))))) | T3: =IF(OR(B3="",S3="F"),"",COUNTIFS(P:P,">"&P3,S:S,"<>F")+1) | U3: =IF(B3="","",IF(C3<33.0,0,IF(C3>=100*0.8,5,IF(C3>=100*0.7,4,IF(C3>=100*0.6,3.5,IF(C3>=100*0.5,3,IF(C3>=100*0.4,2,IF(C3>=100*0.33,1,0)))))))) | V3: =IF(B3="","",IF(D3<33.0,0,IF(D3>=100*0.8,5,IF(D3>=100*0.7,4,IF(D3>=100*0.6,3.5,IF(D3>=100*0.5,3,IF(D3>=100*0.4,2,IF(D3>=100*0.33,1,0)))))))) | W3: =IF(B3="","",IF(E3<16.5,0,IF(E3>=50*0.8,5,IF(E3>=50*0.7,4,IF(E3>=50*0.6,3.5,IF(E3>=50*0.5,3,IF(E3>=50*0.4,2,IF(E3>=50*0.33,1,0)))))))) | X3: =IF(B3="","",IF(F3<33.0,0,IF(F3>=100*0.8,5,IF(F3>=100*0.7,4,IF(F3>=100*0.6,3.5,IF(F3>=100*0.5,3,IF(F3>=100*0.4,2,IF(F3>=100*0.33,1,0)))))))) | Y3: =IF(B3="","",IF(G3<16.5,0,IF(G3>=50*0.8,5,IF(G3>=50*0.7,4,IF(G3>=50*0.6,3.5,IF(G3>=50*0.5,3,IF(G3>=50*0.4,2,IF(G3>=50*0.33,1,0)))))))) | Z3: =IF(B3="","",IF(H3<33.0,0,IF(H3>=100*0.8,5,IF(H3>=100*0.7,4,IF(H3>=100*0.6,3.5,IF(H3>=100*0.5,3,IF(H3>=100*0.4,2,IF(H3>=100*0.33,1,0)))))))) | AA3: =IF(B3="","",IF(I3<33.0,0,IF(I3>=100*0.8,5,IF(I3>=100*0.7,4,IF(I3>=100*0.6,3.5,IF(I3>=100*0.5,3,IF(I3>=100*0.4,2,IF(I3>=100*0.33,1,0)))))))) | AB3: =IF(B3="","",IF(J3<33.0,0,IF(J3>=100*0.8,5,IF(J3>=100*0.7,4,IF(J3>=100*0.6,3.5,IF(J3>=100*0.5,3,IF(J3>=100*0.4,2,IF(J3>=100*0.33,1,0)))))))) | AC3: =IF(B3="","",IF(K3<33.0,0,IF(K3>=100*0.8,5,IF(K3>=100*0.7,4,IF(K3>=100*0.6,3.5,IF(K3>=100*0.5,3,IF(K3>=100*0.4,2,IF(K3>=100*0.33,1,0)))))))) | AD3: =IF(B3="","",IF(L3<33.0,0,IF(L3>=100*0.8,5,IF(L3>=100*0.7,4,IF(L3>=100*0.6,3.5,IF(L3>=100*0.5,3,IF(L3>=100*0.4,2,IF(L3>=100*0.33,1,0)))))))) | AE3: =IF(B3="","",IF(M3<33.0,0,IF(M3>=100*0.8,5,IF(M3>=100*0.7,4,IF(M3>=100*0.6,3.5,IF(M3>=100*0.5,3,IF(M3>=100*0.4,2,IF(M3>=100*0.33,1,0)))))))) | AF3: =IF(B3="","",IF(N3<16.5,0,IF(N3>=50*0.8,5,IF(N3>=50*0.7,4,IF(N3>=50*0.6,3.5,IF(N3>=50*0.5,3,IF(N3>=50*0.4,2,IF(N3>=50*0.33,1,0)))))))) | AG3: =IF(B3="","",IF(O3<33.0,0,IF(O3>=100*0.8,5,IF(O3>=100*0.7,4,IF(O3>=100*0.6,3.5,IF(O3>=100*0.5,3,IF(O3>=100*0.4,2,IF(O3>=100*0.33,1,0)))))))) | AH3: =IF(B3="","",IF(OR(U3=0,V3=0,W3=0,X3=0,Y3=0,Z3=0,AA3=0,AB3=0,AC3=0,AD3=0,AE3=0,AF3=0,AG3=0),1,0))
A4: 2 | B4: Bilal Nasir | C4: 80 | D4: 84 | E4: 22 | F4: 51 | G4: 41 | H4: 63 | I4: 97 | J4: 73 | K4: 19 | L4: 92 | M4: 80 | N4: 31 | O4: 74 | P4: =IF(B4="","",SUM(C4:O4)) | Q4: =IF(B4="","",ROUND(P4/13,2)) | R4: =IF(B4="","",IF(AH4=1,0,MIN(5,ROUND((U4+V4+W4+X4+Y4+Z4+AA4+AB4+AC4+AD4+AE4+AF4+AG4)/13,2)))) | S4: =IF(B4="","",IF(R4>=5,"A+",IF(R4>=4,"A",IF(R4>=3.5,"A-",IF(R4>=3,"B",IF(R4>=2,"C",IF(R4>=1,"D","F"))))))) | T4: =IF(OR(B4="",S4="F"),"",COUNTIFS(P:P,">"&P4,S:S,"<>F")+1) | U4: =IF(B4="","",IF(C4<33.0,0,IF(C4>=100*0.8,5,IF(C4>=100*0.7,4,IF(C4>=100*0.6,3.5,IF(C4>=100*0.5,3,IF(C4>=100*0.4,2,IF(C4>=100*0.33,1,0)))))))) | V4: =IF(B4="","",IF(D4<33.0,0,IF(D4>=100*0.8,5,IF(D4>=100*0.7,4,IF(D4>=100*0.6,3.5,IF(D4>=100*0.5,3,IF(D4>=100*0.4,2,IF(D4>=100*0.33,1,0)))))))) | W4: =IF(B4="","",IF(E4<16.5,0,IF(E4>=50*0.8,5,IF(E4>=50*0.7,4,IF(E4>=50*0.6,3.5,IF(E4>=50*0.5,3,IF(E4>=50*0.4,2,IF(E4>=50*0.33,1,0)))))))) | X4: =IF(B4="","",IF(F4<33.0,0,IF(F4>=100*0.8,5,IF(F4>=100*0.7,4,IF(F4>=100*0.6,3.5,IF(F4>=100*0.5,3,IF(F4>=100*0.4,2,IF(F4>=100*0.33,1,0)))))))) | Y4: =IF(B4="","",IF(G4<16.5,0,IF(G4>=50*0.8,5,IF(G4>=50*0.7,4,IF(G4>=50*0.6,3.5,IF(G4>=50*0.5,3,IF(G4>=50*0.4,2,IF(G4>=50*0.33,1,0)))))))) | Z4: =IF(B4="","",IF(H4<33.0,0,IF(H4>=100*0.8,5,IF(H4>=100*0.7,4,IF(H4>=100*0.6,3.5,IF(H4>=100*0.5,3,IF(H4>=100*0.4,2,IF(H4>=100*0.33,1,0)))))))) | AA4: =IF(B4="","",IF(I4<33.0,0,IF(I4>=100*0.8,5,IF(I4>=100*0.7,4,IF(I4>=100*0.6,3.5,IF(I4>=100*0.5,3,IF(I4>=100*0.4,2,IF(I4>=100*0.33,1,0)))))))) | AB4: =IF(B4="","",IF(J4<33.0,0,IF(J4>=100*0.8,5,IF(J4>=100*0.7,4,IF(J4>=100*0.6,3.5,IF(J4>=100*0.5,3,IF(J4>=100*0.4,2,IF(J4>=100*0.33,1,0)))))))) | AC4: =IF(B4="","",IF(K4<33.0,0,IF(K4>=100*0.8,5,IF(K4>=100*0.7,4,IF(K4>=100*0.6,3.5,IF(K4>=100*0.5,3,IF(K4>=100*0.4,2,IF(K4>=100*0.33,1,0)))))))) | AD4: =IF(B4="","",IF(L4<33.0,0,IF(L4>=100*0.8,5,IF(L4>=100*0.7,4,IF(L4>=100*0.6,3.5,IF(L4>=100*0.5,3,IF(L4>=100*0.4,2,IF(L4>=100*0.33,1,0)))))))) | AE4: =IF(B4="","",IF(M4<33.0,0,IF(M4>=100*0.8,5,IF(M4>=100*0.7,4,IF(M4>=100*0.6,3.5,IF(M4>=100*0.5,3,IF(M4>=100*0.4,2,IF(M4>=100*0.33,1,0)))))))) | AF4: =IF(B4="","",IF(N4<16.5,0,IF(N4>=50*0.8,5,IF(N4>=50*0.7,4,IF(N4>=50*0.6,3.5,IF(N4>=50*0.5,3,IF(N4>=50*0.4,2,IF(N4>=50*0.33,1,0)))))))) | AG4: =IF(B4="","",IF(O4<33.0,0,IF(O4>=100*0.8,5,IF(O4>=100*0.7,4,IF(O4>=100*0.6,3.5,IF(O4>=100*0.5,3,IF(O4>=100*0.4,2,IF(O4>=100*0.33,1,0)))))))) | AH4: =IF(B4="","",IF(OR(U4=0,V4=0,W4=0,X4=0,Y4=0,Z4=0,AA4=0,AB4=0,AC4=0,AD4=0,AE4=0,AF4=0,AG4=0),1,0))
A5: 3 | B5: Ahmed Hussain | C5: 98 | D5: 68 | E5: 31 | F5: 73 | G5: 27 | H5: 76 | I5: 84 | J5: 43 | K5: 38 | L5: 92 | M5: 20 | N5: 21 | O5: 91 | P5: =IF(B5="","",SUM(C5:O5)) | Q5: =IF(B5="","",ROUND(P5/13,2)) | R5: =IF(B5="","",IF(AH5=1,0,MIN(5,ROUND((U5+V5+W5+X5+Y5+Z5+AA5+AB5+AC5+AD5+AE5+AF5+AG5)/13,2)))) | S5: =IF(B5="","",IF(R5>=5,"A+",IF(R5>=4,"A",IF(R5>=3.5,"A-",IF(R5>=3,"B",IF(R5>=2,"C",IF(R5>=1,"D","F"))))))) | T5: =IF(OR(B5="",S5="F"),"",COUNTIFS(P:P,">"&P5,S:S,"<>F")+1) | U5: =IF(B5="","",IF(C5<33.0,0,IF(C5>=100*0.8,5,IF(C5>=100*0.7,4,IF(C5>=100*0.6,3.5,IF(C5>=100*0.5,3,IF(C5>=100*0.4,2,IF(C5>=100*0.33,1,0)))))))) | V5: =IF(B5="","",IF(D5<33.0,0,IF(D5>=100*0.8,5,IF(D5>=100*0.7,4,IF(D5>=100*0.6,3.5,IF(D5>=100*0.5,3,IF(D5>=100*0.4,2,IF(D5>=100*0.33,1,0)))))))) | W5: =IF(B5="","",IF(E5<16.5,0,IF(E5>=50*0.8,5,IF(E5>=50*0.7,4,IF(E5>=50*0.6,3.5,IF(E5>=50*0.5,3,IF(E5>=50*0.4,2,IF(E5>=50*0.33,1,0)))))))) | X5: =IF(B5="","",IF(F5<33.0,0,IF(F5>=100*0.8,5,IF(F5>=100*0.7,4,IF(F5>=100*0.6,3.5,IF(F5>=100*0.5,3,IF(F5>=100*0.4,2,IF(F5>=100*0.33,1,0)))))))) | Y5: =IF(B5="","",IF(G5<16.5,0,IF(G5>=50*0.8,5,IF(G5>=50*0.7,4,IF(G5>=50*0.6,3.5,IF(G5>=50*0.5,3,IF(G5>=50*0.4,2,IF(G5>=50*0.33,1,0)))))))) | Z5: =IF(B5="","",IF(H5<33.0,0,IF(H5>=100*0.8,5,IF(H5>=100*0.7,4,IF(H5>=100*0.6,3.5,IF(H5>=100*0.5,3,IF(H5>=100*0.4,2,IF(H5>=100*0.33,1,0)))))))) | AA5: =IF(B5="","",IF(I5<33.0,0,IF(I5>=100*0.8,5,IF(I5>=100*0.7,4,IF(I5>=100*0.6,3.5,IF(I5>=100*0.5,3,IF(I5>=100*0.4,2,IF(I5>=100*0.33,1,0)))))))) | AB5: =IF(B5="","",IF(J5<33.0,0,IF(J5>=100*0.8,5,IF(J5>=100*0.7,4,IF(J5>=100*0.6,3.5,IF(J5>=100*0.5,3,IF(J5>=100*0.4,2,IF(J5>=100*0.33,1,0)))))))) | AC5: =IF(B5="","",IF(K5<33.0,0,IF(K5>=100*0.8,5,IF(K5>=100*0.7,4,IF(K5>=100*0.6,3.5,IF(K5>=100*0.5,3,IF(K5>=100*0.4,2,IF(K5>=100*0.33,1,0)))))))) | AD5: =IF(B5="","",IF(L5<33.0,0,IF(L5>=100*0.8,5,IF(L5>=100*0.7,4,IF(L5>=100*0.6,3.5,IF(L5>=100*0.5,3,IF(L5>=100*0.4,2,IF(L5>=100*0.33,1,0)))))))) | AE5: =IF(B5="","",IF(M5<33.0,0,IF(M5>=100*0.8,5,IF(M5>=100*0.7,4,IF(M5>=100*0.6,3.5,IF(M5>=100*0.5,3,IF(M5>=100*0.4,2,IF(M5>=100*0.33,1,0)))))))) | AF5: =IF(B5="","",IF(N5<16.5,0,IF(N5>=50*0.8,5,IF(N5>=50*0.7,4,IF(N5>=50*0.6,3.5,IF(N5>=50*0.5,3,IF(N5>=50*0.4,2,IF(N5>=50*0.33,1,0)))))))) | AG5: =IF(B5="","",IF(O5<33.0,0,IF(O5>=100*0.8,5,IF(O5>=100*0.7,4,IF(O5>=100*0.6,3.5,IF(O5>=100*0.5,3,IF(O5>=100*0.4,2,IF(O5>=100*0.33,1,0)))))))) | AH5: =IF(B5="","",IF(OR(U5=0,V5=0,W5=0,X5=0,Y5=0,Z5=0,AA5=0,AB5=0,AC5=0,AD5=0,AE5=0,AF5=0,AG5=0),1,0))
A6: 4 | B6: Aisha Ahmed | C6: 93 | D6: 61 | E6: 29 | F6: 12 | G6: 21 | H6: 69 | I6: 44 | J6: 80 | K6: 51 | L6: 39 | M6: 75 | N6: 19 | O6: 41 | P6: =IF(B6="","",SUM(C6:O6)) | Q6: =IF(B6="","",ROUND(P6/13,2)) | R6: =IF(B6="","",IF(AH6=1,0,MIN(5,ROUND((U6+V6+W6+X6+Y6+Z6+AA6+AB6+AC6+AD6+AE6+AF6+AG6)/13,2)))) | S6: =IF(B6="","",IF(R6>=5,"A+",IF(R6>=4,"A",IF(R6>=3.5,"A-",IF(R6>=3,"B",IF(R6>=2,"C",IF(R6>=1,"D","F"))))))) | T6: =IF(OR(B6="",S6="F"),"",COUNTIFS(P:P,">"&P6,S:S,"<>F")+1) | U6: =IF(B6="","",IF(C6<33.0,0,IF(C6>=100*0.8,5,IF(C6>=100*0.7,4,IF(C6>=100*0.6,3.5,IF(C6>=100*0.5,3,IF(C6>=100*0.4,2,IF(C6>=100*0.33,1,0)))))))) | V6: =IF(B6="","",IF(D6<33.0,0,IF(D6>=100*0.8,5,IF(D6>=100*0.7,4,IF(D6>=100*0.6,3.5,IF(D6>=100*0.5,3,IF(D6>=100*0.4,2,IF(D6>=100*0.33,1,0)))))))) | W6: =IF(B6="","",IF(E6<16.5,0,IF(E6>=50*0.8,5,IF(E6>=50*0.7,4,IF(E6>=50*0.6,3.5,IF(E6>=50*0.5,3,IF(E6>=50*0.4,2,IF(E6>=50*0.33,1,0)))))))) | X6: =IF(B6="","",IF(F6<33.0,0,IF(F6>=100*0.8,5,IF(F6>=100*0.7,4,IF(F6>=100*0.6,3.5,IF(F6>=100*0.5,3,IF(F6>=100*0.4,2,IF(F6>=100*0.33,1,0)))))))) | Y6: =IF(B6="","",IF(G6<16.5,0,IF(G6>=50*0.8,5,IF(G6>=50*0.7,4,IF(G6>=50*0.6,3.5,IF(G6>=50*0.5,3,IF(G6>=50*0.4,2,IF(G6>=50*0.33,1,0)))))))) | Z6: =IF(B6="","",IF(H6<33.0,0,IF(H6>=100*0.8,5,IF(H6>=100*0.7,4,IF(H6>=100*0.6,3.5,IF(H6>=100*0.5,3,IF(H6>=100*0.4,2,IF(H6>=100*0.33,1,0)))))))) | AA6: =IF(B6="","",IF(I6<33.0,0,IF(I6>=100*0.8,5,IF(I6>=100*0.7,4,IF(I6>=100*0.6,3.5,IF(I6>=100*0.5,3,IF(I6>=100*0.4,2,IF(I6>=100*0.33,1,0)))))))) | AB6: =IF(B6="","",IF(J6<33.0,0,IF(J6>=100*0.8,5,IF(J6>=100*0.7,4,IF(J6>=100*0.6,3.5,IF(J6>=100*0.5,3,IF(J6>=100*0.4,2,IF(J6>=100*0.33,1,0)))))))) | AC6: =IF(B6="","",IF(K6<33.0,0,IF(K6>=100*0.8,5,IF(K6>=100*0.7,4,IF(K6>=100*0.6,3.5,IF(K6>=100*0.5,3,IF(K6>=100*0.4,2,IF(K6>=100*0.33,1,0)))))))) | AD6: =IF(B6="","",IF(L6<33.0,0,IF(L6>=100*0.8,5,IF(L6>=100*0.7,4,IF(L6>=100*0.6,3.5,IF(L6>=100*0.5,3,IF(L6>=100*0.4,2,IF(L6>=100*0.33,1,0)))))))) | AE6: =IF(B6="","",IF(M6<33.0,0,IF(M6>=100*0.8,5,IF(M6>=100*0.7,4,IF(M6>=100*0.6,3.5,IF(M6>=100*0.5,3,IF(M6>=100*0.4,2,IF(M6>=100*0.33,1,0)))))))) | AF6: =IF(B6="","",IF(N6<16.5,0,IF(N6>=50*0.8,5,IF(N6>=50*0.7,4,IF(N6>=50*0.6,3.5,IF(N6>=50*0.5,3,IF(N6>=50*0.4,2,IF(N6>=50*0.33,1,0)))))))) | AG6: =IF(B6="","",IF(O6<33.0,0,IF(O6>=100*0.8,5,IF(O6>=100*0.7,4,IF(O6>=100*0.6,3.5,IF(O6>=100*0.5,3,IF(O6>=100*0.4,2,IF(O6>=100*0.33,1,0)))))))) | AH6: =IF(B6="","",IF(OR(U6=0,V6=0,W6=0,X6=0,Y6=0,Z6=0,AA6=0,AB6=0,AC6=0,AD6=0,AE6=0,AF6=0,AG6=0),1,0))
A7: 5 | B7: Khalid Aziz | C7: 95 | D7: 57 | E7: 17 | F7: 34 | G7: 24 | H7: 92 | I7: 42 | J7: 31 | K7: 47 | L7: 45 | M7: 63 | N7: 37 | O7: 66 | P7: =IF(B7="","",SUM(C7:O7)) | Q7: =IF(B7="","",ROUND(P7/13,2)) | R7: =IF(B7="","",IF(AH7=1,0,MIN(5,ROUND((U7+V7+W7+X7+Y7+Z7+AA7+AB7+AC7+AD7+AE7+AF7+AG7)/13,2)))) | S7: =IF(B7="","",IF(R7>=5,"A+",IF(R7>=4,"A",IF(R7>=3.5,"A-",IF(R7>=3,"B",IF(R7>=2,"C",IF(R7>=1,"D","F"))))))) | T7: =IF(OR(B7="",S7="F"),"",COUNTIFS(P:P,">"&P7,S:S,"<>F")+1) | U7: =IF(B7="","",IF(C7<33.0,0,IF(C7>=100*0.8,5,IF(C7>=100*0.7,4,IF(C7>=100*0.6,3.5,IF(C7>=100*0.5,3,IF(C7>=100*0.4,2,IF(C7>=100*0.33,1,0)))))))) | V7: =IF(B7="","",IF(D7<33.0,0,IF(D7>=100*0.8,5,IF(D7>=100*0.7,4,IF(D7>=100*0.6,3.5,IF(D7>=100*0.5,3,IF(D7>=100*0.4,2,IF(D7>=100*0.33,1,0)))))))) | W7: =IF(B7="","",IF(E7<16.5,0,IF(E7>=50*0.8,5,IF(E7>=50*0.7,4,IF(E7>=50*0.6,3.5,IF(E7>=50*0.5,3,IF(E7>=50*0.4,2,IF(E7>=50*0.33,1,0)))))))) | X7: =IF(B7="","",IF(F7<33.0,0,IF(F7>=100*0.8,5,IF(F7>=100*0.7,4,IF(F7>=100*0.6,3.5,IF(F7>=100*0.5,3,IF(F7>=100*0.4,2,IF(F7>=100*0.33,1,0)))))))) | Y7: =IF(B7="","",IF(G7<16.5,0,IF(G7>=50*0.8,5,IF(G7>=50*0.7,4,IF(G7>=50*0.6,3.5,IF(G7>=50*0.5,3,IF(G7>=50*0.4,2,IF(G7>=50*0.33,1,0)))))))) | Z7: =IF(B7="","",IF(H7<33.0,0,IF(H7>=100*0.8,5,IF(H7>=100*0.7,4,IF(H7>=100*0.6,3.5,IF(H7>=100*0.5,3,IF(H7>=100*0.4,2,IF(H7>=100*0.33,1,0)))))))) | AA7: =IF(B7="","",IF(I7<33.0,0,IF(I7>=100*0.8,5,IF(I7>=100*0.7,4,IF(I7>=100*0.6,3.5,IF(I7>=100*0.5,3,IF(I7>=100*0.4,2,IF(I7>=100*0.33,1,0)))))))) | AB7: =IF(B7="","",IF(J7<33.0,0,IF(J7>=100*0.8,5,IF(J7>=100*0.7,4,IF(J7>=100*0.6,3.5,IF(J7>=100*0.5,3,IF(J7>=100*0.4,2,IF(J7>=100*0.33,1,0)))))))) | AC7: =IF(B7="","",IF(K7<33.0,0,IF(K7>=100*0.8,5,IF(K7>=100*0.7,4,IF(K7>=100*0.6,3.5,IF(K7>=100*0.5,3,IF(K7>=100*0.4,2,IF(K7>=100*0.33,1,0)))))))) | AD7: =IF(B7="","",IF(L7<33.0,0,IF(L7>=100*0.8,5,IF(L7>=100*0.7,4,IF(L7>=100*0.6,3.5,IF(L7>=100*0.5,3,IF(L7>=100*0.4,2,IF(L7>=100*0.33,1,0)))))))) | AE7: =IF(B7="","",IF(M7<33.0,0,IF(M7>=100*0.8,5,IF(M7>=100*0.7,4,IF(M7>=100*0.6,3.5,IF(M7>=100*0.5,3,IF(M7>=100*0.4,2,IF(M7>=100*0.33,1,0)))))))) | AF7: =IF(B7="","",IF(N7<16.5,0,IF(N7>=50*0.8,5,IF(N7>=50*0.7,4,IF(N7>=50*0.6,3.5,IF(N7>=50*0.5,3,IF(N7>=50*0.4,2,IF(N7>=50*0.33,1,0)))))))) | AG7: =IF(B7="","",IF(O7<33.0,0,IF(O7>=100*0.8,5,IF(O7>=100*0.7,4,IF(O7>=100*0.6,3.5,IF(O7>=100*0.5,3,IF(O7>=100*0.4,2,IF(O7>=100*0.33,1,0)))))))) | AH7: =IF(B7="","",IF(OR(U7=0,V7=0,W7=0,X7=0,Y7=0,Z7=0,AA7=0,AB7=0,AC7=0,AD7=0,AE7=0,AF7=0,AG7=0),1,0))
A8: 6 | B8: Khadija Khan | C8: 77 | D8: 36 | E8: 50 | F8: 36 | G8: 31 | H8: 73 | I8: 41 | J8: 52 | K8: 90 | L8: 90 | M8: 82 | N8: 23 | O8: 37 | P8: =IF(B8="","",SUM(C8:O8)) | Q8: =IF(B8="","",ROUND(P8/13,2)) | R8: =IF(B8="","",IF(AH8=1,0,MIN(5,ROUND((U8+V8+W8+X8+Y8+Z8+AA8+AB8+AC8+AD8+AE8+AF8+AG8)/13,2)))) | S8: =IF(B8="","",IF(R8>=5,"A+",IF(R8>=4,"A",IF(R8>=3.5,"A-",IF(R8>=3,"B",IF(R8>=2,"C",IF(R8>=1,"D","F"))))))) | T8: =IF(OR(B8="",S8="F"),"",COUNTIFS(P:P,">"&P8,S:S,"<>F")+1) | U8: =IF(B8="","",IF(C8<33.0,0,IF(C8>=100*0.8,5,IF(C8>=100*0.7,4,IF(C8>=100*0.6,3.5,IF(C8>=100*0.5,3,IF(C8>=100*0.4,2,IF(C8>=100*0.33,1,0)))))))) | V8: =IF(B8="","",IF(D8<33.0,0,IF(D8>=100*0.8,5,IF(D8>=100*0.7,4,IF(D8>=100*0.6,3.5,IF(D8>=100*0.5,3,IF(D8>=100*0.4,2,IF(D8>=100*0.33,1,0)))))))) | W8: =IF(B8="","",IF(E8<16.5,0,IF(E8>=50*0.8,5,IF(E8>=50*0.7,4,IF(E8>=50*0.6,3.5,IF(E8>=50*0.5,3,IF(E8>=50*0.4,2,IF(E8>=50*0.33,1,0)))))))) | X8: =IF(B8="","",IF(F8<33.0,0,IF(F8>=100*0.8,5,IF(F8>=100*0.7,4,IF(F8>=100*0.6,3.5,IF(F8>=100*0.5,3,IF(F8>=100*0.4,2,IF(F8>=100*0.33,1,0)))))))) | Y8: =IF(B8="","",IF(G8<16.5,0,IF(G8>=50*0.8,5,IF(G8>=50*0.7,4,IF(G8>=50*0.6,3.5,IF(G8>=50*0.5,3,IF(G8>=50*0.4,2,IF(G8>=50*0.33,1,0)))))))) | Z8: =IF(B8="","",IF(H8<33.0,0,IF(H8>=100*0.8,5,IF(H8>=100*0.7,4,IF(H8>=100*0.6,3.5,IF(H8>=100*0.5,3,IF(H8>=100*0.4,2,IF(H8>=100*0.33,1,0)))))))) | AA8: =IF(B8="","",IF(I8<33.0,0,IF(I8>=100*0.8,5,IF(I8>=100*0.7,4,IF(I8>=100*0.6,3.5,IF(I8>=100*0.5,3,IF(I8>=100*0.4,2,IF(I8>=100*0.33,1,0)))))))) | AB8: =IF(B8="","",IF(J8<33.0,0,IF(J8>=100*0.8,5,IF(J8>=100*0.7,4,IF(J8>=100*0.6,3.5,IF(J8>=100*0.5,3,IF(J8>=100*0.4,2,IF(J8>=100*0.33,1,0)))))))) | AC8: =IF(B8="","",IF(K8<33.0,0,IF(K8>=100*0.8,5,IF(K8>=100*0.7,4,IF(K8>=100*0.6,3.5,IF(K8>=100*0.5,3,IF(K8>=100*0.4,2,IF(K8>=100*0.33,1,0)))))))) | AD8: =IF(B8="","",IF(L8<33.0,0,IF(L8>=100*0.8,5,IF(L8>=100*0.7,4,IF(L8>=100*0.6,3.5,IF(L8>=100*0.5,3,IF(L8>=100*0.4,2,IF(L8>=100*0.33,1,0)))))))) | AE8: =IF(B8="","",IF(M8<33.0,0,IF(M8>=100*0.8,5,IF(M8>=100*0.7,4,IF(M8>=100*0.6,3.5,IF(M8>=100*0.5,3,IF(M8>=100*0.4,2,IF(M8>=100*0.33,1,0)))))))) | AF8: =IF(B8="","",IF(N8<16.5,0,IF(N8>=50*0.8,5,IF(N8>=50*0.7,4,IF(N8>=50*0.6,3.5,IF(N8>=50*0.5,3,IF(N8>=50*0.4,2,IF(N8>=50*0.33,1,0)))))))) | AG8: =IF(B8="","",IF(O8<33.0,0,IF(O8>=100*0.8,5,IF(O8>=100*0.7,4,IF(O8>=100*0.6,3.5,IF(O8>=100*0.5,3,IF(O8>=100*0.4,2,IF(O8>=100*0.33,1,0)))))))) | AH8: =IF(B8="","",IF(OR(U8=0,V8=0,W8=0,X8=0,Y8=0,Z8=0,AA8=0,AB8=0,AC8=0,AD8=0,AE8=0,AF8=0,AG8=0),1,0))
A9: 7 | B9: Zainab Rahman | C9: 72 | D9: 81 | E9: 19 | F9: 72 | G9: 46 | H9: 3 | I9: 35 | J9: 82 | K9: 56 | L9: 92 | M9: 69 | N9: 25 | O9: 82 | P9: =IF(B9="","",SUM(C9:O9)) | Q9: =IF(B9="","",ROUND(P9/13,2)) | R9: =IF(B9="","",IF(AH9=1,0,MIN(5,ROUND((U9+V9+W9+X9+Y9+Z9+AA9+AB9+AC9+AD9+AE9+AF9+AG9)/13,2)))) | S9: =IF(B9="","",IF(R9>=5,"A+",IF(R9>=4,"A",IF(R9>=3.5,"A-",IF(R9>=3,"B",IF(R9>=2,"C",IF(R9>=1,"D","F"))))))) | T9: =IF(OR(B9="",S9="F"),"",COUNTIFS(P:P,">"&P9,S:S,"<>F")+1) | U9: =IF(B9="","",IF(C9<33.0,0,IF(C9>=100*0.8,5,IF(C9>=100*0.7,4,IF(C9>=100*0.6,3.5,IF(C9>=100*0.5,3,IF(C9>=100*0.4,2,IF(C9>=100*0.33,1,0)))))))) | V9: =IF(B9="","",IF(D9<33.0,0,IF(D9>=100*0.8,5,IF(D9>=100*0.7,4,IF(D9>=100*0.6,3.5,IF(D9>=100*0.5,3,IF(D9>=100*0.4,2,IF(D9>=100*0.33,1,0)))))))) | W9: =IF(B9="","",IF(E9<16.5,0,IF(E9>=50*0.8,5,IF(E9>=50*0.7,4,IF(E9>=50*0.6,3.5,IF(E9>=50*0.5,3,IF(E9>=50*0.4,2,IF(E9>=50*0.33,1,0)))))))) | X9: =IF(B9="","",IF(F9<33.0,0,IF(F9>=100*0.8,5,IF(F9>=100*0.7,4,IF(F9>=100*0.6,3.5,IF(F9>=100*0.5,3,IF(F9>=100*0.4,2,IF(F9>=100*0.33,1,0)))))))) | Y9: =IF(B9="","",IF(G9<16.5,0,IF(G9>=50*0.8,5,IF(G9>=50*0.7,4,IF(G9>=50*0.6,3.5,IF(G9>=50*0.5,3,IF(G9>=50*0.4,2,IF(G9>=50*0.33,1,0)))))))) | Z9: =IF(B9="","",IF(H9<33.0,0,IF(H9>=100*0.8,5,IF(H9>=100*0.7,4,IF(H9>=100*0.6,3.5,IF(H9>=100*0.5,3,IF(H9>=100*0.4,2,IF(H9>=100*0.33,1,0)))))))) | AA9: =IF(B9="","",IF(I9<33.0,0,IF(I9>=100*0.8,5,IF(I9>=100*0.7,4,IF(I9>=100*0.6,3.5,IF(I9>=100*0.5,3,IF(I9>=100*0.4,2,IF(I9>=100*0.33,1,0)))))))) | AB9: =IF(B9="","",IF(J9<33.0,0,IF(J9>=100*0.8,5,IF(J9>=100*0.7,4,IF(J9>=100*0.6,3.5,IF(J9>=100*0.5,3,IF(J9>=100*0.4,2,IF(J9>=100*0.33,1,0)))))))) | AC9: =IF(B9="","",IF(K9<33.0,0,IF(K9>=100*0.8,5,IF(K9>=100*0.7,4,IF(K9>=100*0.6,3.5,IF(K9>=100*0.5,3,IF(K9>=100*0.4,2,IF(K9>=100*0.33,1,0)))))))) | AD9: =IF(B9="","",IF(L9<33.0,0,IF(L9>=100*0.8,5,IF(L9>=100*0.7,4,IF(L9>=100*0.6,3.5,IF(L9>=100*0.5,3,IF(L9>=100*0.4,2,IF(L9>=100*0.33,1,0)))))))) | AE9: =IF(B9="","",IF(M9<33.0,0,IF(M9>=100*0.8,5,IF(M9>=100*0.7,4,IF(M9>=100*0.6,3.5,IF(M9>=100*0.5,3,IF(M9>=100*0.4,2,IF(M9>=100*0.33,1,0)))))))) | AF9: =IF(B9="","",IF(N9<16.5,0,IF(N9>=50*0.8,5,IF(N9>=50*0.7,4,IF(N9>=50*0.6,3.5,IF(N9>=50*0.5,3,IF(N9>=50*0.4,2,IF(N9>=50*0.33,1,0)))))))) | AG9: =IF(B9="","",IF(O9<33.0,0,IF(O9>=100*0.8,5,IF(O9>=100*0.7,4,IF(O9>=100*0.6,3.5,IF(O9>=100*0.5,3,IF(O9>=100*0.4,2,IF(O9>=100*0.33,1,0)))))))) | AH9: =IF(B9="","",IF(OR(U9=0,V9=0,W9=0,X9=0,Y9=0,Z9=0,AA9=0,AB9=0,AC9=0,AD9=0,AE9=0,AF9=0,AG9=0),1,0))
A10: 8 | B10: Fatima Hassan | C10: 66 | D10: 38 | E10: 38 | F10: 63 | G10: 3 | H10: 55 | I10: 42 | J10: 48 | K10: 90 | L10: 63 | M10: 92 | N10: 45 | O10: 61 | P10: =IF(B10="","",SUM(C10:O10)) | Q10: =IF(B10="","",ROUND(P10/13,2)) | R10: =IF(B10="","",IF(AH10=1,0,MIN(5,ROUND((U10+V10+W10+X10+Y10+Z10+AA10+AB10+AC10+AD10+AE10+AF10+AG10)/13,2)))) | S10: =IF(B10="","",IF(R10>=5,"A+",IF(R10>=4,"A",IF(R10>=3.5,"A-",IF(R10>=3,"B",IF(R10>=2,"C",IF(R10>=1,"D","F"))))))) | T10: =IF(OR(B10="",S10="F"),"",COUNTIFS(P:P,">"&P10,S:S,"<>F")+1) | U10: =IF(B10="","",IF(C10<33.0,0,IF(C10>=100*0.8,5,IF(C10>=100*0.7,4,IF(C10>=100*0.6,3.5,IF(C10>=100*0.5,3,IF(C10>=100*0.4,2,IF(C10>=100*0.33,1,0)))))))) | V10: =IF(B10="","",IF(D10<33.0,0,IF(D10>=100*0.8,5,IF(D10>=100*0.7,4,IF(D10>=100*0.6,3.5,IF(D10>=100*0.5,3,IF(D10>=100*0.4,2,IF(D10>=100*0.33,1,0)))))))) | W10: =IF(B10="","",IF(E10<16.5,0,IF(E10>=50*0.8,5,IF(E10>=50*0.7,4,IF(E10>=50*0.6,3.5,IF(E10>=50*0.5,3,IF(E10>=50*0.4,2,IF(E10>=50*0.33,1,0)))))))) | X10: =IF(B10="","",IF(F10<33.0,0,IF(F10>=100*0.8,5,IF(F10>=100*0.7,4,IF(F10>=100*0.6,3.5,IF(F10>=100*0.5,3,IF(F10>=100*0.4,2,IF(F10>=100*0.33,1,0)))))))) | Y10: =IF(B10="","",IF(G10<16.5,0,IF(G10>=50*0.8,5,IF(G10>=50*0.7,4,IF(G10>=50*0.6,3.5,IF(G10>=50*0.5,3,IF(G10>=50*0.4,2,IF(G10>=50*0.33,1,0)))))))) | Z10: =IF(B10="","",IF(H10<33.0,0,IF(H10>=100*0.8,5,IF(H10>=100*0.7,4,IF(H10>=100*0.6,3.5,IF(H10>=100*0.5,3,IF(H10>=100*0.4,2,IF(H10>=100*0.33,1,0)))))))) | AA10: =IF(B10="","",IF(I10<33.0,0,IF(I10>=100*0.8,5,IF(I10>=100*0.7,4,IF(I10>=100*0.6,3.5,IF(I10>=100*0.5,3,IF(I10>=100*0.4,2,IF(I10>=100*0.33,1,0)))))))) | AB10: =IF(B10="","",IF(J10<33.0,0,IF(J10>=100*0.8,5,IF(J10>=100*0.7,4,IF(J10>=100*0.6,3.5,IF(J10>=100*0.5,3,IF(J10>=100*0.4,2,IF(J10>=100*0.33,1,0)))))))) | AC10: =IF(B10="","",IF(K10<33.0,0,IF(K10>=100*0.8,5,IF(K10>=100*0.7,4,IF(K10>=100*0.6,3.5,IF(K10>=100*0.5,3,IF(K10>=100*0.4,2,IF(K10>=100*0.33,1,0)))))))) | AD10: =IF(B10="","",IF(L10<33.0,0,IF(L10>=100*0.8,5,IF(L10>=100*0.7,4,IF(L10>=100*0.6,3.5,IF(L10>=100*0.5,3,IF(L10>=100*0.4,2,IF(L10>=100*0.33,1,0)))))))) | AE10: =IF(B10="","",IF(M10<33.0,0,IF(M10>=100*0.8,5,IF(M10>=100*0.7,4,IF(M10>=100*0.6,3.5,IF(M10>=100*0.5,3,IF(M10>=100*0.4,2,IF(M10>=100*0.33,1,0)))))))) | AF10: =IF(B10="","",IF(N10<16.5,0,IF(N10>=50*0.8,5,IF(N10>=50*0.7,4,IF(N10>=50*0.6,3.5,IF(N10>=50*0.5,3,IF(N10>=50*0.4,2,IF(N10>=50*0.33,1,0)))))))) | AG10: =IF(B10="","",IF(O10<33.0,0,IF(O10>=100*0.8,5,IF(O10>=100*0.7,4,IF(O10>=100*0.6,3.5,IF(O10>=100*0.5,3,IF(O10>=100*0.4,2,IF(O10>=100*0.33,1,0)))))))) | AH10: =IF(B10="","",IF(OR(U10=0,V10=0,W10=0,X10=0,Y10=0,Z10=0,AA10=0,AB10=0,AC10=0,AD10=0,AE10=0,AF10=0,AG10=0),1,0))
A11: 9 | B11: Aisha Ali | C11: 77 | D11: 67 | E11: 32 | F11: 41 | G11: 24 | H11: 51 | I11: 71 | J11: 100 | K11: 6 | L11: 58 | M11: 55 | N11: 28 | O11: 73 | P11: =IF(B11="","",SUM(C11:O11)) | Q11: =IF(B11="","",ROUND(P11/13,2)) | R11: =IF(B11="","",IF(AH11=1,0,MIN(5,ROUND((U11+V11+W11+X11+Y11+Z11+AA11+AB11+AC11+AD11+AE11+AF11+AG11)/13,2)))) | S11: =IF(B11="","",IF(R11>=5,"A+",IF(R11>=4,"A",IF(R11>=3.5,"A-",IF(R11>=3,"B",IF(R11>=2,"C",IF(R11>=1,"D","F"))))))) | T11: =IF(OR(B11="",S11="F"),"",COUNTIFS(P:P,">"&P11,S:S,"<>F")+1) | U11: =IF(B11="","",IF(C11<33.0,0,IF(C11>=100*0.8,5,IF(C11>=100*0.7,4,IF(C11>=100*0.6,3.5,IF(C11>=100*0.5,3,IF(C11>=100*0.4,2,IF(C11>=100*0.33,1,0)))))))) | V11: =IF(B11="","",IF(D11<33.0,0,IF(D11>=100*0.8,5,IF(D11>=100*0.7,4,IF(D11>=100*0.6,3.5,IF(D11>=100*0.5,3,IF(D11>=100*0.4,2,IF(D11>=100*0.33,1,0)))))))) | W11: =IF(B11="","",IF(E11<16.5,0,IF(E11>=50*0.8,5,IF(E11>=50*0.7,4,IF(E11>=50*0.6,3.5,IF(E11>=50*0.5,3,IF(E11>=50*0.4,2,IF(E11>=50*0.33,1,0)))))))) | X11: =IF(B11="","",IF(F11<33.0,0,IF(F11>=100*0.8,5,IF(F11>=100*0.7,4,IF(F11>=100*0.6,3.5,IF(F11>=100*0.5,3,IF(F11>=100*0.4,2,IF(F11>=100*0.33,1,0)))))))) | Y11: =IF(B11="","",IF(G11<16.5,0,IF(G11>=50*0.8,5,IF(G11>=50*0.7,4,IF(G11>=50*0.6,3.5,IF(G11>=50*0.5,3,IF(G11>=50*0.4,2,IF(G11>=50*0.33,1,0)))))))) | Z11: =IF(B11="","",IF(H11<33.0,0,IF(H11>=100*0.8,5,IF(H11>=100*0.7,4,IF(H11>=100*0.6,3.5,IF(H11>=100*0.5,3,IF(H11>=100*0.4,2,IF(H11>=100*0.33,1,0)))))))) | AA11: =IF(B11="","",IF(I11<33.0,0,IF(I11>=100*0.8,5,IF(I11>=100*0.7,4,IF(I11>=100*0.6,3.5,IF(I11>=100*0.5,3,IF(I11>=100*0.4,2,IF(I11>=100*0.33,1,0)))))))) | AB11: =IF(B11="","",IF(J11<33.0,0,IF(J11>=100*0.8,5,IF(J11>=100*0.7,4,IF(J11>=100*0.6,3.5,IF(J11>=100*0.5,3,IF(J11>=100*0.4,2,IF(J11>=100*0.33,1,0)))))))) | AC11: =IF(B11="","",IF(K11<33.0,0,IF(K11>=100*0.8,5,IF(K11>=100*0.7,4,IF(K11>=100*0.6,3.5,IF(K11>=100*0.5,3,IF(K11>=100*0.4,2,IF(K11>=100*0.33,1,0)))))))) | AD11: =IF(B11="","",IF(L11<33.0,0,IF(L11>=100*0.8,5,IF(L11>=100*0.7,4,IF(L11>=100*0.6,3.5,IF(L11>=100*0.5,3,IF(L11>=100*0.4,2,IF(L11>=100*0.33,1,0)))))))) | AE11: =IF(B11="","",IF(M11<33.0,0,IF(M11>=100*0.8,5,IF(M11>=100*0.7,4,IF(M11>=100*0.6,3.5,IF(M11>=100*0.5,3,IF(M11>=100*0.4,2,IF(M11>=100*0.33,1,0)))))))) | AF11: =IF(B11="","",IF(N11<16.5,0,IF(N11>=50*0.8,5,IF(N11>=50*0.7,4,IF(N11>=50*0.6,3.5,IF(N11>=50*0.5,3,IF(N11>=50*0.4,2,IF(N11>=50*0.33,1,0)))))))) | AG11: =IF(B11="","",IF(O11<33.0,0,IF(O11>=100*0.8,5,IF(O11>=100*0.7,4,IF(O11>=100*0.6,3.5,IF(O11>=100*0.5,3,IF(O11>=100*0.4,2,IF(O11>=100*0.33,1,0)))))))) | AH11: =IF(B11="","",IF(OR(U11=0,V11=0,W11=0,X11=0,Y11=0,Z11=0,AA11=0,AB11=0,AC11=0,AD11=0,AE11=0,AF11=0,AG11=0),1,0))
A12: 10 | B12: Omar Rahman | C12: 36 | D12: 73 | E12: 25 | F12: 57 | G12: 45 | H12: 63 | I12: 53 | J12: 43 | K12: 29 | L12: 98 | M12: 91 | N12: 44 | O12: 43 | P12: =IF(B12="","",SUM(C12:O12)) | Q12: =IF(B12="","",ROUND(P12/13,2)) | R12: =IF(B12="","",IF(AH12=1,0,MIN(5,ROUND((U12+V12+W12+X12+Y12+Z12+AA12+AB12+AC12+AD12+AE12+AF12+AG12)/13,2)))) | S12: =IF(B12="","",IF(R12>=5,"A+",IF(R12>=4,"A",IF(R12>=3.5,"A-",IF(R12>=3,"B",IF(R12>=2,"C",IF(R12>=1,"D","F"))))))) | T12: =IF(OR(B12="",S12="F"),"",COUNTIFS(P:P,">"&P12,S:S,"<>F")+1) | U12: =IF(B12="","",IF(C12<33.0,0,IF(C12>=100*0.8,5,IF(C12>=100*0.7,4,IF(C12>=100*0.6,3.5,IF(C12>=100*0.5,3,IF(C12>=100*0.4,2,IF(C12>=100*0.33,1,0)))))))) | V12: =IF(B12="","",IF(D12<33.0,0,IF(D12>=100*0.8,5,IF(D12>=100*0.7,4,IF(D12>=100*0.6,3.5,IF(D12>=100*0.5,3,IF(D12>=100*0.4,2,IF(D12>=100*0.33,1,0)))))))) | W12: =IF(B12="","",IF(E12<16.5,0,IF(E12>=50*0.8,5,IF(E12>=50*0.7,4,IF(E12>=50*0.6,3.5,IF(E12>=50*0.5,3,IF(E12>=50*0.4,2,IF(E12>=50*0.33,1,0)))))))) | X12: =IF(B12="","",IF(F12<33.0,0,IF(F12>=100*0.8,5,IF(F12>=100*0.7,4,IF(F12>=100*0.6,3.5,IF(F12>=100*0.5,3,IF(F12>=100*0.4,2,IF(F12>=100*0.33,1,0)))))))) | Y12: =IF(B12="","",IF(G12<16.5,0,IF(G12>=50*0.8,5,IF(G12>=50*0.7,4,IF(G12>=50*0.6,3.5,IF(G12>=50*0.5,3,IF(G12>=50*0.4,2,IF(G12>=50*0.33,1,0)))))))) | Z12: =IF(B12="","",IF(H12<33.0,0,IF(H12>=100*0.8,5,IF(H12>=100*0.7,4,IF(H12>=100*0.6,3.5,IF(H12>=100*0.5,3,IF(H12>=100*0.4,2,IF(H12>=100*0.33,1,0)))))))) | AA12: =IF(B12="","",IF(I12<33.0,0,IF(I12>=100*0.8,5,IF(I12>=100*0.7,4,IF(I12>=100*0.6,3.5,IF(I12>=100*0.5,3,IF(I12>=100*0.4,2,IF(I12>=100*0.33,1,0)))))))) | AB12: =IF(B12="","",IF(J12<33.0,0,IF(J12>=100*0.8,5,IF(J12>=100*0.7,4,IF(J12>=100*0.6,3.5,IF(J12>=100*0.5,3,IF(J12>=100*0.4,2,IF(J12>=100*0.33,1,0)))))))) | AC12: =IF(B12="","",IF(K12<33.0,0,IF(K12>=100*0.8,5,IF(K12>=100*0.7,4,IF(K12>=100*0.6,3.5,IF(K12>=100*0.5,3,IF(K12>=100*0.4,2,IF(K12>=100*0.33,1,0)))))))) | AD12: =IF(B12="","",IF(L12<33.0,0,IF(L12>=100*0.8,5,IF(L12>=100*0.7,4,IF(L12>=100*0.6,3.5,IF(L12>=100*0.5,3,IF(L12>=100*0.4,2,IF(L12>=100*0.33,1,0)))))))) | AE12: =IF(B12="","",IF(M12<33.0,0,IF(M12>=100*0.8,5,IF(M12>=100*0.7,4,IF(M12>=100*0.6,3.5,IF(M12>=100*0.5,3,IF(M12>=100*0.4,2,IF(M12>=100*0.33,1,0)))))))) | AF12: =IF(B12="","",IF(N12<16.5,0,IF(N12>=50*0.8,5,IF(N12>=50*0.7,4,IF(N12>=50*0.6,3.5,IF(N12>=50*0.5,3,IF(N12>=50*0.4,2,IF(N12>=50*0.33,1,0)))))))) | AG12: =IF(B12="","",IF(O12<33.0,0,IF(O12>=100*0.8,5,IF(O12>=100*0.7,4,IF(O12>=100*0.6,3.5,IF(O12>=100*0.5,3,IF(O12>=100*0.4,2,IF(O12>=100*0.33,1,0)))))))) | AH12: =IF(B12="","",IF(OR(U12=0,V12=0,W12=0,X12=0,Y12=0,Z12=0,AA12=0,AB12=0,AC12=0,AD12=0,AE12=0,AF12=0,AG12=0),1,0))
A13: 11 | B13: Sumaya Shah | C13: 59 | D13: 89 | E13: 30 | F13: 84 | G13: 27 | H13: 78 | I13: 88 | J13: 65 | K13: 58 | L13: 100 | M13: 16 | N13: 32 | O13: 79 | P13: =IF(B13="","",SUM(C13:O13)) | Q13: =IF(B13="","",ROUND(P13/13,2)) | R13: =IF(B13="","",IF(AH13=1,0,MIN(5,ROUND((U13+V13+W13+X13+Y13+Z13+AA13+AB13+AC13+AD13+AE13+AF13+AG13)/13,2)))) | S13: =IF(B13="","",IF(R13>=5,"A+",IF(R13>=4,"A",IF(R13>=3.5,"A-",IF(R13>=3,"B",IF(R13>=2,"C",IF(R13>=1,"D","F"))))))) | T13: =IF(OR(B13="",S13="F"),"",COUNTIFS(P:P,">"&P13,S:S,"<>F")+1) | U13: =IF(B13="","",IF(C13<33.0,0,IF(C13>=100*0.8,5,IF(C13>=100*0.7,4,IF(C13>=100*0.6,3.5,IF(C13>=100*0.5,3,IF(C13>=100*0.4,2,IF(C13>=100*0.33,1,0)))))))) | V13: =IF(B13="","",IF(D13<33.0,0,IF(D13>=100*0.8,5,IF(D13>=100*0.7,4,IF(D13>=100*0.6,3.5,IF(D13>=100*0.5,3,IF(D13>=100*0.4,2,IF(D13>=100*0.33,1,0)))))))) | W13: =IF(B13="","",IF(E13<16.5,0,IF(E13>=50*0.8,5,IF(E13>=50*0.7,4,IF(E13>=50*0.6,3.5,IF(E13>=50*0.5,3,IF(E13>=50*0.4,2,IF(E13>=50*0.33,1,0)))))))) | X13: =IF(B13="","",IF(F13<33.0,0,IF(F13>=100*0.8,5,IF(F13>=100*0.7,4,IF(F13>=100*0.6,3.5,IF(F13>=100*0.5,3,IF(F13>=100*0.4,2,IF(F13>=100*0.33,1,0)))))))) | Y13: =IF(B13="","",IF(G13<16.5,0,IF(G13>=50*0.8,5,IF(G13>=50*0.7,4,IF(G13>=50*0.6,3.5,IF(G13>=50*0.5,3,IF(G13>=50*0.4,2,IF(G13>=50*0.33,1,0)))))))) | Z13: =IF(B13="","",IF(H13<33.0,0,IF(H13>=100*0.8,5,IF(H13>=100*0.7,4,IF(H13>=100*0.6,3.5,IF(H13>=100*0.5,3,IF(H13>=100*0.4,2,IF(H13>=100*0.33,1,0)))))))) | AA13: =IF(B13="","",IF(I13<33.0,0,IF(I13>=100*0.8,5,IF(I13>=100*0.7,4,IF(I13>=100*0.6,3.5,IF(I13>=100*0.5,3,IF(I13>=100*0.4,2,IF(I13>=100*0.33,1,0)))))))) | AB13: =IF(B13="","",IF(J13<33.0,0,IF(J13>=100*0.8,5,IF(J13>=100*0.7,4,IF(J13>=100*0.6,3.5,IF(J13>=100*0.5,3,IF(J13>=100*0.4,2,IF(J13>=100*0.33,1,0)))))))) | AC13: =IF(B13="","",IF(K13<33.0,0,IF(K13>=100*0.8,5,IF(K13>=100*0.7,4,IF(K13>=100*0.6,3.5,IF(K13>=100*0.5,3,IF(K13>=100*0.4,2,IF(K13>=100*0.33,1,0)))))))) | AD13: =IF(B13="","",IF(L13<33.0,0,IF(L13>=100*0.8,5,IF(L13>=100*0.7,4,IF(L13>=100*0.6,3.5,IF(L13>=100*0.5,3,IF(L13>=100*0.4,2,IF(L13>=100*0.33,1,0)))))))) | AE13: =IF(B13="","",IF(M13<33.0,0,IF(M13>=100*0.8,5,IF(M13>=100*0.7,4,IF(M13>=100*0.6,3.5,IF(M13>=100*0.5,3,IF(M13>=100*0.4,2,IF(M13>=100*0.33,1,0)))))))) | AF13: =IF(B13="","",IF(N13<16.5,0,IF(N13>=50*0.8,5,IF(N13>=50*0.7,4,IF(N13>=50*0.6,3.5,IF(N13>=50*0.5,3,IF(N13>=50*0.4,2,IF(N13>=50*0.33,1,0)))))))) | AG13: =IF(B13="","",IF(O13<33.0,0,IF(O13>=100*0.8,5,IF(O13>=100*0.7,4,IF(O13>=100*0.6,3.5,IF(O13>=100*0.5,3,IF(O13>=100*0.4,2,IF(O13>=100*0.33,1,0)))))))) | AH13: =IF(B13="","",IF(OR(U13=0,V13=0,W13=0,X13=0,Y13=0,Z13=0,AA13=0,AB13=0,AC13=0,AD13=0,AE13=0,AF13=0,AG13=0),1,0))
A14: 12 | B14: Khadija Nasir | C14: 81 | D14: 67 | E14: 47 | F14: 47 | G14: 32 | H14: 41 | I14: 98 | J14: 33 | K14: 73 | L14: 4 | M14: 50 | N14: 40 | O14: 81 | P14: =IF(B14="","",SUM(C14:O14)) | Q14: =IF(B14="","",ROUND(P14/13,2)) | R14: =IF(B14="","",IF(AH14=1,0,MIN(5,ROUND((U14+V14+W14+X14+Y14+Z14+AA14+AB14+AC14+AD14+AE14+AF14+AG14)/13,2)))) | S14: =IF(B14="","",IF(R14>=5,"A+",IF(R14>=4,"A",IF(R14>=3.5,"A-",IF(R14>=3,"B",IF(R14>=2,"C",IF(R14>=1,"D","F"))))))) | T14: =IF(OR(B14="",S14="F"),"",COUNTIFS(P:P,">"&P14,S:S,"<>F")+1) | U14: =IF(B14="","",IF(C14<33.0,0,IF(C14>=100*0.8,5,IF(C14>=100*0.7,4,IF(C14>=100*0.6,3.5,IF(C14>=100*0.5,3,IF(C14>=100*0.4,2,IF(C14>=100*0.33,1,0)))))))) | V14: =IF(B14="","",IF(D14<33.0,0,IF(D14>=100*0.8,5,IF(D14>=100*0.7,4,IF(D14>=100*0.6,3.5,IF(D14>=100*0.5,3,IF(D14>=100*0.4,2,IF(D14>=100*0.33,1,0)))))))) | W14: =IF(B14="","",IF(E14<16.5,0,IF(E14>=50*0.8,5,IF(E14>=50*0.7,4,IF(E14>=50*0.6,3.5,IF(E14>=50*0.5,3,IF(E14>=50*0.4,2,IF(E14>=50*0.33,1,0)))))))) | X14: =IF(B14="","",IF(F14<33.0,0,IF(F14>=100*0.8,5,IF(F14>=100*0.7,4,IF(F14>=100*0.6,3.5,IF(F14>=100*0.5,3,IF(F14>=100*0.4,2,IF(F14>=100*0.33,1,0)))))))) | Y14: =IF(B14="","",IF(G14<16.5,0,IF(G14>=50*0.8,5,IF(G14>=50*0.7,4,IF(G14>=50*0.6,3.5,IF(G14>=50*0.5,3,IF(G14>=50*0.4,2,IF(G14>=50*0.33,1,0)))))))) | Z14: =IF(B14="","",IF(H14<33.0,0,IF(H14>=100*0.8,5,IF(H14>=100*0.7,4,IF(H14>=100*0.6,3.5,IF(H14>=100*0.5,3,IF(H14>=100*0.4,2,IF(H14>=100*0.33,1,0)))))))) | AA14: =IF(B14="","",IF(I14<33.0,0,IF(I14>=100*0.8,5,IF(I14>=100*0.7,4,IF(I14>=100*0.6,3.5,IF(I14>=100*0.5,3,IF(I14>=100*0.4,2,IF(I14>=100*0.33,1,0)))))))) | AB14: =IF(B14="","",IF(J14<33.0,0,IF(J14>=100*0.8,5,IF(J14>=100*0.7,4,IF(J14>=100*0.6,3.5,IF(J14>=100*0.5,3,IF(J14>=100*0.4,2,IF(J14>=100*0.33,1,0)))))))) | AC14: =IF(B14="","",IF(K14<33.0,0,IF(K14>=100*0.8,5,IF(K14>=100*0.7,4,IF(K14>=100*0.6,3.5,IF(K14>=100*0.5,3,IF(K14>=100*0.4,2,IF(K14>=100*0.33,1,0)))))))) | AD14: =IF(B14="","",IF(L14<33.0,0,IF(L14>=100*0.8,5,IF(L14>=100*0.7,4,IF(L14>=100*0.6,3.5,IF(L14>=100*0.5,3,IF(L14>=100*0.4,2,IF(L14>=100*0.33,1,0)))))))) | AE14: =IF(B14="","",IF(M14<33.0,0,IF(M14>=100*0.8,5,IF(M14>=100*0.7,4,IF(M14>=100*0.6,3.5,IF(M14>=100*0.5,3,IF(M14>=100*0.4,2,IF(M14>=100*0.33,1,0)))))))) | AF14: =IF(B14="","",IF(N14<16.5,0,IF(N14>=50*0.8,5,IF(N14>=50*0.7,4,IF(N14>=50*0.6,3.5,IF(N14>=50*0.5,3,IF(N14>=50*0.4,2,IF(N14>=50*0.33,1,0)))))))) | AG14: =IF(B14="","",IF(O14<33.0,0,IF(O14>=100*0.8,5,IF(O14>=100*0.7,4,IF(O14>=100*0.6,3.5,IF(O14>=100*0.5,3,IF(O14>=100*0.4,2,IF(O14>=100*0.33,1,0)))))))) | AH14: =IF(B14="","",IF(OR(U14=0,V14=0,W14=0,X14=0,Y14=0,Z14=0,AA14=0,AB14=0,AC14=0,AD14=0,AE14=0,AF14=0,AG14=0),1,0))
... A22: 20 | B22: Safiya Iqbal | C22: 32 | D22: 48 | E22: 33 | F22: 75 | G22: 30 | H22: 54 | I22: 53 | J22: 86 | K22: 62 | L22: 89 | M22: 13 | N22: 48 | O22: 37 | P22: =IF(B22="","",SUM(C22:O22)) | Q22: =IF(B22="","",ROUND(P22/13,2)) | R22: =IF(B22="","",IF(AH22=1,0,MIN(5,ROUND((U22+V22+W22+X22+Y22+Z22+AA22+AB22+AC22+AD22+AE22+AF22+AG22)/13,2)))) | S22: =IF(B22="","",IF(R22>=5,"A+",IF(R22>=4,"A",IF(R22>=3.5,"A-",IF(R22>=3,"B",IF(R22>=2,"C",IF(R22>=1,"D","F"))))))) | T22: =IF(OR(B22="",S22="F"),"",COUNTIFS(P:P,">"&P22,S:S,"<>F")+1) | U22: =IF(B22="","",IF(C22<33.0,0,IF(C22>=100*0.8,5,IF(C22>=100*0.7,4,IF(C22>=100*0.6,3.5,IF(C22>=100*0.5,3,IF(C22>=100*0.4,2,IF(C22>=100*0.33,1,0)))))))) | V22: =IF(B22="","",IF(D22<33.0,0,IF(D22>=100*0.8,5,IF(D22>=100*0.7,4,IF(D22>=100*0.6,3.5,IF(D22>=100*0.5,3,IF(D22>=100*0.4,2,IF(D22>=100*0.33,1,0)))))))) | W22: =IF(B22="","",IF(E22<16.5,0,IF(E22>=50*0.8,5,IF(E22>=50*0.7,4,IF(E22>=50*0.6,3.5,IF(E22>=50*0.5,3,IF(E22>=50*0.4,2,IF(E22>=50*0.33,1,0)))))))) | X22: =IF(B22="","",IF(F22<33.0,0,IF(F22>=100*0.8,5,IF(F22>=100*0.7,4,IF(F22>=100*0.6,3.5,IF(F22>=100*0.5,3,IF(F22>=100*0.4,2,IF(F22>=100*0.33,1,0)))))))) | Y22: =IF(B22="","",IF(G22<16.5,0,IF(G22>=50*0.8,5,IF(G22>=50*0.7,4,IF(G22>=50*0.6,3.5,IF(G22>=50*0.5,3,IF(G22>=50*0.4,2,IF(G22>=50*0.33,1,0)))))))) | Z22: =IF(B22="","",IF(H22<33.0,0,IF(H22>=100*0.8,5,IF(H22>=100*0.7,4,IF(H22>=100*0.6,3.5,IF(H22>=100*0.5,3,IF(H22>=100*0.4,2,IF(H22>=100*0.33,1,0)))))))) | AA22: =IF(B22="","",IF(I22<33.0,0,IF(I22>=100*0.8,5,IF(I22>=100*0.7,4,IF(I22>=100*0.6,3.5,IF(I22>=100*0.5,3,IF(I22>=100*0.4,2,IF(I22>=100*0.33,1,0)))))))) | AB22: =IF(B22="","",IF(J22<33.0,0,IF(J22>=100*0.8,5,IF(J22>=100*0.7,4,IF(J22>=100*0.6,3.5,IF(J22>=100*0.5,3,IF(J22>=100*0.4,2,IF(J22>=100*0.33,1,0)))))))) | AC22: =IF(B22="","",IF(K22<33.0,0,IF(K22>=100*0.8,5,IF(K22>=100*0.7,4,IF(K22>=100*0.6,3.5,IF(K22>=100*0.5,3,IF(K22>=100*0.4,2,IF(K22>=100*0.33,1,0)))))))) | AD22: =IF(B22="","",IF(L22<33.0,0,IF(L22>=100*0.8,5,IF(L22>=100*0.7,4,IF(L22>=100*0.6,3.5,IF(L22>=100*0.5,3,IF(L22>=100*0.4,2,IF(L22>=100*0.33,1,0)))))))) | AE22: =IF(B22="","",IF(M22<33.0,0,IF(M22>=100*0.8,5,IF(M22>=100*0.7,4,IF(M22>=100*0.6,3.5,IF(M22>=100*0.5,3,IF(M22>=100*0.4,2,IF(M22>=100*0.33,1,0)))))))) | AF22: =IF(B22="","",IF(N22<16.5,0,IF(N22>=50*0.8,5,IF(N22>=50*0.7,4,IF(N22>=50*0.6,3.5,IF(N22>=50*0.5,3,IF(N22>=50*0.4,2,IF(N22>=50*0.33,1,0)))))))) | AG22: =IF(B22="","",IF(O22<33.0,0,IF(O22>=100*0.8,5,IF(O22>=100*0.7,4,IF(O22>=100*0.6,3.5,IF(O22>=100*0.5,3,IF(O22>=100*0.4,2,IF(O22>=100*0.33,1,0)))))))) | AH22: =IF(B22="","",IF(OR(U22=0,V22=0,W22=0,X22=0,Y22=0,Z22=0,AA22=0,AB22=0,AC22=0,AD22=0,AE22=0,AF22=0,AG22=0),1,0))
A23: =IF(B23="","",ROW()-2) | P23: =IF(B23="","",SUM(C23:O23)) | Q23: =IF(B23="","",ROUND(P23/13,2)) | R23: =IF(B23="","",IF(AH23=1,0,MIN(5,ROUND((U23+V23+W23+X23+Y23+Z23+AA23+AB23+AC23+AD23+AE23+AF23+AG23)/13,2)))) | S23: =IF(B23="","",IF(R23>=5,"A+",IF(R23>=4,"A",IF(R23>=3.5,"A-",IF(R23>=3,"B",IF(R23>=2,"C",IF(R23>=1,"D","F"))))))) | T23: =IF(OR(B23="",S23="F"),"",COUNTIFS(P:P,">"&P23,S:S,"<>F")+1) | U23: =IF(B23="","",IF(C23<33.0,0,IF(C23>=100*0.8,5,IF(C23>=100*0.7,4,IF(C23>=100*0.6,3.5,IF(C23>=100*0.5,3,IF(C23>=100*0.4,2,IF(C23>=100*0.33,1,0)))))))) | V23: =IF(B23="","",IF(D23<33.0,0,IF(D23>=100*0.8,5,IF(D23>=100*0.7,4,IF(D23>=100*0.6,3.5,IF(D23>=100*0.5,3,IF(D23>=100*0.4,2,IF(D23>=100*0.33,1,0)))))))) | W23: =IF(B23="","",IF(E23<16.5,0,IF(E23>=50*0.8,5,IF(E23>=50*0.7,4,IF(E23>=50*0.6,3.5,IF(E23>=50*0.5,3,IF(E23>=50*0.4,2,IF(E23>=50*0.33,1,0)))))))) | X23: =IF(B23="","",IF(F23<33.0,0,IF(F23>=100*0.8,5,IF(F23>=100*0.7,4,IF(F23>=100*0.6,3.5,IF(F23>=100*0.5,3,IF(F23>=100*0.4,2,IF(F23>=100*0.33,1,0)))))))) | Y23: =IF(B23="","",IF(G23<16.5,0,IF(G23>=50*0.8,5,IF(G23>=50*0.7,4,IF(G23>=50*0.6,3.5,IF(G23>=50*0.5,3,IF(G23>=50*0.4,2,IF(G23>=50*0.33,1,0)))))))) | Z23: =IF(B23="","",IF(H23<33.0,0,IF(H23>=100*0.8,5,IF(H23>=100*0.7,4,IF(H23>=100*0.6,3.5,IF(H23>=100*0.5,3,IF(H23>=100*0.4,2,IF(H23>=100*0.33,1,0)))))))) | AA23: =IF(B23="","",IF(I23<33.0,0,IF(I23>=100*0.8,5,IF(I23>=100*0.7,4,IF(I23>=100*0.6,3.5,IF(I23>=100*0.5,3,IF(I23>=100*0.4,2,IF(I23>=100*0.33,1,0)))))))) | AB23: =IF(B23="","",IF(J23<33.0,0,IF(J23>=100*0.8,5,IF(J23>=100*0.7,4,IF(J23>=100*0.6,3.5,IF(J23>=100*0.5,3,IF(J23>=100*0.4,2,IF(J23>=100*0.33,1,0)))))))) | AC23: =IF(B23="","",IF(K23<33.0,0,IF(K23>=100*0.8,5,IF(K23>=100*0.7,4,IF(K23>=100*0.6,3.5,IF(K23>=100*0.5,3,IF(K23>=100*0.4,2,IF(K23>=100*0.33,1,0)))))))) | AD23: =IF(B23="","",IF(L23<33.0,0,IF(L23>=100*0.8,5,IF(L23>=100*0.7,4,IF(L23>=100*0.6,3.5,IF(L23>=100*0.5,3,IF(L23>=100*0.4,2,IF(L23>=100*0.33,1,0)))))))) | AE23: =IF(B23="","",IF(M23<33.0,0,IF(M23>=100*0.8,5,IF(M23>=100*0.7,4,IF(M23>=100*0.6,3.5,IF(M23>=100*0.5,3,IF(M23>=100*0.4,2,IF(M23>=100*0.33,1,0)))))))) | AF23: =IF(B23="","",IF(N23<16.5,0,IF(N23>=50*0.8,5,IF(N23>=50*0.7,4,IF(N23>=50*0.6,3.5,IF(N23>=50*0.5,3,IF(N23>=50*0.4,2,IF(N23>=50*0.33,1,0)))))))) | AG23: =IF(B23="","",IF(O23<33.0,0,IF(O23>=100*0.8,5,IF(O23>=100*0.7,4,IF(O23>=100*0.6,3.5,IF(O23>=100*0.5,3,IF(O23>=100*0.4,2,IF(O23>=100*0.33,1,0)))))))) | AH23: =IF(B23="","",IF(OR(U23=0,V23=0,W23=0,X23=0,Y23=0,Z23=0,AA23=0,AB23=0,AC23=0,AD23=0,AE23=0,AF23=0,AG23=0),1,0))
A24: =IF(B24="","",ROW()-2) | P24: =IF(B24="","",SUM(C24:O24)) | Q24: =IF(B24="","",ROUND(P24/13,2)) | R24: =IF(B24="","",IF(AH24=1,0,MIN(5,ROUND((U24+V24+W24+X24+Y24+Z24+AA24+AB24+AC24+AD24+AE24+AF24+AG24)/13,2)))) | S24: =IF(B24="","",IF(R24>=5,"A+",IF(R24>=4,"A",IF(R24>=3.5,"A-",IF(R24>=3,"B",IF(R24>=2,"C",IF(R24>=1,"D","F"))))))) | T24: =IF(OR(B24="",S24="F"),"",COUNTIFS(P:P,">"&P24,S:S,"<>F")+1) | U24: =IF(B24="","",IF(C24<33.0,0,IF(C24>=100*0.8,5,IF(C24>=100*0.7,4,IF(C24>=100*0.6,3.5,IF(C24>=100*0.5,3,IF(C24>=100*0.4,2,IF(C24>=100*0.33,1,0)))))))) | V24: =IF(B24="","",IF(D24<33.0,0,IF(D24>=100*0.8,5,IF(D24>=100*0.7,4,IF(D24>=100*0.6,3.5,IF(D24>=100*0.5,3,IF(D24>=100*0.4,2,IF(D24>=100*0.33,1,0)))))))) | W24: =IF(B24="","",IF(E24<16.5,0,IF(E24>=50*0.8,5,IF(E24>=50*0.7,4,IF(E24>=50*0.6,3.5,IF(E24>=50*0.5,3,IF(E24>=50*0.4,2,IF(E24>=50*0.33,1,0)))))))) | X24: =IF(B24="","",IF(F24<33.0,0,IF(F24>=100*0.8,5,IF(F24>=100*0.7,4,IF(F24>=100*0.6,3.5,IF(F24>=100*0.5,3,IF(F24>=100*0.4,2,IF(F24>=100*0.33,1,0)))))))) | Y24: =IF(B24="","",IF(G24<16.5,0,IF(G24>=50*0.8,5,IF(G24>=50*0.7,4,IF(G24>=50*0.6,3.5,IF(G24>=50*0.5,3,IF(G24>=50*0.4,2,IF(G24>=50*0.33,1,0)))))))) | Z24: =IF(B24="","",IF(H24<33.0,0,IF(H24>=100*0.8,5,IF(H24>=100*0.7,4,IF(H24>=100*0.6,3.5,IF(H24>=100*0.5,3,IF(H24>=100*0.4,2,IF(H24>=100*0.33,1,0)))))))) | AA24: =IF(B24="","",IF(I24<33.0,0,IF(I24>=100*0.8,5,IF(I24>=100*0.7,4,IF(I24>=100*0.6,3.5,IF(I24>=100*0.5,3,IF(I24>=100*0.4,2,IF(I24>=100*0.33,1,0)))))))) | AB24: =IF(B24="","",IF(J24<33.0,0,IF(J24>=100*0.8,5,IF(J24>=100*0.7,4,IF(J24>=100*0.6,3.5,IF(J24>=100*0.5,3,IF(J24>=100*0.4,2,IF(J24>=100*0.33,1,0)))))))) | AC24: =IF(B24="","",IF(K24<33.0,0,IF(K24>=100*0.8,5,IF(K24>=100*0.7,4,IF(K24>=100*0.6,3.5,IF(K24>=100*0.5,3,IF(K24>=100*0.4,2,IF(K24>=100*0.33,1,0)))))))) | AD24: =IF(B24="","",IF(L24<33.0,0,IF(L24>=100*0.8,5,IF(L24>=100*0.7,4,IF(L24>=100*0.6,3.5,IF(L24>=100*0.5,3,IF(L24>=100*0.4,2,IF(L24>=100*0.33,1,0)))))))) | AE24: =IF(B24="","",IF(M24<33.0,0,IF(M24>=100*0.8,5,IF(M24>=100*0.7,4,IF(M24>=100*0.6,3.5,IF(M24>=100*0.5,3,IF(M24>=100*0.4,2,IF(M24>=100*0.33,1,0)))))))) | AF24: =IF(B24="","",IF(N24<16.5,0,IF(N24>=50*0.8,5,IF(N24>=50*0.7,4,IF(N24>=50*0.6,3.5,IF(N24>=50*0.5,3,IF(N24>=50*0.4,2,IF(N24>=50*0.33,1,0)))))))) | AG24: =IF(B24="","",IF(O24<33.0,0,IF(O24>=100*0.8,5,IF(O24>=100*0.7,4,IF(O24>=100*0.6,3.5,IF(O24>=100*0.5,3,IF(O24>=100*0.4,2,IF(O24>=100*0.33,1,0)))))))) | AH24: =IF(B24="","",IF(OR(U24=0,V24=0,W24=0,X24=0,Y24=0,Z24=0,AA24=0,AB24=0,AC24=0,AD24=0,AE24=0,AF24=0,AG24=0),1,0))
A25: =IF(B25="","",ROW()-2) | P25: =IF(B25="","",SUM(C25:O25)) | Q25: =IF(B25="","",ROUND(P25/13,2)) | R25: =IF(B25="","",IF(AH25=1,0,MIN(5,ROUND((U25+V25+W25+X25+Y25+Z25+AA25+AB25+AC25+AD25+AE25+AF25+AG25)/13,2)))) | S25: =IF(B25="","",IF(R25>=5,"A+",IF(R25>=4,"A",IF(R25>=3.5,"A-",IF(R25>=3,"B",IF(R25>=2,"C",IF(R25>=1,"D","F"))))))) | T25: =IF(OR(B25="",S25="F"),"",COUNTIFS(P:P,">"&P25,S:S,"<>F")+1) | U25: =IF(B25="","",IF(C25<33.0,0,IF(C25>=100*0.8,5,IF(C25>=100*0.7,4,IF(C25>=100*0.6,3.5,IF(C25>=100*0.5,3,IF(C25>=100*0.4,2,IF(C25>=100*0.33,1,0)))))))) | V25: =IF(B25="","",IF(D25<33.0,0,IF(D25>=100*0.8,5,IF(D25>=100*0.7,4,IF(D25>=100*0.6,3.5,IF(D25>=100*0.5,3,IF(D25>=100*0.4,2,IF(D25>=100*0.33,1,0)))))))) | W25: =IF(B25="","",IF(E25<16.5,0,IF(E25>=50*0.8,5,IF(E25>=50*0.7,4,IF(E25>=50*0.6,3.5,IF(E25>=50*0.5,3,IF(E25>=50*0.4,2,IF(E25>=50*0.33,1,0)))))))) | X25: =IF(B25="","",IF(F25<33.0,0,IF(F25>=100*0.8,5,IF(F25>=100*0.7,4,IF(F25>=100*0.6,3.5,IF(F25>=100*0.5,3,IF(F25>=100*0.4,2,IF(F25>=100*0.33,1,0)))))))) | Y25: =IF(B25="","",IF(G25<16.5,0,IF(G25>=50*0.8,5,IF(G25>=50*0.7,4,IF(G25>=50*0.6,3.5,IF(G25>=50*0.5,3,IF(G25>=50*0.4,2,IF(G25>=50*0.33,1,0)))))))) | Z25: =IF(B25="","",IF(H25<33.0,0,IF(H25>=100*0.8,5,IF(H25>=100*0.7,4,IF(H25>=100*0.6,3.5,IF(H25>=100*0.5,3,IF(H25>=100*0.4,2,IF(H25>=100*0.33,1,0)))))))) | AA25: =IF(B25="","",IF(I25<33.0,0,IF(I25>=100*0.8,5,IF(I25>=100*0.7,4,IF(I25>=100*0.6,3.5,IF(I25>=100*0.5,3,IF(I25>=100*0.4,2,IF(I25>=100*0.33,1,0)))))))) | AB25: =IF(B25="","",IF(J25<33.0,0,IF(J25>=100*0.8,5,IF(J25>=100*0.7,4,IF(J25>=100*0.6,3.5,IF(J25>=100*0.5,3,IF(J25>=100*0.4,2,IF(J25>=100*0.33,1,0)))))))) | AC25: =IF(B25="","",IF(K25<33.0,0,IF(K25>=100*0.8,5,IF(K25>=100*0.7,4,IF(K25>=100*0.6,3.5,IF(K25>=100*0.5,3,IF(K25>=100*0.4,2,IF(K25>=100*0.33,1,0)))))))) | AD25: =IF(B25="","",IF(L25<33.0,0,IF(L25>=100*0.8,5,IF(L25>=100*0.7,4,IF(L25>=100*0.6,3.5,IF(L25>=100*0.5,3,IF(L25>=100*0.4,2,IF(L25>=100*0.33,1,0)))))))) | AE25: =IF(B25="","",IF(M25<33.0,0,IF(M25>=100*0.8,5,IF(M25>=100*0.7,4,IF(M25>=100*0.6,3.5,IF(M25>=100*0.5,3,IF(M25>=100*0.4,2,IF(M25>=100*0.33,1,0)))))))) | AF25: =IF(B25="","",IF(N25<16.5,0,IF(N25>=50*0.8,5,IF(N25>=50*0.7,4,IF(N25>=50*0.6,3.5,IF(N25>=50*0.5,3,IF(N25>=50*0.4,2,IF(N25>=50*0.33,1,0)))))))) | AG25: =IF(B25="","",IF(O25<33.0,0,IF(O25>=100*0.8,5,IF(O25>=100*0.7,4,IF(O25>=100*0.6,3.5,IF(O25>=100*0.5,3,IF(O25>=100*0.4,2,IF(O25>=100*0.33,1,0)))))))) | AH25: =IF(B25="","",IF(OR(U25=0,V25=0,W25=0,X25=0,Y25=0,Z25=0,AA25=0,AB25=0,AC25=0,AD25=0,AE25=0,AF25=0,AG25=0),1,0))
A26: =IF(B26="","",ROW()-2) | P26: =IF(B26="","",SUM(C26:O26)) | Q26: =IF(B26="","",ROUND(P26/13,2)) | R26: =IF(B26="","",IF(AH26=1,0,MIN(5,ROUND((U26+V26+W26+X26+Y26+Z26+AA26+AB26+AC26+AD26+AE26+AF26+AG26)/13,2)))) | S26: =IF(B26="","",IF(R26>=5,"A+",IF(R26>=4,"A",IF(R26>=3.5,"A-",IF(R26>=3,"B",IF(R26>=2,"C",IF(R26>=1,"D","F"))))))) | T26: =IF(OR(B26="",S26="F"),"",COUNTIFS(P:P,">"&P26,S:S,"<>F")+1) | U26: =IF(B26="","",IF(C26<33.0,0,IF(C26>=100*0.8,5,IF(C26>=100*0.7,4,IF(C26>=100*0.6,3.5,IF(C26>=100*0.5,3,IF(C26>=100*0.4,2,IF(C26>=100*0.33,1,0)))))))) | V26: =IF(B26="","",IF(D26<33.0,0,IF(D26>=100*0.8,5,IF(D26>=100*0.7,4,IF(D26>=100*0.6,3.5,IF(D26>=100*0.5,3,IF(D26>=100*0.4,2,IF(D26>=100*0.33,1,0)))))))) | W26: =IF(B26="","",IF(E26<16.5,0,IF(E26>=50*0.8,5,IF(E26>=50*0.7,4,IF(E26>=50*0.6,3.5,IF(E26>=50*0.5,3,IF(E26>=50*0.4,2,IF(E26>=50*0.33,1,0)))))))) | X26: =IF(B26="","",IF(F26<33.0,0,IF(F26>=100*0.8,5,IF(F26>=100*0.7,4,IF(F26>=100*0.6,3.5,IF(F26>=100*0.5,3,IF(F26>=100*0.4,2,IF(F26>=100*0.33,1,0)))))))) | Y26: =IF(B26="","",IF(G26<16.5,0,IF(G26>=50*0.8,5,IF(G26>=50*0.7,4,IF(G26>=50*0.6,3.5,IF(G26>=50*0.5,3,IF(G26>=50*0.4,2,IF(G26>=50*0.33,1,0)))))))) | Z26: =IF(B26="","",IF(H26<33.0,0,IF(H26>=100*0.8,5,IF(H26>=100*0.7,4,IF(H26>=100*0.6,3.5,IF(H26>=100*0.5,3,IF(H26>=100*0.4,2,IF(H26>=100*0.33,1,0)))))))) | AA26: =IF(B26="","",IF(I26<33.0,0,IF(I26>=100*0.8,5,IF(I26>=100*0.7,4,IF(I26>=100*0.6,3.5,IF(I26>=100*0.5,3,IF(I26>=100*0.4,2,IF(I26>=100*0.33,1,0)))))))) | AB26: =IF(B26="","",IF(J26<33.0,0,IF(J26>=100*0.8,5,IF(J26>=100*0.7,4,IF(J26>=100*0.6,3.5,IF(J26>=100*0.5,3,IF(J26>=100*0.4,2,IF(J26>=100*0.33,1,0)))))))) | AC26: =IF(B26="","",IF(K26<33.0,0,IF(K26>=100*0.8,5,IF(K26>=100*0.7,4,IF(K26>=100*0.6,3.5,IF(K26>=100*0.5,3,IF(K26>=100*0.4,2,IF(K26>=100*0.33,1,0)))))))) | AD26: =IF(B26="","",IF(L26<33.0,0,IF(L26>=100*0.8,5,IF(L26>=100*0.7,4,IF(L26>=100*0.6,3.5,IF(L26>=100*0.5,3,IF(L26>=100*0.4,2,IF(L26>=100*0.33,1,0)))))))) | AE26: =IF(B26="","",IF(M26<33.0,0,IF(M26>=100*0.8,5,IF(M26>=100*0.7,4,IF(M26>=100*0.6,3.5,IF(M26>=100*0.5,3,IF(M26>=100*0.4,2,IF(M26>=100*0.33,1,0)))))))) | AF26: =IF(B26="","",IF(N26<16.5,0,IF(N26>=50*0.8,5,IF(N26>=50*0.7,4,IF(N26>=50*0.6,3.5,IF(N26>=50*0.5,3,IF(N26>=50*0.4,2,IF(N26>=50*0.33,1,0)))))))) | AG26: =IF(B26="","",IF(O26<33.0,0,IF(O26>=100*0.8,5,IF(O26>=100*0.7,4,IF(O26>=100*0.6,3.5,IF(O26>=100*0.5,3,IF(O26>=100*0.4,2,IF(O26>=100*0.33,1,0)))))))) | AH26: =IF(B26="","",IF(OR(U26=0,V26=0,W26=0,X26=0,Y26=0,Z26=0,AA26=0,AB26=0,AC26=0,AD26=0,AE26=0,AF26=0,AG26=0),1,0))
A27: =IF(B27="","",ROW()-2) | P27: =IF(B27="","",SUM(C27:O27)) | Q27: =IF(B27="","",ROUND(P27/13,2)) | R27: =IF(B27="","",IF(AH27=1,0,MIN(5,ROUND((U27+V27+W27+X27+Y27+Z27+AA27+AB27+AC27+AD27+AE27+AF27+AG27)/13,2)))) | S27: =IF(B27="","",IF(R27>=5,"A+",IF(R27>=4,"A",IF(R27>=3.5,"A-",IF(R27>=3,"B",IF(R27>=2,"C",IF(R27>=1,"D","F"))))))) | T27: =IF(OR(B27="",S27="F"),"",COUNTIFS(P:P,">"&P27,S:S,"<>F")+1) | U27: =IF(B27="","",IF(C27<33.0,0,IF(C27>=100*0.8,5,IF(C27>=100*0.7,4,IF(C27>=100*0.6,3.5,IF(C27>=100*0.5,3,IF(C27>=100*0.4,2,IF(C27>=100*0.33,1,0)))))))) | V27: =IF(B27="","",IF(D27<33.0,0,IF(D27>=100*0.8,5,IF(D27>=100*0.7,4,IF(D27>=100*0.6,3.5,IF(D27>=100*0.5,3,IF(D27>=100*0.4,2,IF(D27>=100*0.33,1,0)))))))) | W27: =IF(B27="","",IF(E27<16.5,0,IF(E27>=50*0.8,5,IF(E27>=50*0.7,4,IF(E27>=50*0.6,3.5,IF(E27>=50*0.5,3,IF(E27>=50*0.4,2,IF(E27>=50*0.33,1,0)))))))) | X27: =IF(B27="","",IF(F27<33.0,0,IF(F27>=100*0.8,5,IF(F27>=100*0.7,4,IF(F27>=100*0.6,3.5,IF(F27>=100*0.5,3,IF(F27>=100*0.4,2,IF(F27>=100*0.33,1,0)))))))) | Y27: =IF(B27="","",IF(G27<16.5,0,IF(G27>=50*0.8,5,IF(G27>=50*0.7,4,IF(G27>=50*0.6,3.5,IF(G27>=50*0.5,3,IF(G27>=50*0.4,2,IF(G27>=50*0.33,1,0)))))))) | Z27: =IF(B27="","",IF(H27<33.0,0,IF(H27>=100*0.8,5,IF(H27>=100*0.7,4,IF(H27>=100*0.6,3.5,IF(H27>=100*0.5,3,IF(H27>=100*0.4,2,IF(H27>=100*0.33,1,0)))))))) | AA27: =IF(B27="","",IF(I27<33.0,0,IF(I27>=100*0.8,5,IF(I27>=100*0.7,4,IF(I27>=100*0.6,3.5,IF(I27>=100*0.5,3,IF(I27>=100*0.4,2,IF(I27>=100*0.33,1,0)))))))) | AB27: =IF(B27="","",IF(J27<33.0,0,IF(J27>=100*0.8,5,IF(J27>=100*0.7,4,IF(J27>=100*0.6,3.5,IF(J27>=100*0.5,3,IF(J27>=100*0.4,2,IF(J27>=100*0.33,1,0)))))))) | AC27: =IF(B27="","",IF(K27<33.0,0,IF(K27>=100*0.8,5,IF(K27>=100*0.7,4,IF(K27>=100*0.6,3.5,IF(K27>=100*0.5,3,IF(K27>=100*0.4,2,IF(K27>=100*0.33,1,0)))))))) | AD27: =IF(B27="","",IF(L27<33.0,0,IF(L27>=100*0.8,5,IF(L27>=100*0.7,4,IF(L27>=100*0.6,3.5,IF(L27>=100*0.5,3,IF(L27>=100*0.4,2,IF(L27>=100*0.33,1,0)))))))) | AE27: =IF(B27="","",IF(M27<33.0,0,IF(M27>=100*0.8,5,IF(M27>=100*0.7,4,IF(M27>=100*0.6,3.5,IF(M27>=100*0.5,3,IF(M27>=100*0.4,2,IF(M27>=100*0.33,1,0)))))))) | AF27: =IF(B27="","",IF(N27<16.5,0,IF(N27>=50*0.8,5,IF(N27>=50*0.7,4,IF(N27>=50*0.6,3.5,IF(N27>=50*0.5,3,IF(N27>=50*0.4,2,IF(N27>=50*0.33,1,0)))))))) | AG27: =IF(B27="","",IF(O27<33.0,0,IF(O27>=100*0.8,5,IF(O27>=100*0.7,4,IF(O27>=100*0.6,3.5,IF(O27>=100*0.5,3,IF(O27>=100*0.4,2,IF(O27>=100*0.33,1,0)))))))) | AH27: =IF(B27="","",IF(OR(U27=0,V27=0,W27=0,X27=0,Y27=0,Z27=0,AA27=0,AB27=0,AC27=0,AD27=0,AE27=0,AF27=0,AG27=0),1,0))
A28: =IF(B28="","",ROW()-2) | P28: =IF(B28="","",SUM(C28:O28)) | Q28: =IF(B28="","",ROUND(P28/13,2)) | R28: =IF(B28="","",IF(AH28=1,0,MIN(5,ROUND((U28+V28+W28+X28+Y28+Z28+AA28+AB28+AC28+AD28+AE28+AF28+AG28)/13,2)))) | S28: =IF(B28="","",IF(R28>=5,"A+",IF(R28>=4,"A",IF(R28>=3.5,"A-",IF(R28>=3,"B",IF(R28>=2,"C",IF(R28>=1,"D","F"))))))) | T28: =IF(OR(B28="",S28="F"),"",COUNTIFS(P:P,">"&P28,S:S,"<>F")+1) | U28: =IF(B28="","",IF(C28<33.0,0,IF(C28>=100*0.8,5,IF(C28>=100*0.7,4,IF(C28>=100*0.6,3.5,IF(C28>=100*0.5,3,IF(C28>=100*0.4,2,IF(C28>=100*0.33,1,0)))))))) | V28: =IF(B28="","",IF(D28<33.0,0,IF(D28>=100*0.8,5,IF(D28>=100*0.7,4,IF(D28>=100*0.6,3.5,IF(D28>=100*0.5,3,IF(D28>=100*0.4,2,IF(D28>=100*0.33,1,0)))))))) | W28: =IF(B28="","",IF(E28<16.5,0,IF(E28>=50*0.8,5,IF(E28>=50*0.7,4,IF(E28>=50*0.6,3.5,IF(E28>=50*0.5,3,IF(E28>=50*0.4,2,IF(E28>=50*0.33,1,0)))))))) | X28: =IF(B28="","",IF(F28<33.0,0,IF(F28>=100*0.8,5,IF(F28>=100*0.7,4,IF(F28>=100*0.6,3.5,IF(F28>=100*0.5,3,IF(F28>=100*0.4,2,IF(F28>=100*0.33,1,0)))))))) | Y28: =IF(B28="","",IF(G28<16.5,0,IF(G28>=50*0.8,5,IF(G28>=50*0.7,4,IF(G28>=50*0.6,3.5,IF(G28>=50*0.5,3,IF(G28>=50*0.4,2,IF(G28>=50*0.33,1,0)))))))) | Z28: =IF(B28="","",IF(H28<33.0,0,IF(H28>=100*0.8,5,IF(H28>=100*0.7,4,IF(H28>=100*0.6,3.5,IF(H28>=100*0.5,3,IF(H28>=100*0.4,2,IF(H28>=100*0.33,1,0)))))))) | AA28: =IF(B28="","",IF(I28<33.0,0,IF(I28>=100*0.8,5,IF(I28>=100*0.7,4,IF(I28>=100*0.6,3.5,IF(I28>=100*0.5,3,IF(I28>=100*0.4,2,IF(I28>=100*0.33,1,0)))))))) | AB28: =IF(B28="","",IF(J28<33.0,0,IF(J28>=100*0.8,5,IF(J28>=100*0.7,4,IF(J28>=100*0.6,3.5,IF(J28>=100*0.5,3,IF(J28>=100*0.4,2,IF(J28>=100*0.33,1,0)))))))) | AC28: =IF(B28="","",IF(K28<33.0,0,IF(K28>=100*0.8,5,IF(K28>=100*0.7,4,IF(K28>=100*0.6,3.5,IF(K28>=100*0.5,3,IF(K28>=100*0.4,2,IF(K28>=100*0.33,1,0)))))))) | AD28: =IF(B28="","",IF(L28<33.0,0,IF(L28>=100*0.8,5,IF(L28>=100*0.7,4,IF(L28>=100*0.6,3.5,IF(L28>=100*0.5,3,IF(L28>=100*0.4,2,IF(L28>=100*0.33,1,0)))))))) | AE28: =IF(B28="","",IF(M28<33.0,0,IF(M28>=100*0.8,5,IF(M28>=100*0.7,4,IF(M28>=100*0.6,3.5,IF(M28>=100*0.5,3,IF(M28>=100*0.4,2,IF(M28>=100*0.33,1,0)))))))) | AF28: =IF(B28="","",IF(N28<16.5,0,IF(N28>=50*0.8,5,IF(N28>=50*0.7,4,IF(N28>=50*0.6,3.5,IF(N28>=50*0.5,3,IF(N28>=50*0.4,2,IF(N28>=50*0.33,1,0)))))))) | AG28: =IF(B28="","",IF(O28<33.0,0,IF(O28>=100*0.8,5,IF(O28>=100*0.7,4,IF(O28>=100*0.6,3.5,IF(O28>=100*0.5,3,IF(O28>=100*0.4,2,IF(O28>=100*0.33,1,0)))))))) | AH28: =IF(B28="","",IF(OR(U28=0,V28=0,W28=0,X28=0,Y28=0,Z28=0,AA28=0,AB28=0,AC28=0,AD28=0,AE28=0,AF28=0,AG28=0),1,0))
A29: =IF(B29="","",ROW()-2) | P29: =IF(B29="","",SUM(C29:O29)) | Q29: =IF(B29="","",ROUND(P29/13,2)) | R29: =IF(B29="","",IF(AH29=1,0,MIN(5,ROUND((U29+V29+W29+X29+Y29+Z29+AA29+AB29+AC29+AD29+AE29+AF29+AG29)/13,2)))) | S29: =IF(B29="","",IF(R29>=5,"A+",IF(R29>=4,"A",IF(R29>=3.5,"A-",IF(R29>=3,"B",IF(R29>=2,"C",IF(R29>=1,"D","F"))))))) | T29: =IF(OR(B29="",S29="F"),"",COUNTIFS(P:P,">"&P29,S:S,"<>F")+1) | U29: =IF(B29="","",IF(C29<33.0,0,IF(C29>=100*0.8,5,IF(C29>=100*0.7,4,IF(C29>=100*0.6,3.5,IF(C29>=100*0.5,3,IF(C29>=100*0.4,2,IF(C29>=100*0.33,1,0)))))))) | V29: =IF(B29="","",IF(D29<33.0,0,IF(D29>=100*0.8,5,IF(D29>=100*0.7,4,IF(D29>=100*0.6,3.5,IF(D29>=100*0.5,3,IF(D29>=100*0.4,2,IF(D29>=100*0.33,1,0)))))))) | W29: =IF(B29="","",IF(E29<16.5,0,IF(E29>=50*0.8,5,IF(E29>=50*0.7,4,IF(E29>=50*0.6,3.5,IF(E29>=50*0.5,3,IF(E29>=50*0.4,2,IF(E29>=50*0.33,1,0)))))))) | X29: =IF(B29="","",IF(F29<33.0,0,IF(F29>=100*0.8,5,IF(F29>=100*0.7,4,IF(F29>=100*0.6,3.5,IF(F29>=100*0.5,3,IF(F29>=100*0.4,2,IF(F29>=100*0.33,1,0)))))))) | Y29: =IF(B29="","",IF(G29<16.5,0,IF(G29>=50*0.8,5,IF(G29>=50*0.7,4,IF(G29>=50*0.6,3.5,IF(G29>=50*0.5,3,IF(G29>=50*0.4,2,IF(G29>=50*0.33,1,0)))))))) | Z29: =IF(B29="","",IF(H29<33.0,0,IF(H29>=100*0.8,5,IF(H29>=100*0.7,4,IF(H29>=100*0.6,3.5,IF(H29>=100*0.5,3,IF(H29>=100*0.4,2,IF(H29>=100*0.33,1,0)))))))) | AA29: =IF(B29="","",IF(I29<33.0,0,IF(I29>=100*0.8,5,IF(I29>=100*0.7,4,IF(I29>=100*0.6,3.5,IF(I29>=100*0.5,3,IF(I29>=100*0.4,2,IF(I29>=100*0.33,1,0)))))))) | AB29: =IF(B29="","",IF(J29<33.0,0,IF(J29>=100*0.8,5,IF(J29>=100*0.7,4,IF(J29>=100*0.6,3.5,IF(J29>=100*0.5,3,IF(J29>=100*0.4,2,IF(J29>=100*0.33,1,0)))))))) | AC29: =IF(B29="","",IF(K29<33.0,0,IF(K29>=100*0.8,5,IF(K29>=100*0.7,4,IF(K29>=100*0.6,3.5,IF(K29>=100*0.5,3,IF(K29>=100*0.4,2,IF(K29>=100*0.33,1,0)))))))) | AD29: =IF(B29="","",IF(L29<33.0,0,IF(L29>=100*0.8,5,IF(L29>=100*0.7,4,IF(L29>=100*0.6,3.5,IF(L29>=100*0.5,3,IF(L29>=100*0.4,2,IF(L29>=100*0.33,1,0)))))))) | AE29: =IF(B29="","",IF(M29<33.0,0,IF(M29>=100*0.8,5,IF(M29>=100*0.7,4,IF(M29>=100*0.6,3.5,IF(M29>=100*0.5,3,IF(M29>=100*0.4,2,IF(M29>=100*0.33,1,0)))))))) | AF29: =IF(B29="","",IF(N29<16.5,0,IF(N29>=50*0.8,5,IF(N29>=50*0.7,4,IF(N29>=50*0.6,3.5,IF(N29>=50*0.5,3,IF(N29>=50*0.4,2,IF(N29>=50*0.33,1,0)))))))) | AG29: =IF(B29="","",IF(O29<33.0,0,IF(O29>=100*0.8,5,IF(O29>=100*0.7,4,IF(O29>=100*0.6,3.5,IF(O29>=100*0.5,3,IF(O29>=100*0.4,2,IF(O29>=100*0.33,1,0)))))))) | AH29: =IF(B29="","",IF(OR(U29=0,V29=0,W29=0,X29=0,Y29=0,Z29=0,AA29=0,AB29=0,AC29=0,AD29=0,AE29=0,AF29=0,AG29=0),1,0))
A30: =IF(B30="","",ROW()-2) | P30: =IF(B30="","",SUM(C30:O30)) | Q30: =IF(B30="","",ROUND(P30/13,2)) | R30: =IF(B30="","",IF(AH30=1,0,MIN(5,ROUND((U30+V30+W30+X30+Y30+Z30+AA30+AB30+AC30+AD30+AE30+AF30+AG30)/13,2)))) | S30: =IF(B30="","",IF(R30>=5,"A+",IF(R30>=4,"A",IF(R30>=3.5,"A-",IF(R30>=3,"B",IF(R30>=2,"C",IF(R30>=1,"D","F"))))))) | T30: =IF(OR(B30="",S30="F"),"",COUNTIFS(P:P,">"&P30,S:S,"<>F")+1) | U30: =IF(B30="","",IF(C30<33.0,0,IF(C30>=100*0.8,5,IF(C30>=100*0.7,4,IF(C30>=100*0.6,3.5,IF(C30>=100*0.5,3,IF(C30>=100*0.4,2,IF(C30>=100*0.33,1,0)))))))) | V30: =IF(B30="","",IF(D30<33.0,0,IF(D30>=100*0.8,5,IF(D30>=100*0.7,4,IF(D30>=100*0.6,3.5,IF(D30>=100*0.5,3,IF(D30>=100*0.4,2,IF(D30>=100*0.33,1,0)))))))) | W30: =IF(B30="","",IF(E30<16.5,0,IF(E30>=50*0.8,5,IF(E30>=50*0.7,4,IF(E30>=50*0.6,3.5,IF(E30>=50*0.5,3,IF(E30>=50*0.4,2,IF(E30>=50*0.33,1,0)))))))) | X30: =IF(B30="","",IF(F30<33.0,0,IF(F30>=100*0.8,5,IF(F30>=100*0.7,4,IF(F30>=100*0.6,3.5,IF(F30>=100*0.5,3,IF(F30>=100*0.4,2,IF(F30>=100*0.33,1,0)))))))) | Y30: =IF(B30="","",IF(G30<16.5,0,IF(G30>=50*0.8,5,IF(G30>=50*0.7,4,IF(G30>=50*0.6,3.5,IF(G30>=50*0.5,3,IF(G30>=50*0.4,2,IF(G30>=50*0.33,1,0)))))))) | Z30: =IF(B30="","",IF(H30<33.0,0,IF(H30>=100*0.8,5,IF(H30>=100*0.7,4,IF(H30>=100*0.6,3.5,IF(H30>=100*0.5,3,IF(H30>=100*0.4,2,IF(H30>=100*0.33,1,0)))))))) | AA30: =IF(B30="","",IF(I30<33.0,0,IF(I30>=100*0.8,5,IF(I30>=100*0.7,4,IF(I30>=100*0.6,3.5,IF(I30>=100*0.5,3,IF(I30>=100*0.4,2,IF(I30>=100*0.33,1,0)))))))) | AB30: =IF(B30="","",IF(J30<33.0,0,IF(J30>=100*0.8,5,IF(J30>=100*0.7,4,IF(J30>=100*0.6,3.5,IF(J30>=100*0.5,3,IF(J30>=100*0.4,2,IF(J30>=100*0.33,1,0)))))))) | AC30: =IF(B30="","",IF(K30<33.0,0,IF(K30>=100*0.8,5,IF(K30>=100*0.7,4,IF(K30>=100*0.6,3.5,IF(K30>=100*0.5,3,IF(K30>=100*0.4,2,IF(K30>=100*0.33,1,0)))))))) | AD30: =IF(B30="","",IF(L30<33.0,0,IF(L30>=100*0.8,5,IF(L30>=100*0.7,4,IF(L30>=100*0.6,3.5,IF(L30>=100*0.5,3,IF(L30>=100*0.4,2,IF(L30>=100*0.33,1,0)))))))) | AE30: =IF(B30="","",IF(M30<33.0,0,IF(M30>=100*0.8,5,IF(M30>=100*0.7,4,IF(M30>=100*0.6,3.5,IF(M30>=100*0.5,3,IF(M30>=100*0.4,2,IF(M30>=100*0.33,1,0)))))))) | AF30: =IF(B30="","",IF(N30<16.5,0,IF(N30>=50*0.8,5,IF(N30>=50*0.7,4,IF(N30>=50*0.6,3.5,IF(N30>=50*0.5,3,IF(N30>=50*0.4,2,IF(N30>=50*0.33,1,0)))))))) | AG30: =IF(B30="","",IF(O30<33.0,0,IF(O30>=100*0.8,5,IF(O30>=100*0.7,4,IF(O30>=100*0.6,3.5,IF(O30>=100*0.5,3,IF(O30>=100*0.4,2,IF(O30>=100*0.33,1,0)))))))) | AH30: =IF(B30="","",IF(OR(U30=0,V30=0,W30=0,X30=0,Y30=0,Z30=0,AA30=0,AB30=0,AC30=0,AD30=0,AE30=0,AF30=0,AG30=0),1,0))
A31: =IF(B31="","",ROW()-2) | P31: =IF(B31="","",SUM(C31:O31)) | Q31: =IF(B31="","",ROUND(P31/13,2)) | R31: =IF(B31="","",IF(AH31=1,0,MIN(5,ROUND((U31+V31+W31+X31+Y31+Z31+AA31+AB31+AC31+AD31+AE31+AF31+AG31)/13,2)))) | S31: =IF(B31="","",IF(R31>=5,"A+",IF(R31>=4,"A",IF(R31>=3.5,"A-",IF(R31>=3,"B",IF(R31>=2,"C",IF(R31>=1,"D","F"))))))) | T31: =IF(OR(B31="",S31="F"),"",COUNTIFS(P:P,">"&P31,S:S,"<>F")+1) | U31: =IF(B31="","",IF(C31<33.0,0,IF(C31>=100*0.8,5,IF(C31>=100*0.7,4,IF(C31>=100*0.6,3.5,IF(C31>=100*0.5,3,IF(C31>=100*0.4,2,IF(C31>=100*0.33,1,0)))))))) | V31: =IF(B31="","",IF(D31<33.0,0,IF(D31>=100*0.8,5,IF(D31>=100*0.7,4,IF(D31>=100*0.6,3.5,IF(D31>=100*0.5,3,IF(D31>=100*0.4,2,IF(D31>=100*0.33,1,0)))))))) | W31: =IF(B31="","",IF(E31<16.5,0,IF(E31>=50*0.8,5,IF(E31>=50*0.7,4,IF(E31>=50*0.6,3.5,IF(E31>=50*0.5,3,IF(E31>=50*0.4,2,IF(E31>=50*0.33,1,0)))))))) | X31: =IF(B31="","",IF(F31<33.0,0,IF(F31>=100*0.8,5,IF(F31>=100*0.7,4,IF(F31>=100*0.6,3.5,IF(F31>=100*0.5,3,IF(F31>=100*0.4,2,IF(F31>=100*0.33,1,0)))))))) | Y31: =IF(B31="","",IF(G31<16.5,0,IF(G31>=50*0.8,5,IF(G31>=50*0.7,4,IF(G31>=50*0.6,3.5,IF(G31>=50*0.5,3,IF(G31>=50*0.4,2,IF(G31>=50*0.33,1,0)))))))) | Z31: =IF(B31="","",IF(H31<33.0,0,IF(H31>=100*0.8,5,IF(H31>=100*0.7,4,IF(H31>=100*0.6,3.5,IF(H31>=100*0.5,3,IF(H31>=100*0.4,2,IF(H31>=100*0.33,1,0)))))))) | AA31: =IF(B31="","",IF(I31<33.0,0,IF(I31>=100*0.8,5,IF(I31>=100*0.7,4,IF(I31>=100*0.6,3.5,IF(I31>=100*0.5,3,IF(I31>=100*0.4,2,IF(I31>=100*0.33,1,0)))))))) | AB31: =IF(B31="","",IF(J31<33.0,0,IF(J31>=100*0.8,5,IF(J31>=100*0.7,4,IF(J31>=100*0.6,3.5,IF(J31>=100*0.5,3,IF(J31>=100*0.4,2,IF(J31>=100*0.33,1,0)))))))) | AC31: =IF(B31="","",IF(K31<33.0,0,IF(K31>=100*0.8,5,IF(K31>=100*0.7,4,IF(K31>=100*0.6,3.5,IF(K31>=100*0.5,3,IF(K31>=100*0.4,2,IF(K31>=100*0.33,1,0)))))))) | AD31: =IF(B31="","",IF(L31<33.0,0,IF(L31>=100*0.8,5,IF(L31>=100*0.7,4,IF(L31>=100*0.6,3.5,IF(L31>=100*0.5,3,IF(L31>=100*0.4,2,IF(L31>=100*0.33,1,0)))))))) | AE31: =IF(B31="","",IF(M31<33.0,0,IF(M31>=100*0.8,5,IF(M31>=100*0.7,4,IF(M31>=100*0.6,3.5,IF(M31>=100*0.5,3,IF(M31>=100*0.4,2,IF(M31>=100*0.33,1,0)))))))) | AF31: =IF(B31="","",IF(N31<16.5,0,IF(N31>=50*0.8,5,IF(N31>=50*0.7,4,IF(N31>=50*0.6,3.5,IF(N31>=50*0.5,3,IF(N31>=50*0.4,2,IF(N31>=50*0.33,1,0)))))))) | AG31: =IF(B31="","",IF(O31<33.0,0,IF(O31>=100*0.8,5,IF(O31>=100*0.7,4,IF(O31>=100*0.6,3.5,IF(O31>=100*0.5,3,IF(O31>=100*0.4,2,IF(O31>=100*0.33,1,0)))))))) | AH31: =IF(B31="","",IF(OR(U31=0,V31=0,W31=0,X31=0,Y31=0,Z31=0,AA31=0,AB31=0,AC31=0,AD31=0,AE31=0,AF31=0,AG31=0),1,0))
A32: =IF(B32="","",ROW()-2) | P32: =IF(B32="","",SUM(C32:O32)) | Q32: =IF(B32="","",ROUND(P32/13,2)) | R32: =IF(B32="","",IF(AH32=1,0,MIN(5,ROUND((U32+V32+W32+X32+Y32+Z32+AA32+AB32+AC32+AD32+AE32+AF32+AG32)/13,2)))) | S32: =IF(B32="","",IF(R32>=5,"A+",IF(R32>=4,"A",IF(R32>=3.5,"A-",IF(R32>=3,"B",IF(R32>=2,"C",IF(R32>=1,"D","F"))))))) | T32: =IF(OR(B32="",S32="F"),"",COUNTIFS(P:P,">"&P32,S:S,"<>F")+1) | U32: =IF(B32="","",IF(C32<33.0,0,IF(C32>=100*0.8,5,IF(C32>=100*0.7,4,IF(C32>=100*0.6,3.5,IF(C32>=100*0.5,3,IF(C32>=100*0.4,2,IF(C32>=100*0.33,1,0)))))))) | V32: =IF(B32="","",IF(D32<33.0,0,IF(D32>=100*0.8,5,IF(D32>=100*0.7,4,IF(D32>=100*0.6,3.5,IF(D32>=100*0.5,3,IF(D32>=100*0.4,2,IF(D32>=100*0.33,1,0)))))))) | W32: =IF(B32="","",IF(E32<16.5,0,IF(E32>=50*0.8,5,IF(E32>=50*0.7,4,IF(E32>=50*0.6,3.5,IF(E32>=50*0.5,3,IF(E32>=50*0.4,2,IF(E32>=50*0.33,1,0)))))))) | X32: =IF(B32="","",IF(F32<33.0,0,IF(F32>=100*0.8,5,IF(F32>=100*0.7,4,IF(F32>=100*0.6,3.5,IF(F32>=100*0.5,3,IF(F32>=100*0.4,2,IF(F32>=100*0.33,1,0)))))))) | Y32: =IF(B32="","",IF(G32<16.5,0,IF(G32>=50*0.8,5,IF(G32>=50*0.7,4,IF(G32>=50*0.6,3.5,IF(G32>=50*0.5,3,IF(G32>=50*0.4,2,IF(G32>=50*0.33,1,0)))))))) | Z32: =IF(B32="","",IF(H32<33.0,0,IF(H32>=100*0.8,5,IF(H32>=100*0.7,4,IF(H32>=100*0.6,3.5,IF(H32>=100*0.5,3,IF(H32>=100*0.4,2,IF(H32>=100*0.33,1,0)))))))) | AA32: =IF(B32="","",IF(I32<33.0,0,IF(I32>=100*0.8,5,IF(I32>=100*0.7,4,IF(I32>=100*0.6,3.5,IF(I32>=100*0.5,3,IF(I32>=100*0.4,2,IF(I32>=100*0.33,1,0)))))))) | AB32: =IF(B32="","",IF(J32<33.0,0,IF(J32>=100*0.8,5,IF(J32>=100*0.7,4,IF(J32>=100*0.6,3.5,IF(J32>=100*0.5,3,IF(J32>=100*0.4,2,IF(J32>=100*0.33,1,0)))))))) | AC32: =IF(B32="","",IF(K32<33.0,0,IF(K32>=100*0.8,5,IF(K32>=100*0.7,4,IF(K32>=100*0.6,3.5,IF(K32>=100*0.5,3,IF(K32>=100*0.4,2,IF(K32>=100*0.33,1,0)))))))) | AD32: =IF(B32="","",IF(L32<33.0,0,IF(L32>=100*0.8,5,IF(L32>=100*0.7,4,IF(L32>=100*0.6,3.5,IF(L32>=100*0.5,3,IF(L32>=100*0.4,2,IF(L32>=100*0.33,1,0)))))))) | AE32: =IF(B32="","",IF(M32<33.0,0,IF(M32>=100*0.8,5,IF(M32>=100*0.7,4,IF(M32>=100*0.6,3.5,IF(M32>=100*0.5,3,IF(M32>=100*0.4,2,IF(M32>=100*0.33,1,0)))))))) | AF32: =IF(B32="","",IF(N32<16.5,0,IF(N32>=50*0.8,5,IF(N32>=50*0.7,4,IF(N32>=50*0.6,3.5,IF(N32>=50*0.5,3,IF(N32>=50*0.4,2,IF(N32>=50*0.33,1,0)))))))) | AG32: =IF(B32="","",IF(O32<33.0,0,IF(O32>=100*0.8,5,IF(O32>=100*0.7,4,IF(O32>=100*0.6,3.5,IF(O32>=100*0.5,3,IF(O32>=100*0.4,2,IF(O32>=100*0.33,1,0)))))))) | AH32: =IF(B32="","",IF(OR(U32=0,V32=0,W32=0,X32=0,Y32=0,Z32=0,AA32=0,AB32=0,AC32=0,AD32=0,AE32=0,AF32=0,AG32=0),1,0))
